Workbook

Sheet EEF_curves
A1: diameter_arcsec | B1: EEF_aggregated_pct | C1: EEF_pv_pct | D1: EEF_pearson4_pct | E1: EEF_king_pct
A2: 0 | B2: 0 | C2: 0 | D2: 0 | E2: 0
A3: 0.18604955 | B3: 0.083757343 | C3: 0.10966781 | D3: 0.13540873 | E3: 0.11298748
A4: 0.3720991 | B4: 0.29991979 | C4: 0.32806632 | D4: 0.39920764 | E4: 0.33818132
A5: 0.55814865 | B5: 0.64534151 | C5: 0.65334758 | D5: 0.7843721 | E5: 0.67403272
A6: 0.7441982 | B6: 1.1151776 | C6: 1.0828039 | D6: 1.2838918 | E6: 1.1182518
A7: 0.93024775 | B7: 1.7031714 | C7: 1.6129409 | D7: 1.8907908 | E7: 1.6678465
A8: 1.1162973 | B8: 2.4019865 | C8: 2.2395681 | D8: 2.5981479 | E8: 2.3191721
A9: 1.3023468 | B9: 3.2035442 | C9: 2.9579035 | D9: 3.3991154 | E9: 3.0679907
A10: 1.4883964 | B10: 4.0993345 | C10: 3.7626852 | D10: 4.2869384 | E10: 3.9095382
A11: 1.6744459 | B11: 5.0806816 | C11: 4.6482869 | D11: 5.2549731 | E11: 4.8385969
A12: 1.8604955 | B12: 6.138956 | C12: 5.608831 | D12: 6.2967035 | E12: 5.8495723
A13: 2.046545 | B13: 7.2657342 | C13: 6.6382971 | D13: 7.4057582 | E13: 6.9365717
... A214: 39.442505 | B214: 94.440454 | C214: 94.351865 | D214: 94.523291 | E214: 94.9826
A215: 39.628554 | B215: 94.47352 | C215: 94.386512 | D215: 94.559061
A216: 39.814604 | B216: 94.506276 | C216: 94.420831 | D216: 94.594431
A217: 40.000653 | B217: 94.538727 | C217: 94.454828 | D217: 94.62941
A218: 40.186703 | B218: 94.570876 | C218: 94.488507 | D218: 94.664002
A219: 40.372752 | B219: 94.602729 | C219: 94.521871 | D219: 94.698215
A220: 40.558802 | B220: 94.634289 | C220: 94.554926 | D220: 94.732055
A221: 40.744851 | B221: 94.665561 | C221: 94.587675 | D221: 94.765528
A222: 40.930901 | B222: 94.696549 | C222: 94.620123 | D222: 94.79864
A223: 41.11695 | B223: 94.727256 | C223: 94.652274 | D223: 94.831398
A224: 41.303 | B224: 94.757687 | C224: 94.684131 | D224: 94.863805
A225: 41.48905 | B225: 94.787845 | C225: 94.715699 | D225: 94.89587
A226: 41.675099 | B226: 94.817734 | C226: 94.746982 | D226: 94.927596
... A228: 42.047198 | B228: 94.87672 | C228: 94.808705 | D228: 94.990055
A229: 42.233248 | B229: 94.905824 | C229: 94.839153
A230: 42.419297 | B230: 94.934673 | C230: 94.86933
A231: 42.605347 | B231: 94.963271 | C231: 94.89924
A232: 42.791396 | B232: 94.991621 | C232: 94.928886
A233: 42.977446 | C233: 94.958272
A234: 43.163495 | C234: 94.9874
A235: 43.349545
A236: 43.535595
A237: 43.721644
A238: 43.907694
A239: 44.093743
A240: 44.279793
A241: 44.465842
...

Sheet Fit_parameters
A1: parameter | B1: value
A2: Modified_PV_Amplitude_A | B2: 5978665.5
A3: Modified_PV_Gamma_c_arcsec | B3: 7.9140223
A4: Modified_PV_Gamma_w_arcsec | B4: 4.052751
A5: Modified_PV_eta | B5: 0.36286816
A6: Modified_PV_beta | B6: 1.5408291
A7: Modified_PV_scalar | B7: 4.4665669
A8: Pearson4_Amplitude | B8: 2.8751223e+08
A9: Pearson4_Center_arcsec | B9: 1.9296172
A10: Pearson4_Sigma_arcsec | B10: 6.2463843
A11: Pearson4_Exponent_m | B11: 1.2604289
A12: Pearson4_Skew_nu | B12: 2.6303763
A13: King_I0 | B13: 5813970.8
... A16: King_b | B16: 147.64412

Sheet PSF_pv
A1: radius_arcsec | B1: I_pv_formula
A2: 0 | B2: =VLOOKUP("Modified_PV_Amplitude_A",Fit_parameters!$A:$B,2,FALSE)*((1 - VLOOKUP("Modified_PV_eta",Fit_parameters!$A:$B,2,FALSE))*EXP(-4*LN(2)*((A2/VLOOKUP("Modified_PV_Gamma_c_arcsec",Fit_parameters!$A:$B,2,FALSE))^2)) + VLOOKUP("Modified_PV_eta",Fit_parameters!$A:$B,2,FALSE)*VLOOKUP("Modified_PV_scalar",Fit_parameters!$A:$B,2,FALSE)*1/POWER(1 + (POWER(2,1/VLOOKUP("Modified_PV_beta",Fit_parameters!$A:$B,2,FALSE))-1)*(POWER(2*A2/VLOOKUP("Modified_PV_Gamma_w_arcsec",Fit_parameters!$A:$B,2,FALSE),2)), VLOOKUP("Modified_PV_beta",Fit_parameters!$A:$B,2,FALSE))/(1 - VLOOKUP("Modified_PV_eta",Fit_parameters!$A:$B,2,FALSE)) + VLOOKUP("Modified_PV_eta",Fit_parameters!$A:$B,2,FALSE)*VLOOKUP("Modified_PV_scalar",Fit_parameters!$A:$B,2,FALSE))
A3: 0.093024775 | B3: =VLOOKUP("Modified_PV_Amplitude_A",Fit_parameters!$A:$B,2,FALSE)*((1 - VLOOKUP("Modified_PV_eta",Fit_parameters!$A:$B,2,FALSE))*EXP(-4*LN(2)*((A3/VLOOKUP("Modified_PV_Gamma_c_arcsec",Fit_parameters!$A:$B,2,FALSE))^2)) + VLOOKUP("Modified_PV_eta",Fit_parameters!$A:$B,2,FALSE)*VLOOKUP("Modified_PV_scalar",Fit_parameters!$A:$B,2,FALSE)*1/POWER(1 + (POWER(2,1/VLOOKUP("Modified_PV_beta",Fit_parameters!$A:$B,2,FALSE))-1)*(POWER(2*A3/VLOOKUP("Modified_PV_Gamma_w_arcsec",Fit_parameters!$A:$B,2,FALSE),2)), VLOOKUP("Modified_PV_beta",Fit_parameters!$A:$B,2,FALSE))/(1 - VLOOKUP("Modified_PV_eta",Fit_parameters!$A:$B,2,FALSE)) + VLOOKUP("Modified_PV_eta",Fit_parameters!$A:$B,2,FALSE)*VLOOKUP("Modified_PV_scalar",Fit_parameters!$A:$B,2,FALSE))
A4: 0.18604955 | B4: =VLOOKUP("Modified_PV_Amplitude_A",Fit_parameters!$A:$B,2,FALSE)*((1 - VLOOKUP("Modified_PV_eta",Fit_parameters!$A:$B,2,FALSE))*EXP(-4*LN(2)*((A4/VLOOKUP("Modified_PV_Gamma_c_arcsec",Fit_parameters!$A:$B,2,FALSE))^2)) + VLOOKUP("Modified_PV_eta",Fit_parameters!$A:$B,2,FALSE)*VLOOKUP("Modified_PV_scalar",Fit_parameters!$A:$B,2,FALSE)*1/POWER(1 + (POWER(2,1/VLOOKUP("Modified_PV_beta",Fit_parameters!$A:$B,2,FALSE))-1)*(POWER(2*A4/VLOOKUP("Modified_PV_Gamma_w_arcsec",Fit_parameters!$A:$B,2,FALSE),2)), VLOOKUP("Modified_PV_beta",Fit_parameters!$A:$B,2,FALSE))/(1 - VLOOKUP("Modified_PV_eta",Fit_parameters!$A:$B,2,FALSE)) + VLOOKUP("Modified_PV_eta",Fit_parameters!$A:$B,2,FALSE)*VLOOKUP("Modified_PV_scalar",Fit_parameters!$A:$B,2,FALSE))
A5: 0.27907432 | B5: =VLOOKUP("Modified_PV_Amplitude_A",Fit_parameters!$A:$B,2,FALSE)*((1 - VLOOKUP("Modified_PV_eta",Fit_parameters!$A:$B,2,FALSE))*EXP(-4*LN(2)*((A5/VLOOKUP("Modified_PV_Gamma_c_arcsec",Fit_parameters!$A:$B,2,FALSE))^2)) + VLOOKUP("Modified_PV_eta",Fit_parameters!$A:$B,2,FALSE)*VLOOKUP("Modified_PV_scalar",Fit_parameters!$A:$B,2,FALSE)*1/POWER(1 + (POWER(2,1/VLOOKUP("Modified_PV_beta",Fit_parameters!$A:$B,2,FALSE))-1)*(POWER(2*A5/VLOOKUP("Modified_PV_Gamma_w_arcsec",Fit_parameters!$A:$B,2,FALSE),2)), VLOOKUP("Modified_PV_beta",Fit_parameters!$A:$B,2,FALSE))/(1 - VLOOKUP("Modified_PV_eta",Fit_parameters!$A:$B,2,FALSE)) + VLOOKUP("Modified_PV_eta",Fit_parameters!$A:$B,2,FALSE)*VLOOKUP("Modified_PV_scalar",Fit_parameters!$A:$B,2,FALSE))
A6: 0.3720991 | B6: =VLOOKUP("Modified_PV_Amplitude_A",Fit_parameters!$A:$B,2,FALSE)*((1 - VLOOKUP("Modified_PV_eta",Fit_parameters!$A:$B,2,FALSE))*EXP(-4*LN(2)*((A6/VLOOKUP("Modified_PV_Gamma_c_arcsec",Fit_parameters!$A:$B,2,FALSE))^2)) + VLOOKUP("Modified_PV_eta",Fit_parameters!$A:$B,2,FALSE)*VLOOKUP("Modified_PV_scalar",Fit_parameters!$A:$B,2,FALSE)*1/POWER(1 + (POWER(2,1/VLOOKUP("Modified_PV_beta",Fit_parameters!$A:$B,2,FALSE))-1)*(POWER(2*A6/VLOOKUP("Modified_PV_Gamma_w_arcsec",Fit_parameters!$A:$B,2,FALSE),2)), VLOOKUP("Modified_PV_beta",Fit_parameters!$A:$B,2,FALSE))/(1 - VLOOKUP("Modified_PV_eta",Fit_parameters!$A:$B,2,FALSE)) + VLOOKUP("Modified_PV_eta",Fit_parameters!$A:$B,2,FALSE)*VLOOKUP("Modified_PV_scalar",Fit_parameters!$A:$B,2,FALSE))
A7: 0.46512387 | B7: =VLOOKUP("Modified_PV_Amplitude_A",Fit_parameters!$A:$B,2,FALSE)*((1 - VLOOKUP("Modified_PV_eta",Fit_parameters!$A:$B,2,FALSE))*EXP(-4*LN(2)*((A7/VLOOKUP("Modified_PV_Gamma_c_arcsec",Fit_parameters!$A:$B,2,FALSE))^2)) + VLOOKUP("Modified_PV_eta",Fit_parameters!$A:$B,2,FALSE)*VLOOKUP("Modified_PV_scalar",Fit_parameters!$A:$B,2,FALSE)*1/POWER(1 + (POWER(2,1/VLOOKUP("Modified_PV_beta",Fit_parameters!$A:$B,2,FALSE))-1)*(POWER(2*A7/VLOOKUP("Modified_PV_Gamma_w_arcsec",Fit_parameters!$A:$B,2,FALSE),2)), VLOOKUP("Modified_PV_beta",Fit_parameters!$A:$B,2,FALSE))/(1 - VLOOKUP("Modified_PV_eta",Fit_parameters!$A:$B,2,FALSE)) + VLOOKUP("Modified_PV_eta",Fit_parameters!$A:$B,2,FALSE)*VLOOKUP("Modified_PV_scalar",Fit_parameters!$A:$B,2,FALSE))
A8: 0.55814865 | B8: =VLOOKUP("Modified_PV_Amplitude_A",Fit_parameters!$A:$B,2,FALSE)*((1 - VLOOKUP("Modified_PV_eta",Fit_parameters!$A:$B,2,FALSE))*EXP(-4*LN(2)*((A8/VLOOKUP("Modified_PV_Gamma_c_arcsec",Fit_parameters!$A:$B,2,FALSE))^2)) + VLOOKUP("Modified_PV_eta",Fit_parameters!$A:$B,2,FALSE)*VLOOKUP("Modified_PV_scalar",Fit_parameters!$A:$B,2,FALSE)*1/POWER(1 + (POWER(2,1/VLOOKUP("Modified_PV_beta",Fit_parameters!$A:$B,2,FALSE))-1)*(POWER(2*A8/VLOOKUP("Modified_PV_Gamma_w_arcsec",Fit_parameters!$A:$B,2,FALSE),2)), VLOOKUP("Modified_PV_beta",Fit_parameters!$A:$B,2,FALSE))/(1 - VLOOKUP("Modified_PV_eta",Fit_parameters!$A:$B,2,FALSE)) + VLOOKUP("Modified_PV_eta",Fit_parameters!$A:$B,2,FALSE)*VLOOKUP("Modified_PV_scalar",Fit_parameters!$A:$B,2,FALSE))
A9: 0.65117342 | B9: =VLOOKUP("Modified_PV_Amplitude_A",Fit_parameters!$A:$B,2,FALSE)*((1 - VLOOKUP("Modified_PV_eta",Fit_parameters!$A:$B,2,FALSE))*EXP(-4*LN(2)*((A9/VLOOKUP("Modified_PV_Gamma_c_arcsec",Fit_parameters!$A:$B,2,FALSE))^2)) + VLOOKUP("Modified_PV_eta",Fit_parameters!$A:$B,2,FALSE)*VLOOKUP("Modified_PV_scalar",Fit_parameters!$A:$B,2,FALSE)*1/POWER(1 + (POWER(2,1/VLOOKUP("Modified_PV_beta",Fit_parameters!$A:$B,2,FALSE))-1)*(POWER(2*A9/VLOOKUP("Modified_PV_Gamma_w_arcsec",Fit_parameters!$A:$B,2,FALSE),2)), VLOOKUP("Modified_PV_beta",Fit_parameters!$A:$B,2,FALSE))/(1 - VLOOKUP("Modified_PV_eta",Fit_parameters!$A:$B,2,FALSE)) + VLOOKUP("Modified_PV_eta",Fit_parameters!$A:$B,2,FALSE)*VLOOKUP("Modified_PV_scalar",Fit_parameters!$A:$B,2,FALSE))
A10: 0.7441982 | B10: =VLOOKUP("Modified_PV_Amplitude_A",Fit_parameters!$A:$B,2,FALSE)*((1 - VLOOKUP("Modified_PV_eta",Fit_parameters!$A:$B,2,FALSE))*EXP(-4*LN(2)*((A10/VLOOKUP("Modified_PV_Gamma_c_arcsec",Fit_parameters!$A:$B,2,FALSE))^2)) + VLOOKUP("Modified_PV_eta",Fit_parameters!$A:$B,2,FALSE)*VLOOKUP("Modified_PV_scalar",Fit_parameters!$A:$B,2,FALSE)*1/POWER(1 + (POWER(2,1/VLOOKUP("Modified_PV_beta",Fit_parameters!$A:$B,2,FALSE))-1)*(POWER(2*A10/VLOOKUP("Modified_PV_Gamma_w_arcsec",Fit_parameters!$A:$B,2,FALSE),2)), VLOOKUP("Modified_PV_beta",Fit_parameters!$A:$B,2,FALSE))/(1 - VLOOKUP("Modified_PV_eta",Fit_parameters!$A:$B,2,FALSE)) + VLOOKUP("Modified_PV_eta",Fit_parameters!$A:$B,2,FALSE)*VLOOKUP("Modified_PV_scalar",Fit_parameters!$A:$B,2,FALSE))
A11: 0.83722297 | B11: =VLOOKUP("Modified_PV_Amplitude_A",Fit_parameters!$A:$B,2,FALSE)*((1 - VLOOKUP("Modified_PV_eta",Fit_parameters!$A:$B,2,FALSE))*EXP(-4*LN(2)*((A11/VLOOKUP("Modified_PV_Gamma_c_arcsec",Fit_parameters!$A:$B,2,FALSE))^2)) + VLOOKUP("Modified_PV_eta",Fit_parameters!$A:$B,2,FALSE)*VLOOKUP("Modified_PV_scalar",Fit_parameters!$A:$B,2,FALSE)*1/POWER(1 + (POWER(2,1/VLOOKUP("Modified_PV_beta",Fit_parameters!$A:$B,2,FALSE))-1)*(POWER(2*A11/VLOOKUP("Modified_PV_Gamma_w_arcsec",Fit_parameters!$A:$B,2,FALSE),2)), VLOOKUP("Modified_PV_beta",Fit_parameters!$A:$B,2,FALSE))/(1 - VLOOKUP("Modified_PV_eta",Fit_parameters!$A:$B,2,FALSE)) + VLOOKUP("Modified_PV_eta",Fit_parameters!$A:$B,2,FALSE)*VLOOKUP("Modified_PV_scalar",Fit_parameters!$A:$B,2,FALSE))
A12: 0.93024775 | B12: =VLOOKUP("Modified_PV_Amplitude_A",Fit_parameters!$A:$B,2,FALSE)*((1 - VLOOKUP("Modified_PV_eta",Fit_parameters!$A:$B,2,FALSE))*EXP(-4*LN(2)*((A12/VLOOKUP("Modified_PV_Gamma_c_arcsec",Fit_parameters!$A:$B,2,FALSE))^2)) + VLOOKUP("Modified_PV_eta",Fit_parameters!$A:$B,2,FALSE)*VLOOKUP("Modified_PV_scalar",Fit_parameters!$A:$B,2,FALSE)*1/POWER(1 + (POWER(2,1/VLOOKUP("Modified_PV_beta",Fit_parameters!$A:$B,2,FALSE))-1)*(POWER(2*A12/VLOOKUP("Modified_PV_Gamma_w_arcsec",Fit_parameters!$A:$B,2,FALSE),2)), VLOOKUP("Modified_PV_beta",Fit_parameters!$A:$B,2,FALSE))/(1 - VLOOKUP("Modified_PV_eta",Fit_parameters!$A:$B,2,FALSE)) + VLOOKUP("Modified_PV_eta",Fit_parameters!$A:$B,2,FALSE)*VLOOKUP("Modified_PV_scalar",Fit_parameters!$A:$B,2,FALSE))
A13: 1.0232725 | B13: =VLOOKUP("Modified_PV_Amplitude_A",Fit_parameters!$A:$B,2,FALSE)*((1 - VLOOKUP("Modified_PV_eta",Fit_parameters!$A:$B,2,FALSE))*EXP(-4*LN(2)*((A13/VLOOKUP("Modified_PV_Gamma_c_arcsec",Fit_parameters!$A:$B,2,FALSE))^2)) + VLOOKUP("Modified_PV_eta",Fit_parameters!$A:$B,2,FALSE)*VLOOKUP("Modified_PV_scalar",Fit_parameters!$A:$B,2,FALSE)*1/POWER(1 + (POWER(2,1/VLOOKUP("Modified_PV_beta",Fit_parameters!$A:$B,2,FALSE))-1)*(POWER(2*A13/VLOOKUP("Modified_PV_Gamma_w_arcsec",Fit_parameters!$A:$B,2,FALSE),2)), VLOOKUP("Modified_PV_beta",Fit_parameters!$A:$B,2,FALSE))/(1 - VLOOKUP("Modified_PV_eta",Fit_parameters!$A:$B,2,FALSE)) + VLOOKUP("Modified_PV_eta",Fit_parameters!$A:$B,2,FALSE)*VLOOKUP("Modified_PV_scalar",Fit_parameters!$A:$B,2,FALSE))
... A1001: 92.93175 | B1001: =VLOOKUP("Modified_PV_Amplitude_A",Fit_parameters!$A:$B,2,FALSE)*((1 - VLOOKUP("Modified_PV_eta",Fit_parameters!$A:$B,2,FALSE))*EXP(-4*LN(2)*((A1001/VLOOKUP("Modified_PV_Gamma_c_arcsec",Fit_parameters!$A:$B,2,FALSE))^2)) + VLOOKUP("Modified_PV_eta",Fit_parameters!$A:$B,2,FALSE)*VLOOKUP("Modified_PV_scalar",Fit_parameters!$A:$B,2,FALSE)*1/POWER(1 + (POWER(2,1/VLOOKUP("Modified_PV_beta",Fit_parameters!$A:$B,2,FALSE))-1)*(POWER(2*A1001/VLOOKUP("Modified_PV_Gamma_w_arcsec",Fit_parameters!$A:$B,2,FALSE),2)), VLOOKUP("Modified_PV_beta",Fit_parameters!$A:$B,2,FALSE))/(1 - VLOOKUP("Modified_PV_eta",Fit_parameters!$A:$B,2,FALSE)) + VLOOKUP("Modified_PV_eta",Fit_parameters!$A:$B,2,FALSE)*VLOOKUP("Modified_PV_scalar",Fit_parameters!$A:$B,2,FALSE))

Sheet PSF_pearson4
A1: radius_arcsec | B1: I_pearson4
A2: 0 | B2: 7462388.7
A3: 0.093024775 | B3: 7274251.8
A4: 0.18604955 | B4: 7085731.3
A5: 0.27907432 | B5: 6897101.7
A6: 0.3720991 | B6: 6708636.9
A7: 0.46512387 | B7: 6520608.8
A8: 0.55814865 | B8: 6333286.3
A9: 0.65117342 | B9: 6146933.7
A10: 0.7441982 | B10: 5961809.8
A11: 0.83722297 | B11: 5778166.8
A12: 0.93024775 | B12: 5596248.8
A13: 1.0232725 | B13: 5416290.8
... A1001: 92.93175 | B1001: 84.914358

Sheet PSF_king
A1: radius_arcsec | B1: I_king_formula
A2: 0 | B2: =VLOOKUP("King_I0",Fit_parameters!$A:$B,2,FALSE)*POWER(1 + POWER(A2/VLOOKUP("King_rc_arcsec",Fit_parameters!$A:$B,2,FALSE),2), -VLOOKUP("King_alpha",Fit_parameters!$A:$B,2,FALSE)) + VLOOKUP("King_b",Fit_parameters!$A:$B,2,FALSE)
A3: 0.093024775 | B3: =VLOOKUP("King_I0",Fit_parameters!$A:$B,2,FALSE)*POWER(1 + POWER(A3/VLOOKUP("King_rc_arcsec",Fit_parameters!$A:$B,2,FALSE),2), -VLOOKUP("King_alpha",Fit_parameters!$A:$B,2,FALSE)) + VLOOKUP("King_b",Fit_parameters!$A:$B,2,FALSE)
A4: 0.18604955 | B4: =VLOOKUP("King_I0",Fit_parameters!$A:$B,2,FALSE)*POWER(1 + POWER(A4/VLOOKUP("King_rc_arcsec",Fit_parameters!$A:$B,2,FALSE),2), -VLOOKUP("King_alpha",Fit_parameters!$A:$B,2,FALSE)) + VLOOKUP("King_b",Fit_parameters!$A:$B,2,FALSE)
A5: 0.27907432 | B5: =VLOOKUP("King_I0",Fit_parameters!$A:$B,2,FALSE)*POWER(1 + POWER(A5/VLOOKUP("King_rc_arcsec",Fit_parameters!$A:$B,2,FALSE),2), -VLOOKUP("King_alpha",Fit_parameters!$A:$B,2,FALSE)) + VLOOKUP("King_b",Fit_parameters!$A:$B,2,FALSE)
A6: 0.3720991 | B6: =VLOOKUP("King_I0",Fit_parameters!$A:$B,2,FALSE)*POWER(1 + POWER(A6/VLOOKUP("King_rc_arcsec",Fit_parameters!$A:$B,2,FALSE),2), -VLOOKUP("King_alpha",Fit_parameters!$A:$B,2,FALSE)) + VLOOKUP("King_b",Fit_parameters!$A:$B,2,FALSE)
A7: 0.46512387 | B7: =VLOOKUP("King_I0",Fit_parameters!$A:$B,2,FALSE)*POWER(1 + POWER(A7/VLOOKUP("King_rc_arcsec",Fit_parameters!$A:$B,2,FALSE),2), -VLOOKUP("King_alpha",Fit_parameters!$A:$B,2,FALSE)) + VLOOKUP("King_b",Fit_parameters!$A:$B,2,FALSE)
A8: 0.55814865 | B8: =VLOOKUP("King_I0",Fit_parameters!$A:$B,2,FALSE)*POWER(1 + POWER(A8/VLOOKUP("King_rc_arcsec",Fit_parameters!$A:$B,2,FALSE),2), -VLOOKUP("King_alpha",Fit_parameters!$A:$B,2,FALSE)) + VLOOKUP("King_b",Fit_parameters!$A:$B,2,FALSE)
A9: 0.65117342 | B9: =VLOOKUP("King_I0",Fit_parameters!$A:$B,2,FALSE)*POWER(1 + POWER(A9/VLOOKUP("King_rc_arcsec",Fit_parameters!$A:$B,2,FALSE),2), -VLOOKUP("King_alpha",Fit_parameters!$A:$B,2,FALSE)) + VLOOKUP("King_b",Fit_parameters!$A:$B,2,FALSE)
A10: 0.7441982 | B10: =VLOOKUP("King_I0",Fit_parameters!$A:$B,2,FALSE)*POWER(1 + POWER(A10/VLOOKUP("King_rc_arcsec",Fit_parameters!$A:$B,2,FALSE),2), -VLOOKUP("King_alpha",Fit_parameters!$A:$B,2,FALSE)) + VLOOKUP("King_b",Fit_parameters!$A:$B,2,FALSE)
A11: 0.83722297 | B11: =VLOOKUP("King_I0",Fit_parameters!$A:$B,2,FALSE)*POWER(1 + POWER(A11/VLOOKUP("King_rc_arcsec",Fit_parameters!$A:$B,2,FALSE),2), -VLOOKUP("King_alpha",Fit_parameters!$A:$B,2,FALSE)) + VLOOKUP("King_b",Fit_parameters!$A:$B,2,FALSE)
A12: 0.93024775 | B12: =VLOOKUP("King_I0",Fit_parameters!$A:$B,2,FALSE)*POWER(1 + POWER(A12/VLOOKUP("King_rc_arcsec",Fit_parameters!$A:$B,2,FALSE),2), -VLOOKUP("King_alpha",Fit_parameters!$A:$B,2,FALSE)) + VLOOKUP("King_b",Fit_parameters!$A:$B,2,FALSE)
A13: 1.0232725 | B13: =VLOOKUP("King_I0",Fit_parameters!$A:$B,2,FALSE)*POWER(1 + POWER(A13/VLOOKUP("King_rc_arcsec",Fit_parameters!$A:$B,2,FALSE),2), -VLOOKUP("King_alpha",Fit_parameters!$A:$B,2,FALSE)) + VLOOKUP("King_b",Fit_parameters!$A:$B,2,FALSE)
... A1001: 92.93175 | B1001: =VLOOKUP("King_I0",Fit_parameters!$A:$B,2,FALSE)*POWER(1 + POWER(A1001/VLOOKUP("King_rc_arcsec",Fit_parameters!$A:$B,2,FALSE),2), -VLOOKUP("King_alpha",Fit_parameters!$A:$B,2,FALSE)) + VLOOKUP("King_b",Fit_parameters!$A:$B,2,FALSE)
