Workbook

Sheet MM configuration
A1: Position # | B1: Petal # | C1: Row # | D1: MM # | E1: x_MM [m] | F1: y_MM [m] | G1: z_MM [m] | H1: r_MM [m]
A2: 1 | B2: 1 | C2: 1 | D2: 1 | E2: 0.043401333 | F2: 0.271106 | G2: 0.0031507873 | H2: 0.27455808
A3: 2 | B3: 1 | C3: 1 | D3: 2 | E3: 0.10741849 | F3: 0.25267253 | G3: 0.0031507873 | H3: 0.27455808
A4: 3 | B4: 1 | C4: 1 | D4: 3 | E4: 0.16511158 | F4: 0.21936341 | G4: 0.0031507873 | H4: 0.27455808
A5: 4 | B5: 1 | C5: 1 | D5: 4 | E5: 0.21308402 | F5: 0.17313966 | G5: 0.0031507873 | H5: 0.27455808
A6: 5 | B6: 1 | C6: 2 | D6: 5 | E6: 0.05212616 | F6: 0.33875848 | G6: 0.0049052246 | H6: 0.34274545
A7: 6 | B7: 1 | C7: 2 | D7: 6 | E7: 0.13345813 | F7: 0.31569507 | G7: 0.0049052246 | H7: 0.34274545
A8: 7 | B8: 1 | C8: 2 | D8: 7 | E8: 0.20667088 | F8: 0.27342566 | G8: 0.0049052246 | H8: 0.34274545
A9: 8 | B9: 1 | C9: 2 | D9: 8 | E9: 0.26731037 | F9: 0.21452182 | G9: 0.0049052246 | H9: 0.34274545
A10: 9 | B10: 1 | C10: 3 | D10: 9 | E10: 0.060914095 | F10: 0.40639176 | G10: 0.0070475585 | H10: 0.41093161
A11: 10 | B11: 1 | C11: 3 | D11: 10 | E11: 0.15951698 | F11: 0.37870717 | G11: 0.0070475585 | H11: 0.41093161
A12: 11 | B12: 1 | C12: 3 | D12: 11 | E12: 0.24821154 | F12: 0.32749934 | G12: 0.0070475585 | H12: 0.41093161
A13: 12 | B13: 1 | C13: 3 | D13: 12 | E13: 0.32148854 | F13: 0.25594903 | G13: 0.0070475585 | H13: 0.41093161
... A601: 600 | B601: 6 | C601: 15 | D601: 600 | E601: -0.079467227 | F601: 1.2219025 | G601: 0.06264642 | H601: 1.2244839

Sheet A_eff
A1: MM # | B1: A_eff_base | C1: A_eff_adjusted | D1: Standard distributions A_eff | E1: Values | J1: A_eff @0.25 keV | K1: A_eff @0.35 keV | L1: A_eff @1 keV | M1: A_eff @2.5 keV | N1: A_eff @7 keV | O1: A_eff @10 keV
A2: 1 | B2: 6 | C2: 5.8746615 | D2: 0.25 keV | E2: J | J2: =VLOOKUP(_xlfn.XLOOKUP($A2,'MM configuration'!$D$2:$D$601,'MM configuration'!$C$2:$C$601),$S$24:$Y$38,2) | K2: =VLOOKUP(_xlfn.XLOOKUP($A2,'MM configuration'!$D$2:$D$601,'MM configuration'!$C$2:$C$601),$S$24:$Y$38,3) | L2: =VLOOKUP(_xlfn.XLOOKUP($A2,'MM configuration'!$D$2:$D$601,'MM configuration'!$C$2:$C$601),$S$24:$Y$38,4) | M2: =VLOOKUP(_xlfn.XLOOKUP($A2,'MM configuration'!$D$2:$D$601,'MM configuration'!$C$2:$C$601),$S$24:$Y$38,5) | N2: =VLOOKUP(_xlfn.XLOOKUP($A2,'MM configuration'!$D$2:$D$601,'MM configuration'!$C$2:$C$601),$S$24:$Y$38,6) | O2: =VLOOKUP(_xlfn.XLOOKUP($A2,'MM configuration'!$D$2:$D$601,'MM configuration'!$C$2:$C$601),$S$24:$Y$38,7) | R2: From effective area budget (05/02/2025). It includes the reductions due to losses at MM level, 7% losses at MAM level and the also the ESA system margin) - results in green
A3: 2 | B3: 6 | C3: 5.8746615 | D3: 0.35 keV | E3: K | J3: =VLOOKUP(_xlfn.XLOOKUP($A3,'MM configuration'!$D$2:$D$601,'MM configuration'!$C$2:$C$601),$S$24:$Y$38,2) | K3: =VLOOKUP(_xlfn.XLOOKUP($A3,'MM configuration'!$D$2:$D$601,'MM configuration'!$C$2:$C$601),$S$24:$Y$38,3) | L3: =VLOOKUP(_xlfn.XLOOKUP($A3,'MM configuration'!$D$2:$D$601,'MM configuration'!$C$2:$C$601),$S$24:$Y$38,4) | M3: =VLOOKUP(_xlfn.XLOOKUP($A3,'MM configuration'!$D$2:$D$601,'MM configuration'!$C$2:$C$601),$S$24:$Y$38,5) | N3: =VLOOKUP(_xlfn.XLOOKUP($A3,'MM configuration'!$D$2:$D$601,'MM configuration'!$C$2:$C$601),$S$24:$Y$38,6) | O3: =VLOOKUP(_xlfn.XLOOKUP($A3,'MM configuration'!$D$2:$D$601,'MM configuration'!$C$2:$C$601),$S$24:$Y$38,7)
A4: 3 | B4: 6 | C4: 5.8746615 | D4: 1 keV | E4: L | J4: =VLOOKUP(_xlfn.XLOOKUP($A4,'MM configuration'!$D$2:$D$601,'MM configuration'!$C$2:$C$601),$S$24:$Y$38,2) | K4: =VLOOKUP(_xlfn.XLOOKUP($A4,'MM configuration'!$D$2:$D$601,'MM configuration'!$C$2:$C$601),$S$24:$Y$38,3) | L4: =VLOOKUP(_xlfn.XLOOKUP($A4,'MM configuration'!$D$2:$D$601,'MM configuration'!$C$2:$C$601),$S$24:$Y$38,4) | M4: =VLOOKUP(_xlfn.XLOOKUP($A4,'MM configuration'!$D$2:$D$601,'MM configuration'!$C$2:$C$601),$S$24:$Y$38,5) | N4: =VLOOKUP(_xlfn.XLOOKUP($A4,'MM configuration'!$D$2:$D$601,'MM configuration'!$C$2:$C$601),$S$24:$Y$38,6) | O4: =VLOOKUP(_xlfn.XLOOKUP($A4,'MM configuration'!$D$2:$D$601,'MM configuration'!$C$2:$C$601),$S$24:$Y$38,7) | S4: Energies | T4: @0.25 keV | U4: @0.35 keV | V4: @1 keV | W4: @2.5 keV | X4: @7 keV | Y4: @10 keV
A5: 4 | B5: 6 | C5: 5.8746615 | D5: 2.5 keV | E5: M | J5: =VLOOKUP(_xlfn.XLOOKUP($A5,'MM configuration'!$D$2:$D$601,'MM configuration'!$C$2:$C$601),$S$24:$Y$38,2) | K5: =VLOOKUP(_xlfn.XLOOKUP($A5,'MM configuration'!$D$2:$D$601,'MM configuration'!$C$2:$C$601),$S$24:$Y$38,3) | L5: =VLOOKUP(_xlfn.XLOOKUP($A5,'MM configuration'!$D$2:$D$601,'MM configuration'!$C$2:$C$601),$S$24:$Y$38,4) | M5: =VLOOKUP(_xlfn.XLOOKUP($A5,'MM configuration'!$D$2:$D$601,'MM configuration'!$C$2:$C$601),$S$24:$Y$38,5) | N5: =VLOOKUP(_xlfn.XLOOKUP($A5,'MM configuration'!$D$2:$D$601,'MM configuration'!$C$2:$C$601),$S$24:$Y$38,6) | O5: =VLOOKUP(_xlfn.XLOOKUP($A5,'MM configuration'!$D$2:$D$601,'MM configuration'!$C$2:$C$601),$S$24:$Y$38,7) | R5: Row | S5: System Margin | T5: 0.0968 | U5: 0.0703 | V5: 0.0704 | W5: 0.0466 | X5: -0.0219 | Y5: 0.0187
A6: 5 | B6: 6 | C6: 5.9616614 | D6: 7 keV | E6: N | J6: =VLOOKUP(_xlfn.XLOOKUP($A6,'MM configuration'!$D$2:$D$601,'MM configuration'!$C$2:$C$601),$S$24:$Y$38,2) | K6: =VLOOKUP(_xlfn.XLOOKUP($A6,'MM configuration'!$D$2:$D$601,'MM configuration'!$C$2:$C$601),$S$24:$Y$38,3) | L6: =VLOOKUP(_xlfn.XLOOKUP($A6,'MM configuration'!$D$2:$D$601,'MM configuration'!$C$2:$C$601),$S$24:$Y$38,4) | M6: =VLOOKUP(_xlfn.XLOOKUP($A6,'MM configuration'!$D$2:$D$601,'MM configuration'!$C$2:$C$601),$S$24:$Y$38,5) | N6: =VLOOKUP(_xlfn.XLOOKUP($A6,'MM configuration'!$D$2:$D$601,'MM configuration'!$C$2:$C$601),$S$24:$Y$38,6) | O6: =VLOOKUP(_xlfn.XLOOKUP($A6,'MM configuration'!$D$2:$D$601,'MM configuration'!$C$2:$C$601),$S$24:$Y$38,7) | R6: 1 | S6: 24 | T6: 0.0306777 | U6: 0.0275707 | V6: 0.0295166 | W6: 0.0276471 | X6: 0.0253849 | Y6: 0.0200959
A7: 6 | B7: 6 | C7: 5.9616614 | D7: 10 keV | E7: O | J7: =VLOOKUP(_xlfn.XLOOKUP($A7,'MM configuration'!$D$2:$D$601,'MM configuration'!$C$2:$C$601),$S$24:$Y$38,2) | K7: =VLOOKUP(_xlfn.XLOOKUP($A7,'MM configuration'!$D$2:$D$601,'MM configuration'!$C$2:$C$601),$S$24:$Y$38,3) | L7: =VLOOKUP(_xlfn.XLOOKUP($A7,'MM configuration'!$D$2:$D$601,'MM configuration'!$C$2:$C$601),$S$24:$Y$38,4) | M7: =VLOOKUP(_xlfn.XLOOKUP($A7,'MM configuration'!$D$2:$D$601,'MM configuration'!$C$2:$C$601),$S$24:$Y$38,5) | N7: =VLOOKUP(_xlfn.XLOOKUP($A7,'MM configuration'!$D$2:$D$601,'MM configuration'!$C$2:$C$601),$S$24:$Y$38,6) | O7: =VLOOKUP(_xlfn.XLOOKUP($A7,'MM configuration'!$D$2:$D$601,'MM configuration'!$C$2:$C$601),$S$24:$Y$38,7) | R7: 2 | S7: 24 | T7: 0.0444676 | U7: 0.0389062 | V7: 0.0422743 | W7: 0.0389822 | X7: 0.0305728 | Y7: 0.0197043
A8: 7 | B8: 6 | C8: 5.9616614 | D8: Variable 5% 0.25 keV | E8: gaussian(J,5%*J) | J8: =VLOOKUP(_xlfn.XLOOKUP($A8,'MM configuration'!$D$2:$D$601,'MM configuration'!$C$2:$C$601),$S$24:$Y$38,2) | K8: =VLOOKUP(_xlfn.XLOOKUP($A8,'MM configuration'!$D$2:$D$601,'MM configuration'!$C$2:$C$601),$S$24:$Y$38,3) | L8: =VLOOKUP(_xlfn.XLOOKUP($A8,'MM configuration'!$D$2:$D$601,'MM configuration'!$C$2:$C$601),$S$24:$Y$38,4) | M8: =VLOOKUP(_xlfn.XLOOKUP($A8,'MM configuration'!$D$2:$D$601,'MM configuration'!$C$2:$C$601),$S$24:$Y$38,5) | N8: =VLOOKUP(_xlfn.XLOOKUP($A8,'MM configuration'!$D$2:$D$601,'MM configuration'!$C$2:$C$601),$S$24:$Y$38,6) | O8: =VLOOKUP(_xlfn.XLOOKUP($A8,'MM configuration'!$D$2:$D$601,'MM configuration'!$C$2:$C$601),$S$24:$Y$38,7) | R8: 3 | S8: 24 | T8: 0.0584217 | U8: 0.0497536 | V8: 0.0549288 | W8: 0.0493485 | X8: 0.0299599 | Y8: 0.0073208
A9: 8 | B9: 6 | C9: 5.9616614 | D9: Variable 10% 0.25 keV | E9: gaussian(J,10%*J) | J9: =VLOOKUP(_xlfn.XLOOKUP($A9,'MM configuration'!$D$2:$D$601,'MM configuration'!$C$2:$C$601),$S$24:$Y$38,2) | K9: =VLOOKUP(_xlfn.XLOOKUP($A9,'MM configuration'!$D$2:$D$601,'MM configuration'!$C$2:$C$601),$S$24:$Y$38,3) | L9: =VLOOKUP(_xlfn.XLOOKUP($A9,'MM configuration'!$D$2:$D$601,'MM configuration'!$C$2:$C$601),$S$24:$Y$38,4) | M9: =VLOOKUP(_xlfn.XLOOKUP($A9,'MM configuration'!$D$2:$D$601,'MM configuration'!$C$2:$C$601),$S$24:$Y$38,5) | N9: =VLOOKUP(_xlfn.XLOOKUP($A9,'MM configuration'!$D$2:$D$601,'MM configuration'!$C$2:$C$601),$S$24:$Y$38,6) | O9: =VLOOKUP(_xlfn.XLOOKUP($A9,'MM configuration'!$D$2:$D$601,'MM configuration'!$C$2:$C$601),$S$24:$Y$38,7) | R9: 4 | S9: 30 | T9: 0.0689765 | U9: 0.0570826 | V9: 0.0640197 | W9: 0.0554219 | X9: 0.0257771 | Y9: 0.0001266
A10: 9 | B10: 6 | C10: 6 | D10: Variable 20% 0.25 keV | E10: gaussian(J,20%*J) | J10: =VLOOKUP(_xlfn.XLOOKUP($A10,'MM configuration'!$D$2:$D$601,'MM configuration'!$C$2:$C$601),$S$24:$Y$38,2) | K10: =VLOOKUP(_xlfn.XLOOKUP($A10,'MM configuration'!$D$2:$D$601,'MM configuration'!$C$2:$C$601),$S$24:$Y$38,3) | L10: =VLOOKUP(_xlfn.XLOOKUP($A10,'MM configuration'!$D$2:$D$601,'MM configuration'!$C$2:$C$601),$S$24:$Y$38,4) | M10: =VLOOKUP(_xlfn.XLOOKUP($A10,'MM configuration'!$D$2:$D$601,'MM configuration'!$C$2:$C$601),$S$24:$Y$38,5) | N10: =VLOOKUP(_xlfn.XLOOKUP($A10,'MM configuration'!$D$2:$D$601,'MM configuration'!$C$2:$C$601),$S$24:$Y$38,6) | O10: =VLOOKUP(_xlfn.XLOOKUP($A10,'MM configuration'!$D$2:$D$601,'MM configuration'!$C$2:$C$601),$S$24:$Y$38,7) | R10: 5 | S10: 30 | T10: 0.0828713 | U10: 0.0668814 | V10: 0.075946 | W10: 0.0620219 | X10: 0.0180059 | Y10: 9.11e-05
A11: 10 | B11: 6 | C11: 6 | D11: Variable 5% 0.35 keV | E11: gaussian(K,5%*K) | J11: =VLOOKUP(_xlfn.XLOOKUP($A11,'MM configuration'!$D$2:$D$601,'MM configuration'!$C$2:$C$601),$S$24:$Y$38,2) | K11: =VLOOKUP(_xlfn.XLOOKUP($A11,'MM configuration'!$D$2:$D$601,'MM configuration'!$C$2:$C$601),$S$24:$Y$38,3) | L11: =VLOOKUP(_xlfn.XLOOKUP($A11,'MM configuration'!$D$2:$D$601,'MM configuration'!$C$2:$C$601),$S$24:$Y$38,4) | M11: =VLOOKUP(_xlfn.XLOOKUP($A11,'MM configuration'!$D$2:$D$601,'MM configuration'!$C$2:$C$601),$S$24:$Y$38,5) | N11: =VLOOKUP(_xlfn.XLOOKUP($A11,'MM configuration'!$D$2:$D$601,'MM configuration'!$C$2:$C$601),$S$24:$Y$38,6) | O11: =VLOOKUP(_xlfn.XLOOKUP($A11,'MM configuration'!$D$2:$D$601,'MM configuration'!$C$2:$C$601),$S$24:$Y$38,7) | R11: 6 | S11: 36 | T11: 0.0931819 | U11: 0.0731615 | V11: 0.0840759 | W11: 0.0648836 | X11: 0.0046315 | Y11: 3.58e-05
A12: 11 | B12: 6 | C12: 6 | D12: Variable 10% 0.35 keV | E12: gaussian(K,10%*K) | J12: =VLOOKUP(_xlfn.XLOOKUP($A12,'MM configuration'!$D$2:$D$601,'MM configuration'!$C$2:$C$601),$S$24:$Y$38,2) | K12: =VLOOKUP(_xlfn.XLOOKUP($A12,'MM configuration'!$D$2:$D$601,'MM configuration'!$C$2:$C$601),$S$24:$Y$38,3) | L12: =VLOOKUP(_xlfn.XLOOKUP($A12,'MM configuration'!$D$2:$D$601,'MM configuration'!$C$2:$C$601),$S$24:$Y$38,4) | M12: =VLOOKUP(_xlfn.XLOOKUP($A12,'MM configuration'!$D$2:$D$601,'MM configuration'!$C$2:$C$601),$S$24:$Y$38,5) | N12: =VLOOKUP(_xlfn.XLOOKUP($A12,'MM configuration'!$D$2:$D$601,'MM configuration'!$C$2:$C$601),$S$24:$Y$38,6) | O12: =VLOOKUP(_xlfn.XLOOKUP($A12,'MM configuration'!$D$2:$D$601,'MM configuration'!$C$2:$C$601),$S$24:$Y$38,7) | R12: 7 | S12: 42 | T12: 0.1035582 | U12: 0.0791522 | V12: 0.0921518 | W12: 0.0647503 | X12: 0.000222 | Y12: 3.2e-06
A13: 12 | B13: 6 | C13: 6 | D13: Variable 20% 0.35 keV | E13: gaussian(K,20%*K) | J13: =VLOOKUP(_xlfn.XLOOKUP($A13,'MM configuration'!$D$2:$D$601,'MM configuration'!$C$2:$C$601),$S$24:$Y$38,2) | K13: =VLOOKUP(_xlfn.XLOOKUP($A13,'MM configuration'!$D$2:$D$601,'MM configuration'!$C$2:$C$601),$S$24:$Y$38,3) | L13: =VLOOKUP(_xlfn.XLOOKUP($A13,'MM configuration'!$D$2:$D$601,'MM configuration'!$C$2:$C$601),$S$24:$Y$38,4) | M13: =VLOOKUP(_xlfn.XLOOKUP($A13,'MM configuration'!$D$2:$D$601,'MM configuration'!$C$2:$C$601),$S$24:$Y$38,5) | N13: =VLOOKUP(_xlfn.XLOOKUP($A13,'MM configuration'!$D$2:$D$601,'MM configuration'!$C$2:$C$601),$S$24:$Y$38,6) | O13: =VLOOKUP(_xlfn.XLOOKUP($A13,'MM configuration'!$D$2:$D$601,'MM configuration'!$C$2:$C$601),$S$24:$Y$38,7) | R13: 8 | S13: 42 | T13: 0.11637 | U13: 0.0866057 | V13: 0.1019048 | W13: 0.0622199 | X13: 7.61e-05 | Y13: 2e-06
A14: 13 | B14: 6 | C14: 6 | D14: Variable 5% 1 keV | E14: gaussian(L,5%*L) | J14: =VLOOKUP(_xlfn.XLOOKUP($A14,'MM configuration'!$D$2:$D$601,'MM configuration'!$C$2:$C$601),$S$24:$Y$38,2) | K14: =VLOOKUP(_xlfn.XLOOKUP($A14,'MM configuration'!$D$2:$D$601,'MM configuration'!$C$2:$C$601),$S$24:$Y$38,3) | L14: =VLOOKUP(_xlfn.XLOOKUP($A14,'MM configuration'!$D$2:$D$601,'MM configuration'!$C$2:$C$601),$S$24:$Y$38,4) | M14: =VLOOKUP(_xlfn.XLOOKUP($A14,'MM configuration'!$D$2:$D$601,'MM configuration'!$C$2:$C$601),$S$24:$Y$38,5) | N14: =VLOOKUP(_xlfn.XLOOKUP($A14,'MM configuration'!$D$2:$D$601,'MM configuration'!$C$2:$C$601),$S$24:$Y$38,6) | O14: =VLOOKUP(_xlfn.XLOOKUP($A14,'MM configuration'!$D$2:$D$601,'MM configuration'!$C$2:$C$601),$S$24:$Y$38,7) | R14: 9 | S14: 42 | T14: 0.1165133 | U14: 0.0936818 | V14: 0.1115269 | W14: 0.0559518 | X14: 0.0001508 | Y14: 5.5e-06
A15: 14 | B15: 6 | C15: 6 | D15: Variable 10% 1 keV | E15: gaussian(L,10%*L) | J15: =VLOOKUP(_xlfn.XLOOKUP($A15,'MM configuration'!$D$2:$D$601,'MM configuration'!$C$2:$C$601),$S$24:$Y$38,2) | K15: =VLOOKUP(_xlfn.XLOOKUP($A15,'MM configuration'!$D$2:$D$601,'MM configuration'!$C$2:$C$601),$S$24:$Y$38,3) | L15: =VLOOKUP(_xlfn.XLOOKUP($A15,'MM configuration'!$D$2:$D$601,'MM configuration'!$C$2:$C$601),$S$24:$Y$38,4) | M15: =VLOOKUP(_xlfn.XLOOKUP($A15,'MM configuration'!$D$2:$D$601,'MM configuration'!$C$2:$C$601),$S$24:$Y$38,5) | N15: =VLOOKUP(_xlfn.XLOOKUP($A15,'MM configuration'!$D$2:$D$601,'MM configuration'!$C$2:$C$601),$S$24:$Y$38,6) | O15: =VLOOKUP(_xlfn.XLOOKUP($A15,'MM configuration'!$D$2:$D$601,'MM configuration'!$C$2:$C$601),$S$24:$Y$38,7) | R15: 10 | S15: 48 | T15: 0.1389669 | U15: 0.0976777 | V15: 0.1175242 | W15: 0.0454628 | X15: 4.66e-05 | Y15: 8e-07
A16: 15 | B16: 6 | C16: 6 | D16: Variable 20% 1 keV | E16: gaussian(L,20%*L) | J16: =VLOOKUP(_xlfn.XLOOKUP($A16,'MM configuration'!$D$2:$D$601,'MM configuration'!$C$2:$C$601),$S$24:$Y$38,2) | K16: =VLOOKUP(_xlfn.XLOOKUP($A16,'MM configuration'!$D$2:$D$601,'MM configuration'!$C$2:$C$601),$S$24:$Y$38,3) | L16: =VLOOKUP(_xlfn.XLOOKUP($A16,'MM configuration'!$D$2:$D$601,'MM configuration'!$C$2:$C$601),$S$24:$Y$38,4) | M16: =VLOOKUP(_xlfn.XLOOKUP($A16,'MM configuration'!$D$2:$D$601,'MM configuration'!$C$2:$C$601),$S$24:$Y$38,5) | N16: =VLOOKUP(_xlfn.XLOOKUP($A16,'MM configuration'!$D$2:$D$601,'MM configuration'!$C$2:$C$601),$S$24:$Y$38,6) | O16: =VLOOKUP(_xlfn.XLOOKUP($A16,'MM configuration'!$D$2:$D$601,'MM configuration'!$C$2:$C$601),$S$24:$Y$38,7) | R16: 11 | S16: 48 | T16: 0.1515634 | U16: 0.1036544 | V16: 0.1256972 | W16: 0.0350108 | X16: 1.07e-05 | Y16: 1e-07
A17: 16 | B17: 6 | C17: 6 | D17: Variable 5% 2.5 keV | E17: gaussian(M,5%*M) | J17: =VLOOKUP(_xlfn.XLOOKUP($A17,'MM configuration'!$D$2:$D$601,'MM configuration'!$C$2:$C$601),$S$24:$Y$38,2) | K17: =VLOOKUP(_xlfn.XLOOKUP($A17,'MM configuration'!$D$2:$D$601,'MM configuration'!$C$2:$C$601),$S$24:$Y$38,3) | L17: =VLOOKUP(_xlfn.XLOOKUP($A17,'MM configuration'!$D$2:$D$601,'MM configuration'!$C$2:$C$601),$S$24:$Y$38,4) | M17: =VLOOKUP(_xlfn.XLOOKUP($A17,'MM configuration'!$D$2:$D$601,'MM configuration'!$C$2:$C$601),$S$24:$Y$38,5) | N17: =VLOOKUP(_xlfn.XLOOKUP($A17,'MM configuration'!$D$2:$D$601,'MM configuration'!$C$2:$C$601),$S$24:$Y$38,6) | O17: =VLOOKUP(_xlfn.XLOOKUP($A17,'MM configuration'!$D$2:$D$601,'MM configuration'!$C$2:$C$601),$S$24:$Y$38,7) | R17: 12 | S17: 48 | T17: 0.163788 | U17: 0.1089055 | V17: 0.1328818 | W17: 0.0250923 | X17: 8e-07 | Y17: 2e-07
... A20: 19 | B20: 6 | C20: 6 | D20: Variable 5% 7 keV | E20: gaussian(N,5%*N) | J20: =VLOOKUP(_xlfn.XLOOKUP($A20,'MM configuration'!$D$2:$D$601,'MM configuration'!$C$2:$C$601),$S$24:$Y$38,2) | K20: =VLOOKUP(_xlfn.XLOOKUP($A20,'MM configuration'!$D$2:$D$601,'MM configuration'!$C$2:$C$601),$S$24:$Y$38,3) | L20: =VLOOKUP(_xlfn.XLOOKUP($A20,'MM configuration'!$D$2:$D$601,'MM configuration'!$C$2:$C$601),$S$24:$Y$38,4) | M20: =VLOOKUP(_xlfn.XLOOKUP($A20,'MM configuration'!$D$2:$D$601,'MM configuration'!$C$2:$C$601),$S$24:$Y$38,5) | N20: =VLOOKUP(_xlfn.XLOOKUP($A20,'MM configuration'!$D$2:$D$601,'MM configuration'!$C$2:$C$601),$S$24:$Y$38,6) | O20: =VLOOKUP(_xlfn.XLOOKUP($A20,'MM configuration'!$D$2:$D$601,'MM configuration'!$C$2:$C$601),$S$24:$Y$38,7) | R20: 15 | S20: 54 | T20: 0.1959741 | U20: 0.1199263 | V20: 0.1473081 | W20: 0.0088317 | X20: 3.5e-06 | Y20: 0
A21: 20 | B21: 6 | C21: 6 | D21: Variable 10% 7 keV | E21: gaussian(N,10%*N) | J21: =VLOOKUP(_xlfn.XLOOKUP($A21,'MM configuration'!$D$2:$D$601,'MM configuration'!$C$2:$C$601),$S$24:$Y$38,2) | K21: =VLOOKUP(_xlfn.XLOOKUP($A21,'MM configuration'!$D$2:$D$601,'MM configuration'!$C$2:$C$601),$S$24:$Y$38,3) | L21: =VLOOKUP(_xlfn.XLOOKUP($A21,'MM configuration'!$D$2:$D$601,'MM configuration'!$C$2:$C$601),$S$24:$Y$38,4) | M21: =VLOOKUP(_xlfn.XLOOKUP($A21,'MM configuration'!$D$2:$D$601,'MM configuration'!$C$2:$C$601),$S$24:$Y$38,5) | N21: =VLOOKUP(_xlfn.XLOOKUP($A21,'MM configuration'!$D$2:$D$601,'MM configuration'!$C$2:$C$601),$S$24:$Y$38,6) | O21: =VLOOKUP(_xlfn.XLOOKUP($A21,'MM configuration'!$D$2:$D$601,'MM configuration'!$C$2:$C$601),$S$24:$Y$38,7)
A22: 21 | B22: 6 | C22: 6 | D22: Variable 20% 7 keV | E22: gaussian(N,20%*N) | J22: =VLOOKUP(_xlfn.XLOOKUP($A22,'MM configuration'!$D$2:$D$601,'MM configuration'!$C$2:$C$601),$S$24:$Y$38,2) | K22: =VLOOKUP(_xlfn.XLOOKUP($A22,'MM configuration'!$D$2:$D$601,'MM configuration'!$C$2:$C$601),$S$24:$Y$38,3) | L22: =VLOOKUP(_xlfn.XLOOKUP($A22,'MM configuration'!$D$2:$D$601,'MM configuration'!$C$2:$C$601),$S$24:$Y$38,4) | M22: =VLOOKUP(_xlfn.XLOOKUP($A22,'MM configuration'!$D$2:$D$601,'MM configuration'!$C$2:$C$601),$S$24:$Y$38,5) | N22: =VLOOKUP(_xlfn.XLOOKUP($A22,'MM configuration'!$D$2:$D$601,'MM configuration'!$C$2:$C$601),$S$24:$Y$38,6) | O22: =VLOOKUP(_xlfn.XLOOKUP($A22,'MM configuration'!$D$2:$D$601,'MM configuration'!$C$2:$C$601),$S$24:$Y$38,7) | R22: Per MM type
A23: 22 | B23: 6 | C23: 6 | D23: Variable 5% 10 keV | E23: gaussian(O,5%*O) | J23: =VLOOKUP(_xlfn.XLOOKUP($A23,'MM configuration'!$D$2:$D$601,'MM configuration'!$C$2:$C$601),$S$24:$Y$38,2) | K23: =VLOOKUP(_xlfn.XLOOKUP($A23,'MM configuration'!$D$2:$D$601,'MM configuration'!$C$2:$C$601),$S$24:$Y$38,3) | L23: =VLOOKUP(_xlfn.XLOOKUP($A23,'MM configuration'!$D$2:$D$601,'MM configuration'!$C$2:$C$601),$S$24:$Y$38,4) | M23: =VLOOKUP(_xlfn.XLOOKUP($A23,'MM configuration'!$D$2:$D$601,'MM configuration'!$C$2:$C$601),$S$24:$Y$38,5) | N23: =VLOOKUP(_xlfn.XLOOKUP($A23,'MM configuration'!$D$2:$D$601,'MM configuration'!$C$2:$C$601),$S$24:$Y$38,6) | O23: =VLOOKUP(_xlfn.XLOOKUP($A23,'MM configuration'!$D$2:$D$601,'MM configuration'!$C$2:$C$601),$S$24:$Y$38,7) | S23: Row
A24: 23 | B24: 6 | C24: 5.9832118 | D24: Variable 10% 10 keV | E24: gaussian(O,10%*O) | J24: =VLOOKUP(_xlfn.XLOOKUP($A24,'MM configuration'!$D$2:$D$601,'MM configuration'!$C$2:$C$601),$S$24:$Y$38,2) | K24: =VLOOKUP(_xlfn.XLOOKUP($A24,'MM configuration'!$D$2:$D$601,'MM configuration'!$C$2:$C$601),$S$24:$Y$38,3) | L24: =VLOOKUP(_xlfn.XLOOKUP($A24,'MM configuration'!$D$2:$D$601,'MM configuration'!$C$2:$C$601),$S$24:$Y$38,4) | M24: =VLOOKUP(_xlfn.XLOOKUP($A24,'MM configuration'!$D$2:$D$601,'MM configuration'!$C$2:$C$601),$S$24:$Y$38,5) | N24: =VLOOKUP(_xlfn.XLOOKUP($A24,'MM configuration'!$D$2:$D$601,'MM configuration'!$C$2:$C$601),$S$24:$Y$38,6) | O24: =VLOOKUP(_xlfn.XLOOKUP($A24,'MM configuration'!$D$2:$D$601,'MM configuration'!$C$2:$C$601),$S$24:$Y$38,7) | S24: 1 | T24: =T6*(100%-T$5)/$S6 | U24: =U6*(100%-U$5)/$S6 | V24: =V6*(100%-V$5)/$S6 | W24: =W6*(100%-W$5)/$S6 | X24: =X6*(100%-X$5)/$S6 | Y24: =Y6*(100%-Y$5)/$S6
A25: 24 | B25: 6 | C25: 5.9832118 | D25: Variable 20% 10 keV | E25: gaussian(O,20%*O) | J25: =VLOOKUP(_xlfn.XLOOKUP($A25,'MM configuration'!$D$2:$D$601,'MM configuration'!$C$2:$C$601),$S$24:$Y$38,2) | K25: =VLOOKUP(_xlfn.XLOOKUP($A25,'MM configuration'!$D$2:$D$601,'MM configuration'!$C$2:$C$601),$S$24:$Y$38,3) | L25: =VLOOKUP(_xlfn.XLOOKUP($A25,'MM configuration'!$D$2:$D$601,'MM configuration'!$C$2:$C$601),$S$24:$Y$38,4) | M25: =VLOOKUP(_xlfn.XLOOKUP($A25,'MM configuration'!$D$2:$D$601,'MM configuration'!$C$2:$C$601),$S$24:$Y$38,5) | N25: =VLOOKUP(_xlfn.XLOOKUP($A25,'MM configuration'!$D$2:$D$601,'MM configuration'!$C$2:$C$601),$S$24:$Y$38,6) | O25: =VLOOKUP(_xlfn.XLOOKUP($A25,'MM configuration'!$D$2:$D$601,'MM configuration'!$C$2:$C$601),$S$24:$Y$38,7) | S25: 2 | T25: =T7*(100%-T$5)/$S7 | U25: =U7*(100%-U$5)/$S7 | V25: =V7*(100%-V$5)/$S7 | W25: =W7*(100%-W$5)/$S7 | X25: =X7*(100%-X$5)/$S7 | Y25: =Y7*(100%-Y$5)/$S7
A26: 25 | B26: 6 | C26: 5.9832118 | J26: =VLOOKUP(_xlfn.XLOOKUP($A26,'MM configuration'!$D$2:$D$601,'MM configuration'!$C$2:$C$601),$S$24:$Y$38,2) | K26: =VLOOKUP(_xlfn.XLOOKUP($A26,'MM configuration'!$D$2:$D$601,'MM configuration'!$C$2:$C$601),$S$24:$Y$38,3) | L26: =VLOOKUP(_xlfn.XLOOKUP($A26,'MM configuration'!$D$2:$D$601,'MM configuration'!$C$2:$C$601),$S$24:$Y$38,4) | M26: =VLOOKUP(_xlfn.XLOOKUP($A26,'MM configuration'!$D$2:$D$601,'MM configuration'!$C$2:$C$601),$S$24:$Y$38,5) | N26: =VLOOKUP(_xlfn.XLOOKUP($A26,'MM configuration'!$D$2:$D$601,'MM configuration'!$C$2:$C$601),$S$24:$Y$38,6) | O26: =VLOOKUP(_xlfn.XLOOKUP($A26,'MM configuration'!$D$2:$D$601,'MM configuration'!$C$2:$C$601),$S$24:$Y$38,7) | S26: 3 | T26: =T8*(100%-T$5)/$S8 | U26: =U8*(100%-U$5)/$S8 | V26: =V8*(100%-V$5)/$S8 | W26: =W8*(100%-W$5)/$S8 | X26: =X8*(100%-X$5)/$S8 | Y26: =Y8*(100%-Y$5)/$S8
A27: 26 | B27: 6 | C27: 5.9832118 | J27: =VLOOKUP(_xlfn.XLOOKUP($A27,'MM configuration'!$D$2:$D$601,'MM configuration'!$C$2:$C$601),$S$24:$Y$38,2) | K27: =VLOOKUP(_xlfn.XLOOKUP($A27,'MM configuration'!$D$2:$D$601,'MM configuration'!$C$2:$C$601),$S$24:$Y$38,3) | L27: =VLOOKUP(_xlfn.XLOOKUP($A27,'MM configuration'!$D$2:$D$601,'MM configuration'!$C$2:$C$601),$S$24:$Y$38,4) | M27: =VLOOKUP(_xlfn.XLOOKUP($A27,'MM configuration'!$D$2:$D$601,'MM configuration'!$C$2:$C$601),$S$24:$Y$38,5) | N27: =VLOOKUP(_xlfn.XLOOKUP($A27,'MM configuration'!$D$2:$D$601,'MM configuration'!$C$2:$C$601),$S$24:$Y$38,6) | O27: =VLOOKUP(_xlfn.XLOOKUP($A27,'MM configuration'!$D$2:$D$601,'MM configuration'!$C$2:$C$601),$S$24:$Y$38,7) | S27: 4 | T27: =T9*(100%-T$5)/$S9 | U27: =U9*(100%-U$5)/$S9 | V27: =V9*(100%-V$5)/$S9 | W27: =W9*(100%-W$5)/$S9 | X27: =X9*(100%-X$5)/$S9 | Y27: =Y9*(100%-Y$5)/$S9
A28: 27 | B28: 6 | C28: 5.9832118 | J28: =VLOOKUP(_xlfn.XLOOKUP($A28,'MM configuration'!$D$2:$D$601,'MM configuration'!$C$2:$C$601),$S$24:$Y$38,2) | K28: =VLOOKUP(_xlfn.XLOOKUP($A28,'MM configuration'!$D$2:$D$601,'MM configuration'!$C$2:$C$601),$S$24:$Y$38,3) | L28: =VLOOKUP(_xlfn.XLOOKUP($A28,'MM configuration'!$D$2:$D$601,'MM configuration'!$C$2:$C$601),$S$24:$Y$38,4) | M28: =VLOOKUP(_xlfn.XLOOKUP($A28,'MM configuration'!$D$2:$D$601,'MM configuration'!$C$2:$C$601),$S$24:$Y$38,5) | N28: =VLOOKUP(_xlfn.XLOOKUP($A28,'MM configuration'!$D$2:$D$601,'MM configuration'!$C$2:$C$601),$S$24:$Y$38,6) | O28: =VLOOKUP(_xlfn.XLOOKUP($A28,'MM configuration'!$D$2:$D$601,'MM configuration'!$C$2:$C$601),$S$24:$Y$38,7) | S28: 5 | T28: =T10*(100%-T$5)/$S10 | U28: =U10*(100%-U$5)/$S10 | V28: =V10*(100%-V$5)/$S10 | W28: =W10*(100%-W$5)/$S10 | X28: =X10*(100%-X$5)/$S10 | Y28: =Y10*(100%-Y$5)/$S10
A29: 28 | B29: 6 | C29: 5.9832118 | J29: =VLOOKUP(_xlfn.XLOOKUP($A29,'MM configuration'!$D$2:$D$601,'MM configuration'!$C$2:$C$601),$S$24:$Y$38,2) | K29: =VLOOKUP(_xlfn.XLOOKUP($A29,'MM configuration'!$D$2:$D$601,'MM configuration'!$C$2:$C$601),$S$24:$Y$38,3) | L29: =VLOOKUP(_xlfn.XLOOKUP($A29,'MM configuration'!$D$2:$D$601,'MM configuration'!$C$2:$C$601),$S$24:$Y$38,4) | M29: =VLOOKUP(_xlfn.XLOOKUP($A29,'MM configuration'!$D$2:$D$601,'MM configuration'!$C$2:$C$601),$S$24:$Y$38,5) | N29: =VLOOKUP(_xlfn.XLOOKUP($A29,'MM configuration'!$D$2:$D$601,'MM configuration'!$C$2:$C$601),$S$24:$Y$38,6) | O29: =VLOOKUP(_xlfn.XLOOKUP($A29,'MM configuration'!$D$2:$D$601,'MM configuration'!$C$2:$C$601),$S$24:$Y$38,7) | S29: 6 | T29: =T11*(100%-T$5)/$S11 | U29: =U11*(100%-U$5)/$S11 | V29: =V11*(100%-V$5)/$S11 | W29: =W11*(100%-W$5)/$S11 | X29: =X11*(100%-X$5)/$S11 | Y29: =Y11*(100%-Y$5)/$S11
A30: 29 | B30: 6 | C30: 6 | J30: =VLOOKUP(_xlfn.XLOOKUP($A30,'MM configuration'!$D$2:$D$601,'MM configuration'!$C$2:$C$601),$S$24:$Y$38,2) | K30: =VLOOKUP(_xlfn.XLOOKUP($A30,'MM configuration'!$D$2:$D$601,'MM configuration'!$C$2:$C$601),$S$24:$Y$38,3) | L30: =VLOOKUP(_xlfn.XLOOKUP($A30,'MM configuration'!$D$2:$D$601,'MM configuration'!$C$2:$C$601),$S$24:$Y$38,4) | M30: =VLOOKUP(_xlfn.XLOOKUP($A30,'MM configuration'!$D$2:$D$601,'MM configuration'!$C$2:$C$601),$S$24:$Y$38,5) | N30: =VLOOKUP(_xlfn.XLOOKUP($A30,'MM configuration'!$D$2:$D$601,'MM configuration'!$C$2:$C$601),$S$24:$Y$38,6) | O30: =VLOOKUP(_xlfn.XLOOKUP($A30,'MM configuration'!$D$2:$D$601,'MM configuration'!$C$2:$C$601),$S$24:$Y$38,7) | S30: 7 | T30: =T12*(100%-T$5)/$S12 | U30: =U12*(100%-U$5)/$S12 | V30: =V12*(100%-V$5)/$S12 | W30: =W12*(100%-W$5)/$S12 | X30: =X12*(100%-X$5)/$S12 | Y30: =Y12*(100%-Y$5)/$S12
A31: 30 | B31: 6 | C31: 6 | J31: =VLOOKUP(_xlfn.XLOOKUP($A31,'MM configuration'!$D$2:$D$601,'MM configuration'!$C$2:$C$601),$S$24:$Y$38,2) | K31: =VLOOKUP(_xlfn.XLOOKUP($A31,'MM configuration'!$D$2:$D$601,'MM configuration'!$C$2:$C$601),$S$24:$Y$38,3) | L31: =VLOOKUP(_xlfn.XLOOKUP($A31,'MM configuration'!$D$2:$D$601,'MM configuration'!$C$2:$C$601),$S$24:$Y$38,4) | M31: =VLOOKUP(_xlfn.XLOOKUP($A31,'MM configuration'!$D$2:$D$601,'MM configuration'!$C$2:$C$601),$S$24:$Y$38,5) | N31: =VLOOKUP(_xlfn.XLOOKUP($A31,'MM configuration'!$D$2:$D$601,'MM configuration'!$C$2:$C$601),$S$24:$Y$38,6) | O31: =VLOOKUP(_xlfn.XLOOKUP($A31,'MM configuration'!$D$2:$D$601,'MM configuration'!$C$2:$C$601),$S$24:$Y$38,7) | S31: 8 | T31: =T13*(100%-T$5)/$S13 | U31: =U13*(100%-U$5)/$S13 | V31: =V13*(100%-V$5)/$S13 | W31: =W13*(100%-W$5)/$S13 | X31: =X13*(100%-X$5)/$S13 | Y31: =Y13*(100%-Y$5)/$S13
A32: 31 | B32: 6 | C32: 6 | J32: =VLOOKUP(_xlfn.XLOOKUP($A32,'MM configuration'!$D$2:$D$601,'MM configuration'!$C$2:$C$601),$S$24:$Y$38,2) | K32: =VLOOKUP(_xlfn.XLOOKUP($A32,'MM configuration'!$D$2:$D$601,'MM configuration'!$C$2:$C$601),$S$24:$Y$38,3) | L32: =VLOOKUP(_xlfn.XLOOKUP($A32,'MM configuration'!$D$2:$D$601,'MM configuration'!$C$2:$C$601),$S$24:$Y$38,4) | M32: =VLOOKUP(_xlfn.XLOOKUP($A32,'MM configuration'!$D$2:$D$601,'MM configuration'!$C$2:$C$601),$S$24:$Y$38,5) | N32: =VLOOKUP(_xlfn.XLOOKUP($A32,'MM configuration'!$D$2:$D$601,'MM configuration'!$C$2:$C$601),$S$24:$Y$38,6) | O32: =VLOOKUP(_xlfn.XLOOKUP($A32,'MM configuration'!$D$2:$D$601,'MM configuration'!$C$2:$C$601),$S$24:$Y$38,7) | S32: 9 | T32: =T14*(100%-T$5)/$S14 | U32: =U14*(100%-U$5)/$S14 | V32: =V14*(100%-V$5)/$S14 | W32: =W14*(100%-W$5)/$S14 | X32: =X14*(100%-X$5)/$S14 | Y32: =Y14*(100%-Y$5)/$S14
A33: 32 | B33: 6 | C33: 6 | J33: =VLOOKUP(_xlfn.XLOOKUP($A33,'MM configuration'!$D$2:$D$601,'MM configuration'!$C$2:$C$601),$S$24:$Y$38,2) | K33: =VLOOKUP(_xlfn.XLOOKUP($A33,'MM configuration'!$D$2:$D$601,'MM configuration'!$C$2:$C$601),$S$24:$Y$38,3) | L33: =VLOOKUP(_xlfn.XLOOKUP($A33,'MM configuration'!$D$2:$D$601,'MM configuration'!$C$2:$C$601),$S$24:$Y$38,4) | M33: =VLOOKUP(_xlfn.XLOOKUP($A33,'MM configuration'!$D$2:$D$601,'MM configuration'!$C$2:$C$601),$S$24:$Y$38,5) | N33: =VLOOKUP(_xlfn.XLOOKUP($A33,'MM configuration'!$D$2:$D$601,'MM configuration'!$C$2:$C$601),$S$24:$Y$38,6) | O33: =VLOOKUP(_xlfn.XLOOKUP($A33,'MM configuration'!$D$2:$D$601,'MM configuration'!$C$2:$C$601),$S$24:$Y$38,7) | S33: 10 | T33: =T15*(100%-T$5)/$S15 | U33: =U15*(100%-U$5)/$S15 | V33: =V15*(100%-V$5)/$S15 | W33: =W15*(100%-W$5)/$S15 | X33: =X15*(100%-X$5)/$S15 | Y33: =Y15*(100%-Y$5)/$S15
A34: 33 | B34: 6 | C34: 6 | J34: =VLOOKUP(_xlfn.XLOOKUP($A34,'MM configuration'!$D$2:$D$601,'MM configuration'!$C$2:$C$601),$S$24:$Y$38,2) | K34: =VLOOKUP(_xlfn.XLOOKUP($A34,'MM configuration'!$D$2:$D$601,'MM configuration'!$C$2:$C$601),$S$24:$Y$38,3) | L34: =VLOOKUP(_xlfn.XLOOKUP($A34,'MM configuration'!$D$2:$D$601,'MM configuration'!$C$2:$C$601),$S$24:$Y$38,4) | M34: =VLOOKUP(_xlfn.XLOOKUP($A34,'MM configuration'!$D$2:$D$601,'MM configuration'!$C$2:$C$601),$S$24:$Y$38,5) | N34: =VLOOKUP(_xlfn.XLOOKUP($A34,'MM configuration'!$D$2:$D$601,'MM configuration'!$C$2:$C$601),$S$24:$Y$38,6) | O34: =VLOOKUP(_xlfn.XLOOKUP($A34,'MM configuration'!$D$2:$D$601,'MM configuration'!$C$2:$C$601),$S$24:$Y$38,7) | S34: 11 | T34: =T16*(100%-T$5)/$S16 | U34: =U16*(100%-U$5)/$S16 | V34: =V16*(100%-V$5)/$S16 | W34: =W16*(100%-W$5)/$S16 | X34: =X16*(100%-X$5)/$S16 | Y34: =Y16*(100%-Y$5)/$S16
A35: 34 | B35: 6 | C35: 6 | J35: =VLOOKUP(_xlfn.XLOOKUP($A35,'MM configuration'!$D$2:$D$601,'MM configuration'!$C$2:$C$601),$S$24:$Y$38,2) | K35: =VLOOKUP(_xlfn.XLOOKUP($A35,'MM configuration'!$D$2:$D$601,'MM configuration'!$C$2:$C$601),$S$24:$Y$38,3) | L35: =VLOOKUP(_xlfn.XLOOKUP($A35,'MM configuration'!$D$2:$D$601,'MM configuration'!$C$2:$C$601),$S$24:$Y$38,4) | M35: =VLOOKUP(_xlfn.XLOOKUP($A35,'MM configuration'!$D$2:$D$601,'MM configuration'!$C$2:$C$601),$S$24:$Y$38,5) | N35: =VLOOKUP(_xlfn.XLOOKUP($A35,'MM configuration'!$D$2:$D$601,'MM configuration'!$C$2:$C$601),$S$24:$Y$38,6) | O35: =VLOOKUP(_xlfn.XLOOKUP($A35,'MM configuration'!$D$2:$D$601,'MM configuration'!$C$2:$C$601),$S$24:$Y$38,7) | S35: 12 | T35: =T17*(100%-T$5)/$S17 | U35: =U17*(100%-U$5)/$S17 | V35: =V17*(100%-V$5)/$S17 | W35: =W17*(100%-W$5)/$S17 | X35: =X17*(100%-X$5)/$S17 | Y35: =Y17*(100%-Y$5)/$S17
A36: 35 | B36: 6 | C36: 6 | J36: =VLOOKUP(_xlfn.XLOOKUP($A36,'MM configuration'!$D$2:$D$601,'MM configuration'!$C$2:$C$601),$S$24:$Y$38,2) | K36: =VLOOKUP(_xlfn.XLOOKUP($A36,'MM configuration'!$D$2:$D$601,'MM configuration'!$C$2:$C$601),$S$24:$Y$38,3) | L36: =VLOOKUP(_xlfn.XLOOKUP($A36,'MM configuration'!$D$2:$D$601,'MM configuration'!$C$2:$C$601),$S$24:$Y$38,4) | M36: =VLOOKUP(_xlfn.XLOOKUP($A36,'MM configuration'!$D$2:$D$601,'MM configuration'!$C$2:$C$601),$S$24:$Y$38,5) | N36: =VLOOKUP(_xlfn.XLOOKUP($A36,'MM configuration'!$D$2:$D$601,'MM configuration'!$C$2:$C$601),$S$24:$Y$38,6) | O36: =VLOOKUP(_xlfn.XLOOKUP($A36,'MM configuration'!$D$2:$D$601,'MM configuration'!$C$2:$C$601),$S$24:$Y$38,7) | S36: 13 | T36: =T18*(100%-T$5)/$S18 | U36: =U18*(100%-U$5)/$S18 | V36: =V18*(100%-V$5)/$S18 | W36: =W18*(100%-W$5)/$S18 | X36: =X18*(100%-X$5)/$S18 | Y36: =Y18*(100%-Y$5)/$S18
A37: 36 | B37: 6 | C37: 5.9532913 | J37: =VLOOKUP(_xlfn.XLOOKUP($A37,'MM configuration'!$D$2:$D$601,'MM configuration'!$C$2:$C$601),$S$24:$Y$38,2) | K37: =VLOOKUP(_xlfn.XLOOKUP($A37,'MM configuration'!$D$2:$D$601,'MM configuration'!$C$2:$C$601),$S$24:$Y$38,3) | L37: =VLOOKUP(_xlfn.XLOOKUP($A37,'MM configuration'!$D$2:$D$601,'MM configuration'!$C$2:$C$601),$S$24:$Y$38,4) | M37: =VLOOKUP(_xlfn.XLOOKUP($A37,'MM configuration'!$D$2:$D$601,'MM configuration'!$C$2:$C$601),$S$24:$Y$38,5) | N37: =VLOOKUP(_xlfn.XLOOKUP($A37,'MM configuration'!$D$2:$D$601,'MM configuration'!$C$2:$C$601),$S$24:$Y$38,6) | O37: =VLOOKUP(_xlfn.XLOOKUP($A37,'MM configuration'!$D$2:$D$601,'MM configuration'!$C$2:$C$601),$S$24:$Y$38,7) | S37: 14 | T37: =T19*(100%-T$5)/$S19 | U37: =U19*(100%-U$5)/$S19 | V37: =V19*(100%-V$5)/$S19 | W37: =W19*(100%-W$5)/$S19 | X37: =X19*(100%-X$5)/$S19 | Y37: =Y19*(100%-Y$5)/$S19
A38: 37 | B38: 6 | C38: 5.9532913 | J38: =VLOOKUP(_xlfn.XLOOKUP($A38,'MM configuration'!$D$2:$D$601,'MM configuration'!$C$2:$C$601),$S$24:$Y$38,2) | K38: =VLOOKUP(_xlfn.XLOOKUP($A38,'MM configuration'!$D$2:$D$601,'MM configuration'!$C$2:$C$601),$S$24:$Y$38,3) | L38: =VLOOKUP(_xlfn.XLOOKUP($A38,'MM configuration'!$D$2:$D$601,'MM configuration'!$C$2:$C$601),$S$24:$Y$38,4) | M38: =VLOOKUP(_xlfn.XLOOKUP($A38,'MM configuration'!$D$2:$D$601,'MM configuration'!$C$2:$C$601),$S$24:$Y$38,5) | N38: =VLOOKUP(_xlfn.XLOOKUP($A38,'MM configuration'!$D$2:$D$601,'MM configuration'!$C$2:$C$601),$S$24:$Y$38,6) | O38: =VLOOKUP(_xlfn.XLOOKUP($A38,'MM configuration'!$D$2:$D$601,'MM configuration'!$C$2:$C$601),$S$24:$Y$38,7) | S38: 15 | T38: =T20*(100%-T$5)/$S20 | U38: =U20*(100%-U$5)/$S20 | V38: =V20*(100%-V$5)/$S20 | W38: =W20*(100%-W$5)/$S20 | X38: =X20*(100%-X$5)/$S20 | Y38: =Y20*(100%-Y$5)/$S20
A39: 38 | B39: 6 | C39: 5.9532913 | J39: =VLOOKUP(_xlfn.XLOOKUP($A39,'MM configuration'!$D$2:$D$601,'MM configuration'!$C$2:$C$601),$S$24:$Y$38,2) | K39: =VLOOKUP(_xlfn.XLOOKUP($A39,'MM configuration'!$D$2:$D$601,'MM configuration'!$C$2:$C$601),$S$24:$Y$38,3) | L39: =VLOOKUP(_xlfn.XLOOKUP($A39,'MM configuration'!$D$2:$D$601,'MM configuration'!$C$2:$C$601),$S$24:$Y$38,4) | M39: =VLOOKUP(_xlfn.XLOOKUP($A39,'MM configuration'!$D$2:$D$601,'MM configuration'!$C$2:$C$601),$S$24:$Y$38,5) | N39: =VLOOKUP(_xlfn.XLOOKUP($A39,'MM configuration'!$D$2:$D$601,'MM configuration'!$C$2:$C$601),$S$24:$Y$38,6) | O39: =VLOOKUP(_xlfn.XLOOKUP($A39,'MM configuration'!$D$2:$D$601,'MM configuration'!$C$2:$C$601),$S$24:$Y$38,7)
A40: 39 | B40: 6 | C40: 5.9532913 | J40: =VLOOKUP(_xlfn.XLOOKUP($A40,'MM configuration'!$D$2:$D$601,'MM configuration'!$C$2:$C$601),$S$24:$Y$38,2) | K40: =VLOOKUP(_xlfn.XLOOKUP($A40,'MM configuration'!$D$2:$D$601,'MM configuration'!$C$2:$C$601),$S$24:$Y$38,3) | L40: =VLOOKUP(_xlfn.XLOOKUP($A40,'MM configuration'!$D$2:$D$601,'MM configuration'!$C$2:$C$601),$S$24:$Y$38,4) | M40: =VLOOKUP(_xlfn.XLOOKUP($A40,'MM configuration'!$D$2:$D$601,'MM configuration'!$C$2:$C$601),$S$24:$Y$38,5) | N40: =VLOOKUP(_xlfn.XLOOKUP($A40,'MM configuration'!$D$2:$D$601,'MM configuration'!$C$2:$C$601),$S$24:$Y$38,6) | O40: =VLOOKUP(_xlfn.XLOOKUP($A40,'MM configuration'!$D$2:$D$601,'MM configuration'!$C$2:$C$601),$S$24:$Y$38,7)
A41: 40 | B41: 6 | C41: 5.9532913 | J41: =VLOOKUP(_xlfn.XLOOKUP($A41,'MM configuration'!$D$2:$D$601,'MM configuration'!$C$2:$C$601),$S$24:$Y$38,2) | K41: =VLOOKUP(_xlfn.XLOOKUP($A41,'MM configuration'!$D$2:$D$601,'MM configuration'!$C$2:$C$601),$S$24:$Y$38,3) | L41: =VLOOKUP(_xlfn.XLOOKUP($A41,'MM configuration'!$D$2:$D$601,'MM configuration'!$C$2:$C$601),$S$24:$Y$38,4) | M41: =VLOOKUP(_xlfn.XLOOKUP($A41,'MM configuration'!$D$2:$D$601,'MM configuration'!$C$2:$C$601),$S$24:$Y$38,5) | N41: =VLOOKUP(_xlfn.XLOOKUP($A41,'MM configuration'!$D$2:$D$601,'MM configuration'!$C$2:$C$601),$S$24:$Y$38,6) | O41: =VLOOKUP(_xlfn.XLOOKUP($A41,'MM configuration'!$D$2:$D$601,'MM configuration'!$C$2:$C$601),$S$24:$Y$38,7)
A42: 41 | B42: 6 | C42: 5.9532913 | J42: =VLOOKUP(_xlfn.XLOOKUP($A42,'MM configuration'!$D$2:$D$601,'MM configuration'!$C$2:$C$601),$S$24:$Y$38,2) | K42: =VLOOKUP(_xlfn.XLOOKUP($A42,'MM configuration'!$D$2:$D$601,'MM configuration'!$C$2:$C$601),$S$24:$Y$38,3) | L42: =VLOOKUP(_xlfn.XLOOKUP($A42,'MM configuration'!$D$2:$D$601,'MM configuration'!$C$2:$C$601),$S$24:$Y$38,4) | M42: =VLOOKUP(_xlfn.XLOOKUP($A42,'MM configuration'!$D$2:$D$601,'MM configuration'!$C$2:$C$601),$S$24:$Y$38,5) | N42: =VLOOKUP(_xlfn.XLOOKUP($A42,'MM configuration'!$D$2:$D$601,'MM configuration'!$C$2:$C$601),$S$24:$Y$38,6) | O42: =VLOOKUP(_xlfn.XLOOKUP($A42,'MM configuration'!$D$2:$D$601,'MM configuration'!$C$2:$C$601),$S$24:$Y$38,7)
...

Sheet Vignetting rotazi
A1: Position # | B1: Vignetting rotazi | C1: Selected energy [keV] | H1: Row | I1: rotazi [arcmin] | J1: energy [keV] | K1: vignetting_factor
A2: 1 | B2: 0.9895 | C2: 7 | H2: 1 | I2: 0 | J2: 0.25 | K2: 0.97419871
A3: 2 | B3: 0.9895 | H3: 2 | I3: 0 | J3: 0.25 | K3: 1
A4: 3 | B4: 0.9895 | H4: 3 | I4: 0 | J4: 0.25 | K4: 1
A5: 4 | B5: 0.9895 | H5: 4 | I5: 0 | J5: 0.25 | K5: 1
A6: 5 | B6: 0.9968 | H6: 5 | I6: 0 | J6: 0.25 | K6: 0.96614282
A7: 6 | B7: 0.9968 | H7: 6 | I7: 0 | J7: 0.25 | K7: 1
A8: 7 | B8: 0.9968 | H8: 7 | I8: 0 | J8: 0.25 | K8: 0.99711066
A9: 8 | B9: 0.9968 | H9: 8 | I9: 0 | J9: 0.25 | K9: 1
A10: 9 | B10: 1 | H10: 9 | I10: 0 | J10: 0.25 | K10: 1
A11: 10 | B11: 1 | H11: 10 | I11: 0 | J11: 0.25 | K11: 1
A12: 11 | B12: 1 | H12: 11 | I12: 0 | J12: 0.25 | K12: 1
A13: 12 | B13: 1 | H13: 12 | I13: 0 | J13: 0.25 | K13: 0.98910191
A14: 13 | B14: 1 | H14: 13 | I14: 0 | J14: 0.25 | K14: 0.99312129
... A29: 28 | B29: 0.9986 | H29: 13 | I29: 0.5 | J29: 0.25 | K29: 1
A30: 29 | B30: 1 | H30: =H29+1 | I30: =I29 | J30: =J29 | K30: =K29
A31: 30 | B31: 1 | H31: =H30+1 | I31: =I30 | J31: =J30 | K31: =K30
A32: 31 | B32: 1 | H32: 1 | I32: 1 | J32: 0.25 | K32: 0.95480187
A33: 32 | B33: 1 | H33: 2 | I33: 1 | J33: 0.25 | K33: 0.92691529
A34: 33 | B34: 1 | H34: 3 | I34: 1 | J34: 0.25 | K34: 0.97661238
A35: 34 | B35: 1 | H35: 4 | I35: 1 | J35: 0.25 | K35: 0.97187441
A36: 35 | B36: 1 | H36: 5 | I36: 1 | J36: 0.25 | K36: 0.97595609
A37: 36 | B37: 0.9961 | H37: 6 | I37: 1 | J37: 0.25 | K37: 0.94371078
A38: 37 | B38: 0.9961 | H38: 7 | I38: 1 | J38: 0.25 | K38: 0.98663576
A39: 38 | B39: 0.9961 | H39: 8 | I39: 1 | J39: 0.25 | K39: 0.97791063
A40: 39 | B40: 0.9961 | H40: 9 | I40: 1 | J40: 0.25 | K40: 0.97750075
A41: 40 | B41: 0.9961 | H41: 10 | I41: 1 | J41: 0.25 | K41: 0.94771029
A42: 41 | B42: 0.9961 | H42: 11 | I42: 1 | J42: 0.25 | K42: 0.9434564
A43: 42 | B43: 0.9961 | H43: 12 | I43: 1 | J43: 0.25 | K43: 0.99978043
A44: 43 | B44: 0.9691 | H44: 13 | I44: 1 | J44: 0.25 | K44: 0.9740682
A45: 44 | B45: 0.9691 | H45: =H44+1 | I45: =I44 | J45: =J44 | K45: =K44
A46: 45 | B46: 0.9691 | H46: =H45+1 | I46: =I45 | J46: =J45 | K46: =K45
A47: 46 | B47: 0.9691 | H47: 1 | I47: 2 | J47: 0.25 | K47: 0.9165432
A48: 47 | B48: 0.9691 | H48: 2 | I48: 2 | J48: 0.25 | K48: 0.88434168
A49: 48 | B49: 0.9691 | H49: 3 | I49: 2 | J49: 0.25 | K49: 0.91919655
A50: 49 | B50: 0.9691 | H50: 4 | I50: 2 | J50: 0.25 | K50: 0.94398955
A51: 50 | B51: 0.9985 | H51: 5 | I51: 2 | J51: 0.25 | K51: 0.94922296
A52: 51 | B52: 0.9985 | H52: 6 | I52: 2 | J52: 0.25 | K52: 0.95741536
A53: 52 | B53: 0.9985 | H53: 7 | I53: 2 | J53: 0.25 | K53: 0.94770167
A54: 53 | B54: 0.9985 | H54: 8 | I54: 2 | J54: 0.25 | K54: 0.9911977
...

Sheet Vignetting rotrad
A1: Position # | B1: Vignetting rotrad | C1: Selected energy [keV] | H1: Row | I1: rotrad [arcmin] | J1: energy [keV] | K1: vignetting_factor
A2: 1 | B2: 0.9895 | C2: 7 | H2: 1 | I2: 0 | J2: 0.25 | K2: 0.97419871
A3: 2 | B3: 0.9895 | H3: 2 | I3: 0 | J3: 0.25 | K3: 1
A4: 3 | B4: 0.9895 | H4: 3 | I4: 0 | J4: 0.25 | K4: 1
A5: 4 | B5: 0.9895 | H5: 4 | I5: 0 | J5: 0.25 | K5: 1
A6: 5 | B6: 0.9968 | H6: 5 | I6: 0 | J6: 0.25 | K6: 0.96614282
A7: 6 | B7: 0.9968 | H7: 6 | I7: 0 | J7: 0.25 | K7: 1
A8: 7 | B8: 0.9968 | H8: 7 | I8: 0 | J8: 0.25 | K8: 0.99711066
A9: 8 | B9: 0.9968 | H9: 8 | I9: 0 | J9: 0.25 | K9: 1
A10: 9 | B10: 1 | H10: 9 | I10: 0 | J10: 0.25 | K10: 1
A11: 10 | B11: 1 | H11: 10 | I11: 0 | J11: 0.25 | K11: 1
A12: 11 | B12: 1 | H12: 11 | I12: 0 | J12: 0.25 | K12: 1
A13: 12 | B13: 1 | H13: 12 | I13: 0 | J13: 0.25 | K13: 0.98910191
A14: 13 | B14: 1 | H14: 13 | I14: 0 | J14: 0.25 | K14: 0.99312129
... A29: 28 | B29: 0.9986 | H29: 13 | I29: 0.5 | J29: 0.25 | K29: 1
A30: 29 | B30: 1 | H30: =H29+1 | I30: =I29 | J30: =J29 | K30: =K29
A31: 30 | B31: 1 | H31: =H30+1 | I31: =I30 | J31: =J30 | K31: =K30
A32: 31 | B32: 1 | H32: 1 | I32: 1 | J32: 0.25 | K32: 0.95480187
A33: 32 | B33: 1 | H33: 2 | I33: 1 | J33: 0.25 | K33: 0.92691529
A34: 33 | B34: 1 | H34: 3 | I34: 1 | J34: 0.25 | K34: 0.97661238
A35: 34 | B35: 1 | H35: 4 | I35: 1 | J35: 0.25 | K35: 0.97187441
A36: 35 | B36: 1 | H36: 5 | I36: 1 | J36: 0.25 | K36: 0.97595609
A37: 36 | B37: 0.9961 | H37: 6 | I37: 1 | J37: 0.25 | K37: 0.94371078
A38: 37 | B38: 0.9961 | H38: 7 | I38: 1 | J38: 0.25 | K38: 0.98663576
A39: 38 | B39: 0.9961 | H39: 8 | I39: 1 | J39: 0.25 | K39: 0.97791063
A40: 39 | B40: 0.9961 | H40: 9 | I40: 1 | J40: 0.25 | K40: 0.97750075
A41: 40 | B41: 0.9961 | H41: 10 | I41: 1 | J41: 0.25 | K41: 0.94771029
A42: 41 | B42: 0.9961 | H42: 11 | I42: 1 | J42: 0.25 | K42: 0.9434564
A43: 42 | B43: 0.9961 | H43: 12 | I43: 1 | J43: 0.25 | K43: 0.99978043
A44: 43 | B44: 0.9691 | H44: 13 | I44: 1 | J44: 0.25 | K44: 0.9740682
A45: 44 | B45: 0.9691 | H45: =H44+1 | I45: =I44 | J45: =J44 | K45: =K44
A46: 45 | B46: 0.9691 | H46: =H45+1 | I46: =I45 | J46: =J45 | K46: =K45
A47: 46 | B47: 0.9691 | H47: 1 | I47: 2 | J47: 0.25 | K47: 0.9165432
A48: 47 | B48: 0.9691 | H48: 2 | I48: 2 | J48: 0.25 | K48: 0.88434168
A49: 48 | B49: 0.9691 | H49: 3 | I49: 2 | J49: 0.25 | K49: 0.91919655
A50: 49 | B50: 0.9691 | H50: 4 | I50: 2 | J50: 0.25 | K50: 0.94398955
A51: 50 | B51: 0.9985 | H51: 5 | I51: 2 | J51: 0.25 | K51: 0.94922296
A52: 51 | B52: 0.9985 | H52: 6 | I52: 2 | J52: 0.25 | K52: 0.95741536
A53: 52 | B53: 0.9985 | H53: 7 | I53: 2 | J53: 0.25 | K53: 0.94770167
A54: 53 | B54: 0.9985 | H54: 8 | I54: 2 | J54: 0.25 | K54: 0.9911977
...

Sheet MM_PSF
A1: MM # | B1: m_rad [arcsec] | C1: m_azi [arcsec] | D1: sigma_rad [arcsec] | E1: sigma_azi [arcsec] | F1: distribution | G1: alpha_rad | H1: alpha_azi | K1: Standard MM_PSF distributions | L1: sigma_rad_ | M1: sigma_azi_ | N1: alpha_rad_ | O1: alpha_azi_
A2: 1 | B2: 0 | C2: 0 | D2: 4.1303 | E2: 1.2633 | F2: pseudo-voigt | G2: 0.77 | H2: 0.29 | K2: Fixed Sym Gaussian 0.01" | L2: 0.01 | M2: 0.01 | N2: - | O2: -
A3: 2 | B3: 0 | C3: 0 | D3: 4.1303 | E3: 1.2633 | F3: pseudo-voigt | G3: 0.77 | H3: 0.29 | K3: Fixed Sym Gaussian 4.3" | L3: 1.82635 | M3: 1.82635 | N3: - | O3: - | Q3: From NewAthena Reference telescope design
A4: 3 | B4: 0 | C4: 0 | D4: 4.1303 | E4: 1.2633 | F4: pseudo-voigt | G4: 0.77 | H4: 0.29 | K4: Fixed Sym Gaussian 8" | L4: 3.39833 | M4: 3.39833 | N4: - | O4: -
A5: 4 | B5: 0 | C5: 0 | D5: 4.1303 | E5: 1.2633 | F5: pseudo-voigt | G5: 0.77 | H5: 0.29 | K5: Fixed Asym Gaussian 4.3" (ratio 4:1) | L5: 2.9637409 | M5: 0.74093523 | N5: - | O5: -
A6: 5 | B6: 0 | C6: 0 | D6: 4.1303 | E6: 1.2633 | F6: pseudo-voigt | G6: 0.77 | H6: 0.29 | K6: Fixed Asym Gaussian 8" (ratio 7:1) | L6: 5.7972051 | M6: 0.82817216 | N6: - | O6: -
A7: 6 | B7: 0 | C7: 0 | D7: 4.1303 | E7: 1.2633 | F7: pseudo-voigt | G7: 0.77 | H7: 0.29 | K7: Fixed Pseudo-Voigt 4.3" | L7: 2.22057 | M7: 0.679177 | N7: 0.77 | O7: 0.29
A8: 7 | B8: 0 | C8: 0 | D8: 4.1303 | E8: 1.2633 | F8: pseudo-voigt | G8: 0.77 | H8: 0.29 | K8: Fixed Pseudo-Voigt 8" | L8: 4.1303 | M8: 1.2633 | N8: 0.77 | O8: 0.29
A9: 8 | B9: 0 | C9: 0 | D9: 4.1303 | E9: 1.2633 | F9: pseudo-voigt | G9: 0.77 | H9: 0.29 | K9: 10% Variable Sym Gaussian 4.3" | L9: gamma (1.82635,10%*1.82635) | M9: gamma (1.82635,10%*1.82635) | N9: - | O9: -
A10: 9 | B10: 0 | C10: 0 | D10: 4.1303 | E10: 1.2633 | F10: pseudo-voigt | G10: 0.77 | H10: 0.29 | K10: 30% Variable Sym Gaussian 4.3" | L10: gamma (1.82635,30%*1.82635) | M10: gamma (1.82635,30%*1.82635) | N10: - | O10: -
A11: 10 | B11: 0 | C11: 0 | D11: 4.1303 | E11: 1.2633 | F11: pseudo-voigt | G11: 0.77 | H11: 0.29 | K11: 50% Variable Sym Gaussian 4.3" | L11: gamma (1.82635,50%*1.82635) | M11: gamma (1.82635,50%*1.82635) | N11: - | O11: -
A12: 11 | B12: 0 | C12: 0 | D12: 4.1303 | E12: 1.2633 | F12: pseudo-voigt | G12: 0.77 | H12: 0.29 | K12: 10% Variable Sym Gaussian 8" | L12: gamma (3.39833,10%*3.39833) | M12: gamma (3.39833,10%*3.39833) | N12: - | O12: -
A13: 12 | B13: 0 | C13: 0 | D13: 4.1303 | E13: 1.2633 | F13: pseudo-voigt | G13: 0.77 | H13: 0.29 | K13: 30% Variable Sym Gaussian 8" | L13: gamma (3.39833,30%*3.39833) | M13: gamma (3.39833,30%*3.39833) | N13: - | O13: -
A14: 13 | B14: 0 | C14: 0 | D14: 4.1303 | E14: 1.2633 | F14: pseudo-voigt | G14: 0.77 | H14: 0.29 | K14: 50% Variable Sym Gaussian 8" | L14: gamma (3.39833,50%*3.39833) | M14: gamma (3.39833,50%*3.39833) | N14: - | O14: -
A15: 14 | B15: 0 | C15: 0 | D15: 4.1303 | E15: 1.2633 | F15: pseudo-voigt | G15: 0.77 | H15: 0.29 | K15: 10% Variable Asym Gaussian 4.3" (ratio 4:1) | L15: gamma (2.96374,10%*2.96374) | M15: gamma (0.74093,10%*0.74093) | N15: - | O15: -
A16: 15 | B16: 0 | C16: 0 | D16: 4.1303 | E16: 1.2633 | F16: pseudo-voigt | G16: 0.77 | H16: 0.29 | K16: 30% Variable Asym Gaussian 4.3" (ratio 4:1) | L16: gamma (2.96374,30%*2.96374) | M16: gamma (0.74093,30%*0.74093) | N16: - | O16: -
A17: 16 | B17: 0 | C17: 0 | D17: 4.1303 | E17: 1.2633 | F17: pseudo-voigt | G17: 0.77 | H17: 0.29 | K17: 50% Variable Asym Gaussian 4.3" (ratio 4:1) | L17: gamma (2.96374,50%*2.96374) | M17: gamma (0.74093,50%*0.74093) | N17: - | O17: -
A18: 17 | B18: 0 | C18: 0 | D18: 4.1303 | E18: 1.2633 | F18: pseudo-voigt | G18: 0.77 | H18: 0.29 | K18: 10% Variable Asym Gaussian 8" (ratio 7:1) | L18: gamma (5.79720,10%*5.79720) | M18: gamma (0.82817,10%*0.82817) | N18: - | O18: -
A19: 18 | B19: 0 | C19: 0 | D19: 4.1303 | E19: 1.2633 | F19: pseudo-voigt | G19: 0.77 | H19: 0.29 | K19: 30% Variable Asym Gaussian 8" (ratio 7:1) | L19: gamma (5.79720,30%*5.79720) | M19: gamma (0.82817,30%*0.82817) | N19: - | O19: -
A20: 19 | B20: 0 | C20: 0 | D20: 4.1303 | E20: 1.2633 | F20: pseudo-voigt | G20: 0.77 | H20: 0.29 | K20: 50% Variable Asym Gaussian 8" (ratio 7:1) | L20: gamma (5.79720,50%*5.79720) | M20: gamma (0.82817,50%*0.82817) | N20: - | O20: -
... A26: 25 | B26: 0 | C26: 0 | D26: 4.1303 | E26: 1.2633 | F26: pseudo-voigt | G26: 0.77 | H26: 0.29 | K26: 50% Variable Pseudo-Voigt 8" (alpha 10%) | L26: gamma (4.1303,50%*4.1303) | M26: gamma (1.2633,50%*1.2633) | N26: gamma(0.77,10%*0.77) | O26: gamma(0.29,10%*0.29)
A27: 26 | B27: 0 | C27: 0 | D27: 4.1303 | E27: 1.2633 | F27: pseudo-voigt | G27: 0.77 | H27: 0.29
A28: 27 | B28: 0 | C28: 0 | D28: 4.1303 | E28: 1.2633 | F28: pseudo-voigt | G28: 0.77 | H28: 0.29
A29: 28 | B29: 0 | C29: 0 | D29: 4.1303 | E29: 1.2633 | F29: pseudo-voigt | G29: 0.77 | H29: 0.29
A30: 29 | B30: 0 | C30: 0 | D30: 4.1303 | E30: 1.2633 | F30: pseudo-voigt | G30: 0.77 | H30: 0.29
A31: 30 | B31: 0 | C31: 0 | D31: 4.1303 | E31: 1.2633 | F31: pseudo-voigt | G31: 0.77 | H31: 0.29
A32: 31 | B32: 0 | C32: 0 | D32: 4.1303 | E32: 1.2633 | F32: pseudo-voigt | G32: 0.77 | H32: 0.29
A33: 32 | B33: 0 | C33: 0 | D33: 4.1303 | E33: 1.2633 | F33: pseudo-voigt | G33: 0.77 | H33: 0.29
A34: 33 | B34: 0 | C34: 0 | D34: 4.1303 | E34: 1.2633 | F34: pseudo-voigt | G34: 0.77 | H34: 0.29
A35: 34 | B35: 0 | C35: 0 | D35: 4.1303 | E35: 1.2633 | F35: pseudo-voigt | G35: 0.77 | H35: 0.29
A36: 35 | B36: 0 | C36: 0 | D36: 4.1303 | E36: 1.2633 | F36: pseudo-voigt | G36: 0.77 | H36: 0.29
A37: 36 | B37: 0 | C37: 0 | D37: 4.1303 | E37: 1.2633 | F37: pseudo-voigt | G37: 0.77 | H37: 0.29
A38: 37 | B38: 0 | C38: 0 | D38: 4.1303 | E38: 1.2633 | F38: pseudo-voigt | G38: 0.77 | H38: 0.29
... A601: 600 | B601: 0 | C601: 0 | D601: 4.1303 | E601: 1.2633 | F601: pseudo-voigt | G601: 0.77 | H601: 0.29

Sheet Alignment
A1: Position # | B1: d_align_rad [µm] | C1: d_align_azi [µm] | D1: d_align_z [µm] | E1: d_align_rotazi [arcsec] | F1: d_align_rotrad [arcsec] | G1: d_align_rotz [arcsec] | I1: Standard alignment distributions | J1: d_align_rad_ | K1: d_align_azi_ | L1: d_align_z_ | M1: d_align_rotazi_ | N1: d_align_rotrad_ | O1: d_align_rotz_ | Q1: From MLT documentation (2018) - max values assumed 3 sigma, % is assumed uniform distribution | R1: Unnamed: 5 | S1: Unnamed: 11
A2: 1 | B2: 0 | C2: 0 | D2: 0 | E2: 0 | F2: 0 | G2: 50 | I2: Standard medialario | J2: gaussian (0, 12/3) | K2: gaussian (0, 12/3) | L2: gaussian (0, (380+23+1500+93)/3) | M2: uniform (-30, 30) | N2: uniform (-120, 120) | O2: uniform (-9, 9)
A3: 2 | B3: 0 | C3: 0 | D3: 0 | E3: 0 | F3: 0 | G3: 50 | I3: 10% worse medialario | J3: gaussian (0, 12/3*110%) | K3: gaussian (0, 12/3*110%) | L3: gaussian (0, (380+23+1500+93)/3*110%) | M3: uniform (-30*110%, 30*110%) | N3: uniform (-120*110%, 120*110%) | O3: uniform (-9*110%, 9*110%)
A4: 3 | B4: 0 | C4: 0 | D4: 0 | E4: 0 | F4: 0 | G4: 50 | I4: 30% worse medialario | J4: gaussian (0, 12/3*130%) | K4: gaussian (0, 12/3*130%) | L4: gaussian (0, (380+23+1500+93)/3*130%) | M4: uniform (-30*130%, 30*130%) | N4: uniform (-120*130%, 120*130%) | O4: uniform (-9*130%, 9*130%)
A5: 4 | B5: 0 | C5: 0 | D5: 0 | E5: 0 | F5: 0 | G5: 50 | I5: 50% worse medialario | J5: gaussian (0, 12/3*150%) | K5: gaussian (0, 12/3*150%) | L5: gaussian (0, (380+23+1500+93)/3*150%) | M5: uniform (-30*150%, 30*150%) | N5: uniform (-120*150%, 120*150%) | O5: uniform (-9*150%, 9*150%)
A6: 5 | B6: 0 | C6: 0 | D6: 0 | E6: 0 | F6: 0 | G6: 50 | I6: 100% worse medialario | J6: gaussian (0, 12/3*200%) | K6: gaussian (0, 12/3*200%) | L6: gaussian (0, (380+23+1500+93)/3*200%) | M6: uniform (-30*200%, 30*200%) | N6: uniform (-120*200%, 120*200%) | O6: uniform (-9*200%, 9*200%)
A7: 6 | B7: 0 | C7: 0 | D7: 0 | E7: 0 | F7: 0 | G7: 50
A8: 7 | B8: 0 | C8: 0 | D8: 0 | E8: 0 | F8: 0 | G8: 50
A9: 8 | B9: 0 | C9: 0 | D9: 0 | E9: 0 | F9: 0 | G9: 50
A10: 9 | B10: 0 | C10: 0 | D10: 0 | E10: 0 | F10: 0 | G10: 50
A11: 10 | B11: 0 | C11: 0 | D11: 0 | E11: 0 | F11: 0 | G11: 50
A12: 11 | B12: 0 | C12: 0 | D12: 0 | E12: 0 | F12: 0 | G12: 50
A13: 12 | B13: 0 | C13: 0 | D13: 0 | E13: 0 | F13: 0 | G13: 50
A14: 13 | B14: 0 | C14: 0 | D14: 0 | E14: 0 | F14: 0 | G14: 50
A15: 14 | B15: 0 | C15: 0 | D15: 0 | E15: 0 | F15: 0 | G15: 50
A16: 15 | B16: 0 | C16: 0 | D16: 0 | E16: 0 | F16: 0 | G16: 50
A17: 16 | B17: 0 | C17: 0 | D17: 0 | E17: 0 | F17: 0 | G17: 50
A18: 17 | B18: 0 | C18: 0 | D18: 0 | E18: 0 | F18: 0 | G18: 50
... A601: 600 | B601: 0 | C601: 0 | D601: 0 | E601: 0 | F601: 0 | G601: 50

Sheet Gravity offload
A1: Position # | B1: d_grav_x [µm] | C1: d_grav_y [µm] | D1: d_grav_z [µm] | E1: d_grav_rotx [arcsec] | F1: d_grav_roty [arcsec] | G1: d_grav_rotz [arcsec] | I1: Standard alignment distributions | J1: d_grav_x_ | K1: d_grav_y_ | L1: d_grav_z_ | M1: d_grav_rotx_ | N1: d_grav_roty_ | O1: d_grav_rotz_ | U1: 1GX disX [µm] | V1: 1GX disY [µm] | W1: 1GX disZ [µm] | X1: 1GX rotX [arcsec] | Y1: 1GX rotY [arcsec] | Z1: 1GX rotZ [arcsec] | AA1: 1GY disX [µm] | AB1: 1GY disY [µm] | AC1: 1GY disZ [µm] | AD1: 1GY rotX [arcsec] | AE1: 1GY rotY [arcsec] | AF1: 1GY rotZ [arcsec] | AG1: 1GZ disX [µm] | AH1: 1GZ disY [µm] | AI1: 1GZ disZ [µm] | AJ1: 1GZ rotX [arcsec] | AK1: 1GZ rotY [arcsec] | AL1: 1GZ rotZ [arcsec]
A2: 1 | B2: 0 | C2: 0 | D2: 0 | E2: 120 | F2: 0 | G2: 0 | I2: GX | J2: U | K2: V | L2: W | M2: X | N2: Y | O2: Z | U2: -18.58871 | V2: -0.05507033 | W2: -2.0839711 | X2: -2.9602108 | Y2: -3.2343573 | Z2: -10.740646 | AA2: -1.3255328 | AB2: -18.164879 | AC2: 0.41699731 | AD2: 2.4414682 | AE2: 0.35403555 | AF2: 5.6369779 | AG2: 1.6037272 | AH2: -0.10678088 | AI2: -94.487488 | AJ2: 0.4567937 | AK2: 0.61296861 | AL2: -1.3888335
A3: 2 | B3: 0 | C3: 0 | D3: 0 | E3: 120 | F3: 0 | G3: 0 | I3: GY | J3: AA | K3: AB | L3: AC | M3: AD | N3: AE | O3: AF | U3: -15.112552 | V3: -1.1750112 | W3: -1.6408278 | X3: -0.49696921 | Y3: -2.094758 | Z3: -14.710421 | AA3: -2.575988 | AB3: -17.516275 | AC3: 0.71711701 | AD3: 1.9680426 | AE3: 0.05347824 | AF3: 3.6768094 | AG3: 2.4044212 | AH3: -0.77199516 | AI3: -94.60373 | AJ3: 1.8782741 | AK3: 3.9745618 | AL3: -2.7236585
A4: 3 | B4: 0 | C4: 0 | D4: 0 | E4: 120 | F4: 0 | G4: 0 | I4: GZ | J4: AG | K4: AH | L4: AI | M4: AJ | N4: AK | O4: AL | U4: -14.225165 | V4: -1.5800352 | W4: -1.6258441 | X4: -2.1421125 | Y4: -1.3542057 | Z4: 9.6651619 | AA4: -1.3186681 | AB4: -16.911163 | AC4: 1.4515669 | AD4: 4.329378 | AE4: -0.075622185 | AF4: -12.029276 | AG4: 2.2126294 | AH4: -1.0612004 | AI4: -94.539351 | AJ4: 0.42737779 | AK4: 0.14166445 | AL4: 3.7575866
A5: 4 | B5: 0 | C5: 0 | D5: 0 | E5: 120 | F5: 0 | G5: 0 | U5: -17.697866 | V5: -0.84364399 | W5: -1.2990941 | X5: -1.7274982 | Y5: -1.1571582 | Z5: 9.3580758 | AA5: 0.6066019 | AB5: -18.928496 | AC5: 1.738088 | AD5: 5.1042519 | AE5: -0.7203865 | AF5: -5.6288602 | AG5: 1.1239928 | AH5: -0.98576507 | AI5: -94.467011 | AJ5: -0.45868657 | AK5: -1.458067 | AL5: 2.6274738
A6: 5 | B6: 0 | C6: 0 | D6: 0 | E6: 120 | F6: 0 | G6: 0 | U6: -20.627641 | V6: -1.4712712 | W6: -2.0098895 | X6: -1.4030395 | Y6: -11.381494 | Z6: -9.4384348 | AA6: -1.9668897 | AB6: -21.964624 | AC6: 0.44143973 | AD6: 2.0220126 | AE6: 0.46833234 | AF6: 6.7423474 | AG6: 2.3283985 | AH6: -0.53419403 | AI6: -93.590606 | AJ6: 1.0492041 | AK6: 7.9264945 | AL6: -0.82043524
A7: 6 | B7: 0 | C7: 0 | D7: 0 | E7: 120 | F7: 0 | G7: 0 | U7: -15.90996 | V7: -3.6110576 | W7: -1.9250205 | X7: -0.061709504 | Y7: -2.060807 | Z7: -15.127308 | AA7: -3.9418348 | AB7: -20.817115 | AC7: 0.81674757 | AD7: 1.6855346 | AE7: 0.088056873 | AF7: 5.3715937 | AG7: 2.6867284 | AH7: -1.8410252 | AI7: -93.1992 | AJ7: 3.5044202 | AK7: 5.1434517 | AL7: -3.5514768
A8: 7 | B8: 0 | C8: 0 | D8: 0 | E8: 120 | F8: 0 | G8: 0 | U8: -15.534318 | V8: -2.6630894 | W8: -1.4388448 | X8: -4.8214381 | Y8: -8.9256273 | Z8: 12.100423 | AA8: -2.8309769 | AB8: -19.234599 | AC8: 1.3571049 | AD8: 5.7531362 | AE8: 5.21846 | AF8: -12.385575 | AG8: 3.2320826 | AH8: -1.4658238 | AI8: -93.365356 | AJ8: 3.7266751 | AK8: 8.6622812 | AL8: 4.9642698
A9: 8 | B9: 0 | C9: 0 | D9: 0 | E9: 120 | F9: 0 | G9: 0 | U9: -19.980855 | V9: -1.3722864 | W9: -1.2200174 | X9: -6.0373587 | Y9: -7.6299067 | Z9: 10.298832 | AA9: -0.98207109 | AB9: -22.27946 | AC9: 1.6442184 | AD9: 9.1301851 | AE9: 6.1139499 | AF9: -4.8426568 | AG9: 2.3175679 | AH9: -1.1138855 | AI9: -93.551791 | AJ9: 4.6908833 | AK9: 5.2672313 | AL9: 1.4206453
A10: 9 | B10: 0 | C10: 0 | D10: 0 | E10: 120 | F10: 0 | G10: 0 | U10: -32.145172 | V10: -1.7375565 | W10: -2.4398167 | X10: -0.68744842 | Y10: -11.629356 | Z10: -21.109315 | AA10: -1.4399453 | AB10: -27.617009 | AC10: 0.40350603 | AD10: 1.9098775 | AE10: -0.17620513 | AF10: 6.6804634 | AG10: 4.9260421 | AH10: -0.41615694 | AI10: -91.061598 | AJ10: 0.85288705 | AK10: 10.852122 | AL10: 0.57787903
A11: 10 | B11: 0 | C11: 0 | D11: 0 | E11: 120 | F11: 0 | G11: 0 | U11: -18.958251 | V11: -6.4375421 | W11: -2.2258395 | X11: 0.050133259 | Y11: -2.3803089 | Z11: -23.490683 | AA11: -5.5035859 | AB11: -24.773654 | AC11: 1.019135 | AD11: 1.7247371 | AE11: 0.46418809 | AF11: 8.0812209 | AG11: 4.5458415 | AH11: -1.9045773 | AI11: -90.811104 | AJ11: 4.5206978 | AK11: 7.8884608 | AL11: -0.46913823
A12: 11 | B12: 0 | C12: 0 | D12: 0 | E12: 120 | F12: 0 | G12: 0 | U12: -17.795475 | V12: -4.265274 | W12: -1.8296947 | X12: -4.037215 | Y12: -7.0155424 | Z12: 19.512923 | AA12: -4.5357115 | AB12: -23.828984 | AC12: 1.5711101 | AD12: 5.3832892 | AE12: 4.2803929 | AF12: -18.464641 | AG12: 4.6190551 | AH12: -2.4480809 | AI12: -90.942771 | AJ12: 5.0041144 | AK12: 9.9500146 | AL12: 1.5185969
A13: 12 | B13: 0 | C13: 0 | D13: 0 | E13: 120 | F13: 0 | G13: 0 | U13: -26.895186 | V13: 1.7389346 | W13: -1.3645685 | X13: -5.1352602 | Y13: -6.2715193 | Z13: 16.288967 | AA13: 0.71722651 | AB13: -32.528234 | AC13: 2.0478844 | AD13: 8.4866213 | AE13: 5.2566591 | AF13: -15.058263 | AG13: 3.5186717 | AH13: -3.5791439 | AI13: -91.047343 | AJ13: 8.0203946 | AK13: 7.235612 | AL13: -0.27053349
A14: 13 | B14: 0 | C14: 0 | D14: 0 | E14: 120 | F14: 0 | G14: 0 | U14: -39.779334 | V14: -1.184954 | W14: -2.7874278 | X14: -0.8145719 | Y14: -10.09276 | Z14: -39.186877 | AA14: -1.5007556 | AB14: -32.146737 | AC14: 0.49672186 | AD14: 1.8727532 | AE14: -0.071782275 | AF14: 9.3312076 | AG14: 6.1577568 | AH14: -1.4731726 | AI14: -88.058548 | AJ14: 1.5540725 | AK14: 13.555051 | AL14: 1.6075856
A15: 14 | B15: 0 | C15: 0 | D15: 0 | E15: 120 | F15: 0 | G15: 0 | U15: -28.859286 | V15: -5.8557225 | W15: -2.6682756 | X15: -1.2467065 | Y15: -7.3694392 | Z15: -25.172441 | AA15: -5.1199157 | AB15: -31.300953 | AC15: 0.90616748 | AD15: 2.0092864 | AE15: 0.74789786 | AF15: 11.510156 | AG15: 5.9028242 | AH15: -1.6737719 | AI15: -87.819448 | AJ15: 3.6602781 | AK15: 12.63326 | AL15: 0.46143486
A16: 15 | B16: 0 | C16: 0 | D16: 0 | E16: 120 | F16: 0 | G16: 0 | U16: -21.074504 | V16: -7.5331211 | W16: -2.2845431 | X16: -1.6797148 | Y16: -4.5137376 | Z16: -2.33514 | AA16: -7.0861662 | AB16: -29.277074 | AC16: 1.4263597 | AD16: 3.3726559 | AE16: 2.1073494 | AF16: -5.3295762 | AG16: 5.7610239 | AH16: -2.6281303 | AI16: -87.659508 | AJ16: 6.3790248 | AK16: 11.371863 | AL16: 0.4938747
... A601: 600 | B601: 0 | C601: 0 | D601: 0 | E601: 120 | F601: 0 | G601: 0 | U601: -19.332181 | V601: -0.17367578 | W601: -2.454952 | X601: 0.50871253 | Y601: -5.0893987 | Z601: 2.1070216 | AA601: 0.61696946 | AB601: -12.696 | AC601: -0.11238612 | AD601: 0.83917196 | AE601: -1.1745227 | AF601: 1.3945464 | AG601: 1.241618 | AH601: 2.0875927 | AI601: -18.502937 | AJ601: -1.9313613 | AK601: 4.9889287 | AL601: 2.6942395

Sheet Thermal
A1: Position # | B1: d_therm_x [µm] | C1: d_therm_y [µm] | D1: d_therm_z [µm] | E1: d_therm_rotx [arcsec] | F1: d_therm_roty [arcsec] | G1: d_therm_rotz [arcsec] | I1: Standard alignment distributions | J1: d_therm_x_ | K1: d_therm_y_ | L1: d_therm_z_ | M1: d_therm_rotx_ | N1: d_therm_roty_ | O1: d_therm_rotz_ | U1: Thermal Load Case TC01 (0° FMS Tilt) disX [µm] | V1: Thermal Load Case TC01 (0° FMS Tilt) disY [µm] | W1: Thermal Load Case TC01 (0° FMS Tilt) disZ [µm] | X1: Thermal Load Case TC01 (0° FMS Tilt) rotX [arcsec] | Y1: Thermal Load Case TC01 (0° FMS Tilt) rotY [arcsec] | Z1: Thermal Load Case TC01 (0° FMS Tilt) rotZ [arcsec] | AA1: Thermal Load Case TC02 (+30° FMS Tilt) disX [µm] | AB1: Thermal Load Case TC02 (+30° FMS Tilt) disY [µm] | AC1: Thermal Load Case TC02 (+30° FMS Tilt) disZ [µm] | AD1: Thermal Load Case TC02 (+30° FMS Tilt) rotX [arcsec] | AE1: Thermal Load Case TC02 (+30° FMS Tilt) rotY [arcsec] | AF1: Thermal Load Case TC02 (+30° FMS Tilt) rotZ [arcsec] | AG1: Thermal Load Case TC03 (-30° FMS Tilt) disX [µm] | AH1: Thermal Load Case TC03 (-30° FMS Tilt) disY [µm] | AI1: Thermal Load Case TC03 (-30° FMS Tilt) disZ [µm] | AJ1: Thermal Load Case TC03 (-30° FMS Tilt) rotX [arcsec] | AK1: Thermal Load Case TC03 (-30° FMS Tilt) rotY [arcsec] | AL1: Thermal Load Case TC03 (-30° FMS Tilt) rotZ [arcsec]
A2: 1 | B2: 0 | C2: 0 | D2: 0 | E2: -120 | F2: 0 | G2: 0 | I2: 0 deg FMS Tilt | J2: U | K2: V | L2: W | M2: X | N2: Y | O2: Z | U2: -3.8066778 | V2: 0.22637149 | W2: 4.7915206 | X2: 2.0449545 | Y2: 9.701933 | Z2: -2.4616056 | AA2: -3.9816873 | AB2: 0.19947733 | AC2: 5.2359768 | AD2: 2.2470485 | AE2: 10.841087 | AF2: -2.3420322 | AG2: -4.3212135 | AH2: 0.23987976 | AI2: 5.9159129 | AJ2: 2.5538772 | AK2: 12.53887 | AL2: -2.3662373
A3: 2 | B3: 0 | C3: 0 | D3: 0 | E3: -120 | F3: 0 | G3: 0 | I3: 30 deg FMS Tilt | J3: AA | K3: AB | L3: AC | M3: AD | N3: AE | O3: AF | U3: -2.8274579 | V3: 0.52698884 | W3: 4.8884306 | X3: 4.1921996 | Y3: 8.1554014 | Z3: -1.8350676 | AA3: -3.0303229 | AB3: 0.53719387 | AC3: 5.3275011 | AD3: 4.6121681 | AE3: 9.0901787 | AF3: -1.5188059 | AG3: -3.3407764 | AH3: 0.62221504 | AI3: 6.0041448 | AJ3: 5.233475 | AK3: 10.461773 | AL3: -1.3492641
A4: 3 | B4: 0 | C4: 0 | D4: 0 | E4: -120 | F4: 0 | G4: 0 | I4: 30*-1 deg FMS Tilt | J4: AG | K4: AH | L4: AI | M4: AJ | N4: AK | O4: AL | U4: -1.7987873 | V4: 1.428479 | W4: 5.1072909 | X4: 7.1408154 | Y4: 8.4344472 | Z4: 3.4303523 | AA4: -1.9649101 | AB4: 1.5351071 | AC4: 5.5450182 | AD4: 7.8681528 | AE4: 9.3949064 | AF4: 3.5853327 | AG4: -2.1408831 | AH4: 1.7011182 | AI4: 6.2300162 | AJ4: 8.9620382 | AK4: 10.791217 | AL4: 3.5983646
A5: 4 | B5: 0 | C5: 0 | D5: 0 | E5: -120 | F5: 0 | G5: 0 | U5: -1.7116333 | V5: 2.2931226 | W5: 5.4540887 | X5: 9.0476932 | Y5: 7.7712348 | Z5: 1.878407 | AA5: -1.8275681 | AB5: 2.4671348 | AC5: 5.9053976 | AD5: 10.009225 | AE5: 8.6833049 | AF5: 1.9723991 | AG5: -1.9097949 | AH5: 2.6533269 | AI5: 6.6198508 | AJ5: 11.486019 | AK5: 10.0052 | AL5: 2.0237104
A6: 5 | B6: 0 | C6: 0 | D6: 0 | E6: -120 | F6: 0 | G6: 0 | U6: -3.9573646 | V6: -0.19858261 | W6: 7.7800883 | X6: 3.5677771 | Y6: 12.275618 | Z6: -2.5421605 | AA6: -4.1121062 | AB6: -0.2569682 | AC6: 8.5780155 | AD6: 3.8668827 | AE6: 13.700344 | AF6: -2.4964392 | AG6: -4.4347496 | AH6: -0.21887576 | AI6: 9.779345 | AJ6: 4.3264233 | AK6: 15.807614 | AL6: -2.6513583
A7: 6 | B7: 0 | C7: 0 | D7: 0 | E7: -120 | F7: 0 | G7: 0 | U7: -2.4469388 | V7: -0.30216001 | W7: 8.1815972 | X7: 6.9073151 | Y7: 12.437262 | Z7: -3.5602846 | AA7: -2.5912608 | AB7: -0.33133466 | AC7: 8.9911236 | AD7: 7.5394525 | AE7: 13.834947 | AF7: -3.3780273 | AG7: -2.7923845 | AH7: -0.2592694 | AI7: 10.193252 | AJ7: 8.4896433 | AK7: 15.913291 | AL7: -3.4858713
A8: 7 | B8: 0 | C8: 0 | D8: 0 | E8: -120 | F8: 0 | G8: 0 | U8: -1.4409867 | V8: 0.98522772 | W8: 8.7307097 | X8: 9.3304114 | Y8: 10.337152 | Z8: 5.8630522 | AA8: -1.5720098 | AB8: 1.0526768 | AC8: 9.5565092 | AD8: 10.297313 | AE8: 11.492641 | AF8: 6.1781346 | AG8: -1.6354417 | AH8: 1.1856073 | AI8: 10.789332 | AJ8: 11.765204 | AK8: 13.188339 | AL8: 6.3675468
