Workbook

Sheet MM configuration
A1: Position # | B1: Petal # | C1: Row # | D1: MM # | E1: x_MM [m] | F1: y_MM [m] | G1: z_MM [m] | H1: r_MM [m]
A2: 1 | B2: 1 | C2: 1 | D2: 4 | E2: 0.043401333 | F2: 0.271106 | G2: 0.0031507873 | H2: 0.27455808
A3: 2 | B3: 1 | C3: 1 | D3: 104 | E3: 0.10741849 | F3: 0.25267253 | G3: 0.0031507873 | H3: 0.27455808
A4: 3 | B4: 1 | C4: 1 | D4: 301 | E4: 0.16511158 | F4: 0.21936341 | G4: 0.0031507873 | H4: 0.27455808
A5: 4 | B5: 1 | C5: 1 | D5: 202 | E5: 0.21308402 | F5: 0.17313966 | G5: 0.0031507873 | H5: 0.27455808
A6: 5 | B6: 1 | C6: 2 | D6: 506 | E6: 0.05212616 | F6: 0.33875848 | G6: 0.0049052246 | H6: 0.34274545
A7: 6 | B7: 1 | C7: 2 | D7: 505 | E7: 0.13345813 | F7: 0.31569507 | G7: 0.0049052246 | H7: 0.34274545
A8: 7 | B8: 1 | C8: 2 | D8: 7 | E8: 0.20667088 | F8: 0.27342566 | G8: 0.0049052246 | H8: 0.34274545
A9: 8 | B9: 1 | C9: 2 | D9: 206 | E9: 0.26731037 | F9: 0.21452182 | G9: 0.0049052246 | H9: 0.34274545
A10: 9 | B10: 1 | C10: 3 | D10: 310 | E10: 0.060914095 | F10: 0.40639176 | G10: 0.0070475585 | H10: 0.41093161
A11: 10 | B11: 1 | C11: 3 | D11: 512 | E11: 0.15951698 | F11: 0.37870717 | G11: 0.0070475585 | H11: 0.41093161
A12: 11 | B12: 1 | C12: 3 | D12: 410 | E12: 0.24821154 | F12: 0.32749934 | G12: 0.0070475585 | H12: 0.41093161
A13: 12 | B13: 1 | C13: 3 | D13: 210 | E13: 0.32148854 | F13: 0.25594903 | G13: 0.0070475585 | H13: 0.41093161
... A601: 600 | B601: 6 | C601: 15 | D601: 192 | E601: -0.079467227 | F601: 1.2219025 | G601: 0.06264642 | H601: 1.2244839

Sheet A_eff
A1: MM # | B1: A_eff_base | C1: A_eff_adjusted | D1: Standard distributions A_eff | E1: Values | J1: A_eff @0.2 keV | K1: A_eff @0.35 keV | L1: A_eff @1 keV | M1: A_eff @2 keV | N1: A_eff @4 keV | O1: A_eff @7 keV | P1: A_eff @10 keV | Q1: A_eff @12 keV
A2: 1 | B2: 0.0010419267 | C2: 0.0010419267 | D2: 0.2 keV | E2: J | J2: =VLOOKUP(_xlfn.XLOOKUP($A2,'MM configuration'!$D$2:$D$601,'MM configuration'!$C$2:$C$601),$S$24:$AA$38,2) | K2: =VLOOKUP(_xlfn.XLOOKUP($A2,'MM configuration'!$D$2:$D$601,'MM configuration'!$C$2:$C$601),$S$24:$AA$38,3) | L2: =VLOOKUP(_xlfn.XLOOKUP($A2,'MM configuration'!$D$2:$D$601,'MM configuration'!$C$2:$C$601),$S$24:$AA$38,4) | M2: =VLOOKUP(_xlfn.XLOOKUP($A2,'MM configuration'!$D$2:$D$601,'MM configuration'!$C$2:$C$601),$S$24:$AA$38,5) | N2: =VLOOKUP(_xlfn.XLOOKUP($A2,'MM configuration'!$D$2:$D$601,'MM configuration'!$C$2:$C$601),$S$24:$AA$38,6) | O2: =VLOOKUP(_xlfn.XLOOKUP($A2,'MM configuration'!$D$2:$D$601,'MM configuration'!$C$2:$C$601),$S$24:$AA$38,7) | P2: =VLOOKUP(_xlfn.XLOOKUP($A2,'MM configuration'!$D$2:$D$601,'MM configuration'!$C$2:$C$601),$S$24:$AA$38,8) | Q2: =VLOOKUP(_xlfn.XLOOKUP($A2,'MM configuration'!$D$2:$D$601,'MM configuration'!$C$2:$C$601),$S$24:$AA$38,9) | R2: From effective area budget (05/02/2025). It includes the reductions due to losses at MM level, 7% losses at MAM level and the also the ESA system margin) - results in green
A3: 2 | B3: 0.0010419267 | C3: 0.0010419267 | D3: 0.35 keV | E3: K | J3: =VLOOKUP(_xlfn.XLOOKUP($A3,'MM configuration'!$D$2:$D$601,'MM configuration'!$C$2:$C$601),$S$24:$AA$38,2) | K3: =VLOOKUP(_xlfn.XLOOKUP($A3,'MM configuration'!$D$2:$D$601,'MM configuration'!$C$2:$C$601),$S$24:$AA$38,3) | L3: =VLOOKUP(_xlfn.XLOOKUP($A3,'MM configuration'!$D$2:$D$601,'MM configuration'!$C$2:$C$601),$S$24:$AA$38,4) | M3: =VLOOKUP(_xlfn.XLOOKUP($A3,'MM configuration'!$D$2:$D$601,'MM configuration'!$C$2:$C$601),$S$24:$AA$38,5) | N3: =VLOOKUP(_xlfn.XLOOKUP($A3,'MM configuration'!$D$2:$D$601,'MM configuration'!$C$2:$C$601),$S$24:$AA$38,6) | O3: =VLOOKUP(_xlfn.XLOOKUP($A3,'MM configuration'!$D$2:$D$601,'MM configuration'!$C$2:$C$601),$S$24:$AA$38,7) | P3: =VLOOKUP(_xlfn.XLOOKUP($A3,'MM configuration'!$D$2:$D$601,'MM configuration'!$C$2:$C$601),$S$24:$AA$38,8) | Q3: =VLOOKUP(_xlfn.XLOOKUP($A3,'MM configuration'!$D$2:$D$601,'MM configuration'!$C$2:$C$601),$S$24:$AA$38,9) | R3: Per MM type 09022026 (With Pt/C coating and 1.86 mm rib spacing)
A4: 3 | B4: 0.0010419267 | C4: 0.0010419267 | D4: 1 keV | E4: L | J4: =VLOOKUP(_xlfn.XLOOKUP($A4,'MM configuration'!$D$2:$D$601,'MM configuration'!$C$2:$C$601),$S$24:$AA$38,2) | K4: =VLOOKUP(_xlfn.XLOOKUP($A4,'MM configuration'!$D$2:$D$601,'MM configuration'!$C$2:$C$601),$S$24:$AA$38,3) | L4: =VLOOKUP(_xlfn.XLOOKUP($A4,'MM configuration'!$D$2:$D$601,'MM configuration'!$C$2:$C$601),$S$24:$AA$38,4) | M4: =VLOOKUP(_xlfn.XLOOKUP($A4,'MM configuration'!$D$2:$D$601,'MM configuration'!$C$2:$C$601),$S$24:$AA$38,5) | N4: =VLOOKUP(_xlfn.XLOOKUP($A4,'MM configuration'!$D$2:$D$601,'MM configuration'!$C$2:$C$601),$S$24:$AA$38,6) | O4: =VLOOKUP(_xlfn.XLOOKUP($A4,'MM configuration'!$D$2:$D$601,'MM configuration'!$C$2:$C$601),$S$24:$AA$38,7) | P4: =VLOOKUP(_xlfn.XLOOKUP($A4,'MM configuration'!$D$2:$D$601,'MM configuration'!$C$2:$C$601),$S$24:$AA$38,8) | Q4: =VLOOKUP(_xlfn.XLOOKUP($A4,'MM configuration'!$D$2:$D$601,'MM configuration'!$C$2:$C$601),$S$24:$AA$38,9) | S4: Energies | T4: 0.2 keV | U4: 0.35 keV | V4: 1 keV | W4: 2 keV | X4: 4 keV | Y4: 7 keV | Z4: 10 keV | AA4: 12 keV
A5: 4 | B5: 0.0010419267 | C5: 0.0010419267 | D5: 2 keV | E5: M | J5: =VLOOKUP(_xlfn.XLOOKUP($A5,'MM configuration'!$D$2:$D$601,'MM configuration'!$C$2:$C$601),$S$24:$AA$38,2) | K5: =VLOOKUP(_xlfn.XLOOKUP($A5,'MM configuration'!$D$2:$D$601,'MM configuration'!$C$2:$C$601),$S$24:$AA$38,3) | L5: =VLOOKUP(_xlfn.XLOOKUP($A5,'MM configuration'!$D$2:$D$601,'MM configuration'!$C$2:$C$601),$S$24:$AA$38,4) | M5: =VLOOKUP(_xlfn.XLOOKUP($A5,'MM configuration'!$D$2:$D$601,'MM configuration'!$C$2:$C$601),$S$24:$AA$38,5) | N5: =VLOOKUP(_xlfn.XLOOKUP($A5,'MM configuration'!$D$2:$D$601,'MM configuration'!$C$2:$C$601),$S$24:$AA$38,6) | O5: =VLOOKUP(_xlfn.XLOOKUP($A5,'MM configuration'!$D$2:$D$601,'MM configuration'!$C$2:$C$601),$S$24:$AA$38,7) | P5: =VLOOKUP(_xlfn.XLOOKUP($A5,'MM configuration'!$D$2:$D$601,'MM configuration'!$C$2:$C$601),$S$24:$AA$38,8) | Q5: =VLOOKUP(_xlfn.XLOOKUP($A5,'MM configuration'!$D$2:$D$601,'MM configuration'!$C$2:$C$601),$S$24:$AA$38,9) | R5: Row | S5: System Margin | T5: 0.0968 | U5: 0.0703 | V5: 0.0704 | W5: 0.0466 | X5: -0.0219 | Y5: 0.0187 | Z5: 0.0187 | AA5: 0.0187
A6: 5 | B6: 0.0015106 | C6: 0.0015106 | D6: 4 keV | E6: N | J6: =VLOOKUP(_xlfn.XLOOKUP($A6,'MM configuration'!$D$2:$D$601,'MM configuration'!$C$2:$C$601),$S$24:$AA$38,2) | K6: =VLOOKUP(_xlfn.XLOOKUP($A6,'MM configuration'!$D$2:$D$601,'MM configuration'!$C$2:$C$601),$S$24:$AA$38,3) | L6: =VLOOKUP(_xlfn.XLOOKUP($A6,'MM configuration'!$D$2:$D$601,'MM configuration'!$C$2:$C$601),$S$24:$AA$38,4) | M6: =VLOOKUP(_xlfn.XLOOKUP($A6,'MM configuration'!$D$2:$D$601,'MM configuration'!$C$2:$C$601),$S$24:$AA$38,5) | N6: =VLOOKUP(_xlfn.XLOOKUP($A6,'MM configuration'!$D$2:$D$601,'MM configuration'!$C$2:$C$601),$S$24:$AA$38,6) | O6: =VLOOKUP(_xlfn.XLOOKUP($A6,'MM configuration'!$D$2:$D$601,'MM configuration'!$C$2:$C$601),$S$24:$AA$38,7) | P6: =VLOOKUP(_xlfn.XLOOKUP($A6,'MM configuration'!$D$2:$D$601,'MM configuration'!$C$2:$C$601),$S$24:$AA$38,8) | Q6: =VLOOKUP(_xlfn.XLOOKUP($A6,'MM configuration'!$D$2:$D$601,'MM configuration'!$C$2:$C$601),$S$24:$AA$38,9) | R6: 1 | S6: 24 | T6: 0.0274 | U6: 0.0248 | V6: 0.0269 | W6: 0.0271 | X6: 0.0261 | Y6: 0.0257 | Z6: 0.0198 | AA6: 0.0093
A7: 6 | B7: 0.0015106 | C7: 0.0015106 | D7: 7 keV | E7: O | J7: =VLOOKUP(_xlfn.XLOOKUP($A7,'MM configuration'!$D$2:$D$601,'MM configuration'!$C$2:$C$601),$S$24:$AA$38,2) | K7: =VLOOKUP(_xlfn.XLOOKUP($A7,'MM configuration'!$D$2:$D$601,'MM configuration'!$C$2:$C$601),$S$24:$AA$38,3) | L7: =VLOOKUP(_xlfn.XLOOKUP($A7,'MM configuration'!$D$2:$D$601,'MM configuration'!$C$2:$C$601),$S$24:$AA$38,4) | M7: =VLOOKUP(_xlfn.XLOOKUP($A7,'MM configuration'!$D$2:$D$601,'MM configuration'!$C$2:$C$601),$S$24:$AA$38,5) | N7: =VLOOKUP(_xlfn.XLOOKUP($A7,'MM configuration'!$D$2:$D$601,'MM configuration'!$C$2:$C$601),$S$24:$AA$38,6) | O7: =VLOOKUP(_xlfn.XLOOKUP($A7,'MM configuration'!$D$2:$D$601,'MM configuration'!$C$2:$C$601),$S$24:$AA$38,7) | P7: =VLOOKUP(_xlfn.XLOOKUP($A7,'MM configuration'!$D$2:$D$601,'MM configuration'!$C$2:$C$601),$S$24:$AA$38,8) | Q7: =VLOOKUP(_xlfn.XLOOKUP($A7,'MM configuration'!$D$2:$D$601,'MM configuration'!$C$2:$C$601),$S$24:$AA$38,9) | R7: 2 | S7: 24 | T7: 0.04 | U7: 0.0353 | V7: 0.039 | W7: 0.0391 | X7: 0.0366 | Y7: 0.0315 | Z7: 0.0201 | AA7: 0.0026
A8: 7 | B8: 0.0015106 | C8: 0.0015106 | D8: 10 keV | E8: P | J8: =VLOOKUP(_xlfn.XLOOKUP($A8,'MM configuration'!$D$2:$D$601,'MM configuration'!$C$2:$C$601),$S$24:$AA$38,2) | K8: =VLOOKUP(_xlfn.XLOOKUP($A8,'MM configuration'!$D$2:$D$601,'MM configuration'!$C$2:$C$601),$S$24:$AA$38,3) | L8: =VLOOKUP(_xlfn.XLOOKUP($A8,'MM configuration'!$D$2:$D$601,'MM configuration'!$C$2:$C$601),$S$24:$AA$38,4) | M8: =VLOOKUP(_xlfn.XLOOKUP($A8,'MM configuration'!$D$2:$D$601,'MM configuration'!$C$2:$C$601),$S$24:$AA$38,5) | N8: =VLOOKUP(_xlfn.XLOOKUP($A8,'MM configuration'!$D$2:$D$601,'MM configuration'!$C$2:$C$601),$S$24:$AA$38,6) | O8: =VLOOKUP(_xlfn.XLOOKUP($A8,'MM configuration'!$D$2:$D$601,'MM configuration'!$C$2:$C$601),$S$24:$AA$38,7) | P8: =VLOOKUP(_xlfn.XLOOKUP($A8,'MM configuration'!$D$2:$D$601,'MM configuration'!$C$2:$C$601),$S$24:$AA$38,8) | Q8: =VLOOKUP(_xlfn.XLOOKUP($A8,'MM configuration'!$D$2:$D$601,'MM configuration'!$C$2:$C$601),$S$24:$AA$38,9) | R8: 3 | S8: 24 | T8: 0.0528 | U8: 0.0456 | V8: 0.0506 | W8: 0.0513 | X8: 0.0447 | Y8: 0.0317 | Z8: 0.0072 | AA8: 0
A9: 8 | B9: 0.0015106 | C9: 0.0015106 | D9: 12 keV | E9: Q | J9: =VLOOKUP(_xlfn.XLOOKUP($A9,'MM configuration'!$D$2:$D$601,'MM configuration'!$C$2:$C$601),$S$24:$AA$38,2) | K9: =VLOOKUP(_xlfn.XLOOKUP($A9,'MM configuration'!$D$2:$D$601,'MM configuration'!$C$2:$C$601),$S$24:$AA$38,3) | L9: =VLOOKUP(_xlfn.XLOOKUP($A9,'MM configuration'!$D$2:$D$601,'MM configuration'!$C$2:$C$601),$S$24:$AA$38,4) | M9: =VLOOKUP(_xlfn.XLOOKUP($A9,'MM configuration'!$D$2:$D$601,'MM configuration'!$C$2:$C$601),$S$24:$AA$38,5) | N9: =VLOOKUP(_xlfn.XLOOKUP($A9,'MM configuration'!$D$2:$D$601,'MM configuration'!$C$2:$C$601),$S$24:$AA$38,6) | O9: =VLOOKUP(_xlfn.XLOOKUP($A9,'MM configuration'!$D$2:$D$601,'MM configuration'!$C$2:$C$601),$S$24:$AA$38,7) | P9: =VLOOKUP(_xlfn.XLOOKUP($A9,'MM configuration'!$D$2:$D$601,'MM configuration'!$C$2:$C$601),$S$24:$AA$38,8) | Q9: =VLOOKUP(_xlfn.XLOOKUP($A9,'MM configuration'!$D$2:$D$601,'MM configuration'!$C$2:$C$601),$S$24:$AA$38,9) | R9: 4 | S9: 30 | T9: 0.061 | U9: 0.0517 | V9: 0.0586 | W9: 0.0586 | X9: 0.0466 | Y9: 0.0273 | Z9: 0.0001 | AA9: 0
A10: 9 | B10: 0.0019599067 | C10: 0.0019169579 | D10: Variable 5% 0.2 keV | E10: gaussian(J,5%*J) | J10: =VLOOKUP(_xlfn.XLOOKUP($A10,'MM configuration'!$D$2:$D$601,'MM configuration'!$C$2:$C$601),$S$24:$AA$38,2) | K10: =VLOOKUP(_xlfn.XLOOKUP($A10,'MM configuration'!$D$2:$D$601,'MM configuration'!$C$2:$C$601),$S$24:$AA$38,3) | L10: =VLOOKUP(_xlfn.XLOOKUP($A10,'MM configuration'!$D$2:$D$601,'MM configuration'!$C$2:$C$601),$S$24:$AA$38,4) | M10: =VLOOKUP(_xlfn.XLOOKUP($A10,'MM configuration'!$D$2:$D$601,'MM configuration'!$C$2:$C$601),$S$24:$AA$38,5) | N10: =VLOOKUP(_xlfn.XLOOKUP($A10,'MM configuration'!$D$2:$D$601,'MM configuration'!$C$2:$C$601),$S$24:$AA$38,6) | O10: =VLOOKUP(_xlfn.XLOOKUP($A10,'MM configuration'!$D$2:$D$601,'MM configuration'!$C$2:$C$601),$S$24:$AA$38,7) | P10: =VLOOKUP(_xlfn.XLOOKUP($A10,'MM configuration'!$D$2:$D$601,'MM configuration'!$C$2:$C$601),$S$24:$AA$38,8) | Q10: =VLOOKUP(_xlfn.XLOOKUP($A10,'MM configuration'!$D$2:$D$601,'MM configuration'!$C$2:$C$601),$S$24:$AA$38,9) | R10: 5 | S10: 30 | T10: 0.0746 | U10: 0.0608 | V10: 0.0697 | W10: 0.0693 | X10: 0.0469 | Y10: 0.019 | Z10: 0.0001 | AA10: 0
A11: 10 | B11: 0.0019599067 | C11: 0.0019169579 | D11: Variable 10% 0.2 keV | E11: gaussian(J,10%*J) | J11: =VLOOKUP(_xlfn.XLOOKUP($A11,'MM configuration'!$D$2:$D$601,'MM configuration'!$C$2:$C$601),$S$24:$AA$38,2) | K11: =VLOOKUP(_xlfn.XLOOKUP($A11,'MM configuration'!$D$2:$D$601,'MM configuration'!$C$2:$C$601),$S$24:$AA$38,3) | L11: =VLOOKUP(_xlfn.XLOOKUP($A11,'MM configuration'!$D$2:$D$601,'MM configuration'!$C$2:$C$601),$S$24:$AA$38,4) | M11: =VLOOKUP(_xlfn.XLOOKUP($A11,'MM configuration'!$D$2:$D$601,'MM configuration'!$C$2:$C$601),$S$24:$AA$38,5) | N11: =VLOOKUP(_xlfn.XLOOKUP($A11,'MM configuration'!$D$2:$D$601,'MM configuration'!$C$2:$C$601),$S$24:$AA$38,6) | O11: =VLOOKUP(_xlfn.XLOOKUP($A11,'MM configuration'!$D$2:$D$601,'MM configuration'!$C$2:$C$601),$S$24:$AA$38,7) | P11: =VLOOKUP(_xlfn.XLOOKUP($A11,'MM configuration'!$D$2:$D$601,'MM configuration'!$C$2:$C$601),$S$24:$AA$38,8) | Q11: =VLOOKUP(_xlfn.XLOOKUP($A11,'MM configuration'!$D$2:$D$601,'MM configuration'!$C$2:$C$601),$S$24:$AA$38,9) | R11: 6 | S11: 36 | T11: 0.0832 | U11: 0.066 | V11: 0.0767 | W11: 0.0754 | X11: 0.04 | Y11: 0.0046 | Z11: 0 | AA11: 0
A12: 11 | B12: 0.0019599067 | C12: 0.0019169579 | D12: Variable 20% 0.2 keV | E12: gaussian(J,20%*J) | J12: =VLOOKUP(_xlfn.XLOOKUP($A12,'MM configuration'!$D$2:$D$601,'MM configuration'!$C$2:$C$601),$S$24:$AA$38,2) | K12: =VLOOKUP(_xlfn.XLOOKUP($A12,'MM configuration'!$D$2:$D$601,'MM configuration'!$C$2:$C$601),$S$24:$AA$38,3) | L12: =VLOOKUP(_xlfn.XLOOKUP($A12,'MM configuration'!$D$2:$D$601,'MM configuration'!$C$2:$C$601),$S$24:$AA$38,4) | M12: =VLOOKUP(_xlfn.XLOOKUP($A12,'MM configuration'!$D$2:$D$601,'MM configuration'!$C$2:$C$601),$S$24:$AA$38,5) | N12: =VLOOKUP(_xlfn.XLOOKUP($A12,'MM configuration'!$D$2:$D$601,'MM configuration'!$C$2:$C$601),$S$24:$AA$38,6) | O12: =VLOOKUP(_xlfn.XLOOKUP($A12,'MM configuration'!$D$2:$D$601,'MM configuration'!$C$2:$C$601),$S$24:$AA$38,7) | P12: =VLOOKUP(_xlfn.XLOOKUP($A12,'MM configuration'!$D$2:$D$601,'MM configuration'!$C$2:$C$601),$S$24:$AA$38,8) | Q12: =VLOOKUP(_xlfn.XLOOKUP($A12,'MM configuration'!$D$2:$D$601,'MM configuration'!$C$2:$C$601),$S$24:$AA$38,9) | R12: 7 | S12: 42 | T12: 0.0914 | U12: 0.0709 | V12: 0.0837 | W12: 0.0801 | X12: 0.0314 | Y12: 0.0002 | Z12: 0 | AA12: 0
A13: 12 | B13: 0.0019599067 | C13: 0.0019169579 | D13: Variable 5% 0.35 keV | E13: gaussian(K,5%*K) | J13: =VLOOKUP(_xlfn.XLOOKUP($A13,'MM configuration'!$D$2:$D$601,'MM configuration'!$C$2:$C$601),$S$24:$AA$38,2) | K13: =VLOOKUP(_xlfn.XLOOKUP($A13,'MM configuration'!$D$2:$D$601,'MM configuration'!$C$2:$C$601),$S$24:$AA$38,3) | L13: =VLOOKUP(_xlfn.XLOOKUP($A13,'MM configuration'!$D$2:$D$601,'MM configuration'!$C$2:$C$601),$S$24:$AA$38,4) | M13: =VLOOKUP(_xlfn.XLOOKUP($A13,'MM configuration'!$D$2:$D$601,'MM configuration'!$C$2:$C$601),$S$24:$AA$38,5) | N13: =VLOOKUP(_xlfn.XLOOKUP($A13,'MM configuration'!$D$2:$D$601,'MM configuration'!$C$2:$C$601),$S$24:$AA$38,6) | O13: =VLOOKUP(_xlfn.XLOOKUP($A13,'MM configuration'!$D$2:$D$601,'MM configuration'!$C$2:$C$601),$S$24:$AA$38,7) | P13: =VLOOKUP(_xlfn.XLOOKUP($A13,'MM configuration'!$D$2:$D$601,'MM configuration'!$C$2:$C$601),$S$24:$AA$38,8) | Q13: =VLOOKUP(_xlfn.XLOOKUP($A13,'MM configuration'!$D$2:$D$601,'MM configuration'!$C$2:$C$601),$S$24:$AA$38,9) | R13: 8 | S13: 42 | T13: 0.1036 | U13: 0.0778 | V13: 0.0925 | W13: 0.0862 | X13: 0.0253 | Y13: 0.0001 | Z13: 0 | AA13: 0
A14: 13 | B14: 0.0018158187 | C14: 0.0017137889 | D14: Variable 10% 0.35 keV | E14: gaussian(K,10%*K) | J14: =VLOOKUP(_xlfn.XLOOKUP($A14,'MM configuration'!$D$2:$D$601,'MM configuration'!$C$2:$C$601),$S$24:$AA$38,2) | K14: =VLOOKUP(_xlfn.XLOOKUP($A14,'MM configuration'!$D$2:$D$601,'MM configuration'!$C$2:$C$601),$S$24:$AA$38,3) | L14: =VLOOKUP(_xlfn.XLOOKUP($A14,'MM configuration'!$D$2:$D$601,'MM configuration'!$C$2:$C$601),$S$24:$AA$38,4) | M14: =VLOOKUP(_xlfn.XLOOKUP($A14,'MM configuration'!$D$2:$D$601,'MM configuration'!$C$2:$C$601),$S$24:$AA$38,5) | N14: =VLOOKUP(_xlfn.XLOOKUP($A14,'MM configuration'!$D$2:$D$601,'MM configuration'!$C$2:$C$601),$S$24:$AA$38,6) | O14: =VLOOKUP(_xlfn.XLOOKUP($A14,'MM configuration'!$D$2:$D$601,'MM configuration'!$C$2:$C$601),$S$24:$AA$38,7) | P14: =VLOOKUP(_xlfn.XLOOKUP($A14,'MM configuration'!$D$2:$D$601,'MM configuration'!$C$2:$C$601),$S$24:$AA$38,8) | Q14: =VLOOKUP(_xlfn.XLOOKUP($A14,'MM configuration'!$D$2:$D$601,'MM configuration'!$C$2:$C$601),$S$24:$AA$38,9) | R14: 9 | S14: 42 | T14: 0.1156 | U14: 0.0841 | V14: 0.1015 | W14: 0.0906 | X14: 0.0211 | Y14: 0.0001 | Z14: 0 | AA14: 0
A15: 14 | B15: 0.0018158187 | C15: 0.0017137889 | D15: Variable 20% 0.35 keV | E15: gaussian(K,20%*K) | J15: =VLOOKUP(_xlfn.XLOOKUP($A15,'MM configuration'!$D$2:$D$601,'MM configuration'!$C$2:$C$601),$S$24:$AA$38,2) | K15: =VLOOKUP(_xlfn.XLOOKUP($A15,'MM configuration'!$D$2:$D$601,'MM configuration'!$C$2:$C$601),$S$24:$AA$38,3) | L15: =VLOOKUP(_xlfn.XLOOKUP($A15,'MM configuration'!$D$2:$D$601,'MM configuration'!$C$2:$C$601),$S$24:$AA$38,4) | M15: =VLOOKUP(_xlfn.XLOOKUP($A15,'MM configuration'!$D$2:$D$601,'MM configuration'!$C$2:$C$601),$S$24:$AA$38,5) | N15: =VLOOKUP(_xlfn.XLOOKUP($A15,'MM configuration'!$D$2:$D$601,'MM configuration'!$C$2:$C$601),$S$24:$AA$38,6) | O15: =VLOOKUP(_xlfn.XLOOKUP($A15,'MM configuration'!$D$2:$D$601,'MM configuration'!$C$2:$C$601),$S$24:$AA$38,7) | P15: =VLOOKUP(_xlfn.XLOOKUP($A15,'MM configuration'!$D$2:$D$601,'MM configuration'!$C$2:$C$601),$S$24:$AA$38,8) | Q15: =VLOOKUP(_xlfn.XLOOKUP($A15,'MM configuration'!$D$2:$D$601,'MM configuration'!$C$2:$C$601),$S$24:$AA$38,9) | R15: 10 | S15: 48 | T15: 0.123 | U15: 0.0877 | V15: 0.1067 | W15: 0.0884 | X15: 0.0164 | Y15: 0 | Z15: 0 | AA15: 0
A16: 15 | B16: 0.0018158187 | C16: 0.0017137889 | D16: Variable 5% 1 keV | E16: gaussian(L,5%*L) | J16: =VLOOKUP(_xlfn.XLOOKUP($A16,'MM configuration'!$D$2:$D$601,'MM configuration'!$C$2:$C$601),$S$24:$AA$38,2) | K16: =VLOOKUP(_xlfn.XLOOKUP($A16,'MM configuration'!$D$2:$D$601,'MM configuration'!$C$2:$C$601),$S$24:$AA$38,3) | L16: =VLOOKUP(_xlfn.XLOOKUP($A16,'MM configuration'!$D$2:$D$601,'MM configuration'!$C$2:$C$601),$S$24:$AA$38,4) | M16: =VLOOKUP(_xlfn.XLOOKUP($A16,'MM configuration'!$D$2:$D$601,'MM configuration'!$C$2:$C$601),$S$24:$AA$38,5) | N16: =VLOOKUP(_xlfn.XLOOKUP($A16,'MM configuration'!$D$2:$D$601,'MM configuration'!$C$2:$C$601),$S$24:$AA$38,6) | O16: =VLOOKUP(_xlfn.XLOOKUP($A16,'MM configuration'!$D$2:$D$601,'MM configuration'!$C$2:$C$601),$S$24:$AA$38,7) | P16: =VLOOKUP(_xlfn.XLOOKUP($A16,'MM configuration'!$D$2:$D$601,'MM configuration'!$C$2:$C$601),$S$24:$AA$38,8) | Q16: =VLOOKUP(_xlfn.XLOOKUP($A16,'MM configuration'!$D$2:$D$601,'MM configuration'!$C$2:$C$601),$S$24:$AA$38,9) | R16: 11 | S16: 48 | T16: 0.134 | U16: 0.0923 | V16: 0.1138 | W16: 0.0861 | X16: 0.0115 | Y16: 0 | Z16: 0 | AA16: 0
A17: 16 | B17: 0.0018158187 | C17: 0.0017137889 | D17: Variable 10% 1 keV | E17: gaussian(L,10%*L) | J17: =VLOOKUP(_xlfn.XLOOKUP($A17,'MM configuration'!$D$2:$D$601,'MM configuration'!$C$2:$C$601),$S$24:$AA$38,2) | K17: =VLOOKUP(_xlfn.XLOOKUP($A17,'MM configuration'!$D$2:$D$601,'MM configuration'!$C$2:$C$601),$S$24:$AA$38,3) | L17: =VLOOKUP(_xlfn.XLOOKUP($A17,'MM configuration'!$D$2:$D$601,'MM configuration'!$C$2:$C$601),$S$24:$AA$38,4) | M17: =VLOOKUP(_xlfn.XLOOKUP($A17,'MM configuration'!$D$2:$D$601,'MM configuration'!$C$2:$C$601),$S$24:$AA$38,5) | N17: =VLOOKUP(_xlfn.XLOOKUP($A17,'MM configuration'!$D$2:$D$601,'MM configuration'!$C$2:$C$601),$S$24:$AA$38,6) | O17: =VLOOKUP(_xlfn.XLOOKUP($A17,'MM configuration'!$D$2:$D$601,'MM configuration'!$C$2:$C$601),$S$24:$AA$38,7) | P17: =VLOOKUP(_xlfn.XLOOKUP($A17,'MM configuration'!$D$2:$D$601,'MM configuration'!$C$2:$C$601),$S$24:$AA$38,8) | Q17: =VLOOKUP(_xlfn.XLOOKUP($A17,'MM configuration'!$D$2:$D$601,'MM configuration'!$C$2:$C$601),$S$24:$AA$38,9) | R17: 12 | S17: 48 | T17: 0.145 | U17: 0.0975 | V17: 0.1208 | W17: 0.0791 | X17: 0.0065 | Y17: 0 | Z17: 0 | AA17: 0
... A20: 19 | B20: 0.0021597707 | C20: 0.0021597707 | D20: Variable 10% 2 keV | E20: gaussian(M,10%*M) | J20: =VLOOKUP(_xlfn.XLOOKUP($A20,'MM configuration'!$D$2:$D$601,'MM configuration'!$C$2:$C$601),$S$24:$AA$38,2) | K20: =VLOOKUP(_xlfn.XLOOKUP($A20,'MM configuration'!$D$2:$D$601,'MM configuration'!$C$2:$C$601),$S$24:$AA$38,3) | L20: =VLOOKUP(_xlfn.XLOOKUP($A20,'MM configuration'!$D$2:$D$601,'MM configuration'!$C$2:$C$601),$S$24:$AA$38,4) | M20: =VLOOKUP(_xlfn.XLOOKUP($A20,'MM configuration'!$D$2:$D$601,'MM configuration'!$C$2:$C$601),$S$24:$AA$38,5) | N20: =VLOOKUP(_xlfn.XLOOKUP($A20,'MM configuration'!$D$2:$D$601,'MM configuration'!$C$2:$C$601),$S$24:$AA$38,6) | O20: =VLOOKUP(_xlfn.XLOOKUP($A20,'MM configuration'!$D$2:$D$601,'MM configuration'!$C$2:$C$601),$S$24:$AA$38,7) | P20: =VLOOKUP(_xlfn.XLOOKUP($A20,'MM configuration'!$D$2:$D$601,'MM configuration'!$C$2:$C$601),$S$24:$AA$38,8) | Q20: =VLOOKUP(_xlfn.XLOOKUP($A20,'MM configuration'!$D$2:$D$601,'MM configuration'!$C$2:$C$601),$S$24:$AA$38,9) | R20: 15 | S20: 54 | T20: 0.2233 | U20: 0.1425 | V20: 0.1706 | W20: 0.0568 | X20: 0.0004 | Y20: 0 | Z20: 0 | AA20: 0
A21: 20 | B21: 0.0021597707 | C21: 0.0021597707 | D21: Variable 20% 2 keV | E21: gaussian(M,20%*M) | J21: =VLOOKUP(_xlfn.XLOOKUP($A21,'MM configuration'!$D$2:$D$601,'MM configuration'!$C$2:$C$601),$S$24:$AA$38,2) | K21: =VLOOKUP(_xlfn.XLOOKUP($A21,'MM configuration'!$D$2:$D$601,'MM configuration'!$C$2:$C$601),$S$24:$AA$38,3) | L21: =VLOOKUP(_xlfn.XLOOKUP($A21,'MM configuration'!$D$2:$D$601,'MM configuration'!$C$2:$C$601),$S$24:$AA$38,4) | M21: =VLOOKUP(_xlfn.XLOOKUP($A21,'MM configuration'!$D$2:$D$601,'MM configuration'!$C$2:$C$601),$S$24:$AA$38,5) | N21: =VLOOKUP(_xlfn.XLOOKUP($A21,'MM configuration'!$D$2:$D$601,'MM configuration'!$C$2:$C$601),$S$24:$AA$38,6) | O21: =VLOOKUP(_xlfn.XLOOKUP($A21,'MM configuration'!$D$2:$D$601,'MM configuration'!$C$2:$C$601),$S$24:$AA$38,7) | P21: =VLOOKUP(_xlfn.XLOOKUP($A21,'MM configuration'!$D$2:$D$601,'MM configuration'!$C$2:$C$601),$S$24:$AA$38,8) | Q21: =VLOOKUP(_xlfn.XLOOKUP($A21,'MM configuration'!$D$2:$D$601,'MM configuration'!$C$2:$C$601),$S$24:$AA$38,9)
A22: 21 | B22: 0.0021597707 | C22: 0.0021597707 | D22: Variable 5% 4 keV | E22: gaussian(N,5%*N) | J22: =VLOOKUP(_xlfn.XLOOKUP($A22,'MM configuration'!$D$2:$D$601,'MM configuration'!$C$2:$C$601),$S$24:$AA$38,2) | K22: =VLOOKUP(_xlfn.XLOOKUP($A22,'MM configuration'!$D$2:$D$601,'MM configuration'!$C$2:$C$601),$S$24:$AA$38,3) | L22: =VLOOKUP(_xlfn.XLOOKUP($A22,'MM configuration'!$D$2:$D$601,'MM configuration'!$C$2:$C$601),$S$24:$AA$38,4) | M22: =VLOOKUP(_xlfn.XLOOKUP($A22,'MM configuration'!$D$2:$D$601,'MM configuration'!$C$2:$C$601),$S$24:$AA$38,5) | N22: =VLOOKUP(_xlfn.XLOOKUP($A22,'MM configuration'!$D$2:$D$601,'MM configuration'!$C$2:$C$601),$S$24:$AA$38,6) | O22: =VLOOKUP(_xlfn.XLOOKUP($A22,'MM configuration'!$D$2:$D$601,'MM configuration'!$C$2:$C$601),$S$24:$AA$38,7) | P22: =VLOOKUP(_xlfn.XLOOKUP($A22,'MM configuration'!$D$2:$D$601,'MM configuration'!$C$2:$C$601),$S$24:$AA$38,8) | Q22: =VLOOKUP(_xlfn.XLOOKUP($A22,'MM configuration'!$D$2:$D$601,'MM configuration'!$C$2:$C$601),$S$24:$AA$38,9)
A23: 22 | B23: 0.0021597707 | C23: 0.0021597707 | D23: Variable 10% 4 keV | E23: gaussian(N,10%*N) | J23: =VLOOKUP(_xlfn.XLOOKUP($A23,'MM configuration'!$D$2:$D$601,'MM configuration'!$C$2:$C$601),$S$24:$AA$38,2) | K23: =VLOOKUP(_xlfn.XLOOKUP($A23,'MM configuration'!$D$2:$D$601,'MM configuration'!$C$2:$C$601),$S$24:$AA$38,3) | L23: =VLOOKUP(_xlfn.XLOOKUP($A23,'MM configuration'!$D$2:$D$601,'MM configuration'!$C$2:$C$601),$S$24:$AA$38,4) | M23: =VLOOKUP(_xlfn.XLOOKUP($A23,'MM configuration'!$D$2:$D$601,'MM configuration'!$C$2:$C$601),$S$24:$AA$38,5) | N23: =VLOOKUP(_xlfn.XLOOKUP($A23,'MM configuration'!$D$2:$D$601,'MM configuration'!$C$2:$C$601),$S$24:$AA$38,6) | O23: =VLOOKUP(_xlfn.XLOOKUP($A23,'MM configuration'!$D$2:$D$601,'MM configuration'!$C$2:$C$601),$S$24:$AA$38,7) | P23: =VLOOKUP(_xlfn.XLOOKUP($A23,'MM configuration'!$D$2:$D$601,'MM configuration'!$C$2:$C$601),$S$24:$AA$38,8) | Q23: =VLOOKUP(_xlfn.XLOOKUP($A23,'MM configuration'!$D$2:$D$601,'MM configuration'!$C$2:$C$601),$S$24:$AA$38,9) | S23: Row
A24: 23 | B24: 0.0019805644 | C24: 0.0019255884 | D24: Variable 20% 4 keV | E24: gaussian(N,20%*N) | J24: =VLOOKUP(_xlfn.XLOOKUP($A24,'MM configuration'!$D$2:$D$601,'MM configuration'!$C$2:$C$601),$S$24:$AA$38,2) | K24: =VLOOKUP(_xlfn.XLOOKUP($A24,'MM configuration'!$D$2:$D$601,'MM configuration'!$C$2:$C$601),$S$24:$AA$38,3) | L24: =VLOOKUP(_xlfn.XLOOKUP($A24,'MM configuration'!$D$2:$D$601,'MM configuration'!$C$2:$C$601),$S$24:$AA$38,4) | M24: =VLOOKUP(_xlfn.XLOOKUP($A24,'MM configuration'!$D$2:$D$601,'MM configuration'!$C$2:$C$601),$S$24:$AA$38,5) | N24: =VLOOKUP(_xlfn.XLOOKUP($A24,'MM configuration'!$D$2:$D$601,'MM configuration'!$C$2:$C$601),$S$24:$AA$38,6) | O24: =VLOOKUP(_xlfn.XLOOKUP($A24,'MM configuration'!$D$2:$D$601,'MM configuration'!$C$2:$C$601),$S$24:$AA$38,7) | P24: =VLOOKUP(_xlfn.XLOOKUP($A24,'MM configuration'!$D$2:$D$601,'MM configuration'!$C$2:$C$601),$S$24:$AA$38,8) | Q24: =VLOOKUP(_xlfn.XLOOKUP($A24,'MM configuration'!$D$2:$D$601,'MM configuration'!$C$2:$C$601),$S$24:$AA$38,9) | S24: 1 | T24: =T6*(100%-T$5)/$S6 | U24: =U6*(100%-U$5)/$S6 | V24: =V6*(100%-V$5)/$S6 | W24: =W6*(100%-W$5)/$S6 | X24: =X6*(100%-X$5)/$S6 | Y24: =Y6*(100%-Y$5)/$S6 | Z24: =Z6*(100%-Z$5)/$S6 | AA24: =AA6*(100%-AA$5)/$S6
A25: 24 | B25: 0.0019805644 | C25: 0.0019255884 | D25: Variable 5% 7 keV | E25: gaussian(O,5%*O) | J25: =VLOOKUP(_xlfn.XLOOKUP($A25,'MM configuration'!$D$2:$D$601,'MM configuration'!$C$2:$C$601),$S$24:$AA$38,2) | K25: =VLOOKUP(_xlfn.XLOOKUP($A25,'MM configuration'!$D$2:$D$601,'MM configuration'!$C$2:$C$601),$S$24:$AA$38,3) | L25: =VLOOKUP(_xlfn.XLOOKUP($A25,'MM configuration'!$D$2:$D$601,'MM configuration'!$C$2:$C$601),$S$24:$AA$38,4) | M25: =VLOOKUP(_xlfn.XLOOKUP($A25,'MM configuration'!$D$2:$D$601,'MM configuration'!$C$2:$C$601),$S$24:$AA$38,5) | N25: =VLOOKUP(_xlfn.XLOOKUP($A25,'MM configuration'!$D$2:$D$601,'MM configuration'!$C$2:$C$601),$S$24:$AA$38,6) | O25: =VLOOKUP(_xlfn.XLOOKUP($A25,'MM configuration'!$D$2:$D$601,'MM configuration'!$C$2:$C$601),$S$24:$AA$38,7) | P25: =VLOOKUP(_xlfn.XLOOKUP($A25,'MM configuration'!$D$2:$D$601,'MM configuration'!$C$2:$C$601),$S$24:$AA$38,8) | Q25: =VLOOKUP(_xlfn.XLOOKUP($A25,'MM configuration'!$D$2:$D$601,'MM configuration'!$C$2:$C$601),$S$24:$AA$38,9) | S25: 2 | T25: =T7*(100%-T$5)/$S7 | U25: =U7*(100%-U$5)/$S7 | V25: =V7*(100%-V$5)/$S7 | W25: =W7*(100%-W$5)/$S7 | X25: =X7*(100%-X$5)/$S7 | Y25: =Y7*(100%-Y$5)/$S7 | Z25: =Z7*(100%-Z$5)/$S7 | AA25: =AA7*(100%-AA$5)/$S7
A26: 25 | B26: 0.0019805644 | C26: 0.0019255884 | D26: Variable 10% 7 keV | E26: gaussian(O,10%*O) | J26: =VLOOKUP(_xlfn.XLOOKUP($A26,'MM configuration'!$D$2:$D$601,'MM configuration'!$C$2:$C$601),$S$24:$AA$38,2) | K26: =VLOOKUP(_xlfn.XLOOKUP($A26,'MM configuration'!$D$2:$D$601,'MM configuration'!$C$2:$C$601),$S$24:$AA$38,3) | L26: =VLOOKUP(_xlfn.XLOOKUP($A26,'MM configuration'!$D$2:$D$601,'MM configuration'!$C$2:$C$601),$S$24:$AA$38,4) | M26: =VLOOKUP(_xlfn.XLOOKUP($A26,'MM configuration'!$D$2:$D$601,'MM configuration'!$C$2:$C$601),$S$24:$AA$38,5) | N26: =VLOOKUP(_xlfn.XLOOKUP($A26,'MM configuration'!$D$2:$D$601,'MM configuration'!$C$2:$C$601),$S$24:$AA$38,6) | O26: =VLOOKUP(_xlfn.XLOOKUP($A26,'MM configuration'!$D$2:$D$601,'MM configuration'!$C$2:$C$601),$S$24:$AA$38,7) | P26: =VLOOKUP(_xlfn.XLOOKUP($A26,'MM configuration'!$D$2:$D$601,'MM configuration'!$C$2:$C$601),$S$24:$AA$38,8) | Q26: =VLOOKUP(_xlfn.XLOOKUP($A26,'MM configuration'!$D$2:$D$601,'MM configuration'!$C$2:$C$601),$S$24:$AA$38,9) | S26: 3 | T26: =T8*(100%-T$5)/$S8 | U26: =U8*(100%-U$5)/$S8 | V26: =V8*(100%-V$5)/$S8 | W26: =W8*(100%-W$5)/$S8 | X26: =X8*(100%-X$5)/$S8 | Y26: =Y8*(100%-Y$5)/$S8 | Z26: =Z8*(100%-Z$5)/$S8 | AA26: =AA8*(100%-AA$5)/$S8
A27: 26 | B27: 0.0019805644 | C27: 0.0019255884 | D27: Variable 20% 7 keV | E27: gaussian(O,20%*O) | J27: =VLOOKUP(_xlfn.XLOOKUP($A27,'MM configuration'!$D$2:$D$601,'MM configuration'!$C$2:$C$601),$S$24:$AA$38,2) | K27: =VLOOKUP(_xlfn.XLOOKUP($A27,'MM configuration'!$D$2:$D$601,'MM configuration'!$C$2:$C$601),$S$24:$AA$38,3) | L27: =VLOOKUP(_xlfn.XLOOKUP($A27,'MM configuration'!$D$2:$D$601,'MM configuration'!$C$2:$C$601),$S$24:$AA$38,4) | M27: =VLOOKUP(_xlfn.XLOOKUP($A27,'MM configuration'!$D$2:$D$601,'MM configuration'!$C$2:$C$601),$S$24:$AA$38,5) | N27: =VLOOKUP(_xlfn.XLOOKUP($A27,'MM configuration'!$D$2:$D$601,'MM configuration'!$C$2:$C$601),$S$24:$AA$38,6) | O27: =VLOOKUP(_xlfn.XLOOKUP($A27,'MM configuration'!$D$2:$D$601,'MM configuration'!$C$2:$C$601),$S$24:$AA$38,7) | P27: =VLOOKUP(_xlfn.XLOOKUP($A27,'MM configuration'!$D$2:$D$601,'MM configuration'!$C$2:$C$601),$S$24:$AA$38,8) | Q27: =VLOOKUP(_xlfn.XLOOKUP($A27,'MM configuration'!$D$2:$D$601,'MM configuration'!$C$2:$C$601),$S$24:$AA$38,9) | S27: 4 | T27: =T9*(100%-T$5)/$S9 | U27: =U9*(100%-U$5)/$S9 | V27: =V9*(100%-V$5)/$S9 | W27: =W9*(100%-W$5)/$S9 | X27: =X9*(100%-X$5)/$S9 | Y27: =Y9*(100%-Y$5)/$S9 | Z27: =Z9*(100%-Z$5)/$S9 | AA27: =AA9*(100%-AA$5)/$S9
A28: 27 | B28: 0.0019805644 | C28: 0.0019255884 | D28: Variable 5% 10 keV | E28: gaussian(P,5%*P) | J28: =VLOOKUP(_xlfn.XLOOKUP($A28,'MM configuration'!$D$2:$D$601,'MM configuration'!$C$2:$C$601),$S$24:$AA$38,2) | K28: =VLOOKUP(_xlfn.XLOOKUP($A28,'MM configuration'!$D$2:$D$601,'MM configuration'!$C$2:$C$601),$S$24:$AA$38,3) | L28: =VLOOKUP(_xlfn.XLOOKUP($A28,'MM configuration'!$D$2:$D$601,'MM configuration'!$C$2:$C$601),$S$24:$AA$38,4) | M28: =VLOOKUP(_xlfn.XLOOKUP($A28,'MM configuration'!$D$2:$D$601,'MM configuration'!$C$2:$C$601),$S$24:$AA$38,5) | N28: =VLOOKUP(_xlfn.XLOOKUP($A28,'MM configuration'!$D$2:$D$601,'MM configuration'!$C$2:$C$601),$S$24:$AA$38,6) | O28: =VLOOKUP(_xlfn.XLOOKUP($A28,'MM configuration'!$D$2:$D$601,'MM configuration'!$C$2:$C$601),$S$24:$AA$38,7) | P28: =VLOOKUP(_xlfn.XLOOKUP($A28,'MM configuration'!$D$2:$D$601,'MM configuration'!$C$2:$C$601),$S$24:$AA$38,8) | Q28: =VLOOKUP(_xlfn.XLOOKUP($A28,'MM configuration'!$D$2:$D$601,'MM configuration'!$C$2:$C$601),$S$24:$AA$38,9) | S28: 5 | T28: =T10*(100%-T$5)/$S10 | U28: =U10*(100%-U$5)/$S10 | V28: =V10*(100%-V$5)/$S10 | W28: =W10*(100%-W$5)/$S10 | X28: =X10*(100%-X$5)/$S10 | Y28: =Y10*(100%-Y$5)/$S10 | Z28: =Z10*(100%-Z$5)/$S10 | AA28: =AA10*(100%-AA$5)/$S10
A29: 28 | B29: 0.0019805644 | C29: 0.0019255884 | D29: Variable 10% 10 keV | E29: gaussian(P,10%*P) | J29: =VLOOKUP(_xlfn.XLOOKUP($A29,'MM configuration'!$D$2:$D$601,'MM configuration'!$C$2:$C$601),$S$24:$AA$38,2) | K29: =VLOOKUP(_xlfn.XLOOKUP($A29,'MM configuration'!$D$2:$D$601,'MM configuration'!$C$2:$C$601),$S$24:$AA$38,3) | L29: =VLOOKUP(_xlfn.XLOOKUP($A29,'MM configuration'!$D$2:$D$601,'MM configuration'!$C$2:$C$601),$S$24:$AA$38,4) | M29: =VLOOKUP(_xlfn.XLOOKUP($A29,'MM configuration'!$D$2:$D$601,'MM configuration'!$C$2:$C$601),$S$24:$AA$38,5) | N29: =VLOOKUP(_xlfn.XLOOKUP($A29,'MM configuration'!$D$2:$D$601,'MM configuration'!$C$2:$C$601),$S$24:$AA$38,6) | O29: =VLOOKUP(_xlfn.XLOOKUP($A29,'MM configuration'!$D$2:$D$601,'MM configuration'!$C$2:$C$601),$S$24:$AA$38,7) | P29: =VLOOKUP(_xlfn.XLOOKUP($A29,'MM configuration'!$D$2:$D$601,'MM configuration'!$C$2:$C$601),$S$24:$AA$38,8) | Q29: =VLOOKUP(_xlfn.XLOOKUP($A29,'MM configuration'!$D$2:$D$601,'MM configuration'!$C$2:$C$601),$S$24:$AA$38,9) | S29: 6 | T29: =T11*(100%-T$5)/$S11 | U29: =U11*(100%-U$5)/$S11 | V29: =V11*(100%-V$5)/$S11 | W29: =W11*(100%-W$5)/$S11 | X29: =X11*(100%-X$5)/$S11 | Y29: =Y11*(100%-Y$5)/$S11 | Z29: =Z11*(100%-Z$5)/$S11 | AA29: =AA11*(100%-AA$5)/$S11
A30: 29 | B30: 0.00185256 | C30: 0.00185256 | D30: Variable 20% 10 keV | E30: gaussian(P,20%*P) | J30: =VLOOKUP(_xlfn.XLOOKUP($A30,'MM configuration'!$D$2:$D$601,'MM configuration'!$C$2:$C$601),$S$24:$AA$38,2) | K30: =VLOOKUP(_xlfn.XLOOKUP($A30,'MM configuration'!$D$2:$D$601,'MM configuration'!$C$2:$C$601),$S$24:$AA$38,3) | L30: =VLOOKUP(_xlfn.XLOOKUP($A30,'MM configuration'!$D$2:$D$601,'MM configuration'!$C$2:$C$601),$S$24:$AA$38,4) | M30: =VLOOKUP(_xlfn.XLOOKUP($A30,'MM configuration'!$D$2:$D$601,'MM configuration'!$C$2:$C$601),$S$24:$AA$38,5) | N30: =VLOOKUP(_xlfn.XLOOKUP($A30,'MM configuration'!$D$2:$D$601,'MM configuration'!$C$2:$C$601),$S$24:$AA$38,6) | O30: =VLOOKUP(_xlfn.XLOOKUP($A30,'MM configuration'!$D$2:$D$601,'MM configuration'!$C$2:$C$601),$S$24:$AA$38,7) | P30: =VLOOKUP(_xlfn.XLOOKUP($A30,'MM configuration'!$D$2:$D$601,'MM configuration'!$C$2:$C$601),$S$24:$AA$38,8) | Q30: =VLOOKUP(_xlfn.XLOOKUP($A30,'MM configuration'!$D$2:$D$601,'MM configuration'!$C$2:$C$601),$S$24:$AA$38,9) | S30: 7 | T30: =T12*(100%-T$5)/$S12 | U30: =U12*(100%-U$5)/$S12 | V30: =V12*(100%-V$5)/$S12 | W30: =W12*(100%-W$5)/$S12 | X30: =X12*(100%-X$5)/$S12 | Y30: =Y12*(100%-Y$5)/$S12 | Z30: =Z12*(100%-Z$5)/$S12 | AA30: =AA12*(100%-AA$5)/$S12
A31: 30 | B31: 0.00185256 | C31: 0.00185256 | D31: Variable 5% 12 keV | E31: gaussian(Q,5%*Q) | J31: =VLOOKUP(_xlfn.XLOOKUP($A31,'MM configuration'!$D$2:$D$601,'MM configuration'!$C$2:$C$601),$S$24:$AA$38,2) | K31: =VLOOKUP(_xlfn.XLOOKUP($A31,'MM configuration'!$D$2:$D$601,'MM configuration'!$C$2:$C$601),$S$24:$AA$38,3) | L31: =VLOOKUP(_xlfn.XLOOKUP($A31,'MM configuration'!$D$2:$D$601,'MM configuration'!$C$2:$C$601),$S$24:$AA$38,4) | M31: =VLOOKUP(_xlfn.XLOOKUP($A31,'MM configuration'!$D$2:$D$601,'MM configuration'!$C$2:$C$601),$S$24:$AA$38,5) | N31: =VLOOKUP(_xlfn.XLOOKUP($A31,'MM configuration'!$D$2:$D$601,'MM configuration'!$C$2:$C$601),$S$24:$AA$38,6) | O31: =VLOOKUP(_xlfn.XLOOKUP($A31,'MM configuration'!$D$2:$D$601,'MM configuration'!$C$2:$C$601),$S$24:$AA$38,7) | P31: =VLOOKUP(_xlfn.XLOOKUP($A31,'MM configuration'!$D$2:$D$601,'MM configuration'!$C$2:$C$601),$S$24:$AA$38,8) | Q31: =VLOOKUP(_xlfn.XLOOKUP($A31,'MM configuration'!$D$2:$D$601,'MM configuration'!$C$2:$C$601),$S$24:$AA$38,9) | S31: 8 | T31: =T13*(100%-T$5)/$S13 | U31: =U13*(100%-U$5)/$S13 | V31: =V13*(100%-V$5)/$S13 | W31: =W13*(100%-W$5)/$S13 | X31: =X13*(100%-X$5)/$S13 | Y31: =Y13*(100%-Y$5)/$S13 | Z31: =Z13*(100%-Z$5)/$S13 | AA31: =AA13*(100%-AA$5)/$S13
A32: 31 | B32: 0.00185256 | C32: 0.00185256 | D32: Variable 10% 12 keV | E32: gaussian(Q,10%*Q) | J32: =VLOOKUP(_xlfn.XLOOKUP($A32,'MM configuration'!$D$2:$D$601,'MM configuration'!$C$2:$C$601),$S$24:$AA$38,2) | K32: =VLOOKUP(_xlfn.XLOOKUP($A32,'MM configuration'!$D$2:$D$601,'MM configuration'!$C$2:$C$601),$S$24:$AA$38,3) | L32: =VLOOKUP(_xlfn.XLOOKUP($A32,'MM configuration'!$D$2:$D$601,'MM configuration'!$C$2:$C$601),$S$24:$AA$38,4) | M32: =VLOOKUP(_xlfn.XLOOKUP($A32,'MM configuration'!$D$2:$D$601,'MM configuration'!$C$2:$C$601),$S$24:$AA$38,5) | N32: =VLOOKUP(_xlfn.XLOOKUP($A32,'MM configuration'!$D$2:$D$601,'MM configuration'!$C$2:$C$601),$S$24:$AA$38,6) | O32: =VLOOKUP(_xlfn.XLOOKUP($A32,'MM configuration'!$D$2:$D$601,'MM configuration'!$C$2:$C$601),$S$24:$AA$38,7) | P32: =VLOOKUP(_xlfn.XLOOKUP($A32,'MM configuration'!$D$2:$D$601,'MM configuration'!$C$2:$C$601),$S$24:$AA$38,8) | Q32: =VLOOKUP(_xlfn.XLOOKUP($A32,'MM configuration'!$D$2:$D$601,'MM configuration'!$C$2:$C$601),$S$24:$AA$38,9) | S32: 9 | T32: =T14*(100%-T$5)/$S14 | U32: =U14*(100%-U$5)/$S14 | V32: =V14*(100%-V$5)/$S14 | W32: =W14*(100%-W$5)/$S14 | X32: =X14*(100%-X$5)/$S14 | Y32: =Y14*(100%-Y$5)/$S14 | Z32: =Z14*(100%-Z$5)/$S14 | AA32: =AA14*(100%-AA$5)/$S14
A33: 32 | B33: 0.00185256 | C33: 0.00185256 | D33: Variable 20% 12 keV | E33: gaussian(Q,20%*Q) | J33: =VLOOKUP(_xlfn.XLOOKUP($A33,'MM configuration'!$D$2:$D$601,'MM configuration'!$C$2:$C$601),$S$24:$AA$38,2) | K33: =VLOOKUP(_xlfn.XLOOKUP($A33,'MM configuration'!$D$2:$D$601,'MM configuration'!$C$2:$C$601),$S$24:$AA$38,3) | L33: =VLOOKUP(_xlfn.XLOOKUP($A33,'MM configuration'!$D$2:$D$601,'MM configuration'!$C$2:$C$601),$S$24:$AA$38,4) | M33: =VLOOKUP(_xlfn.XLOOKUP($A33,'MM configuration'!$D$2:$D$601,'MM configuration'!$C$2:$C$601),$S$24:$AA$38,5) | N33: =VLOOKUP(_xlfn.XLOOKUP($A33,'MM configuration'!$D$2:$D$601,'MM configuration'!$C$2:$C$601),$S$24:$AA$38,6) | O33: =VLOOKUP(_xlfn.XLOOKUP($A33,'MM configuration'!$D$2:$D$601,'MM configuration'!$C$2:$C$601),$S$24:$AA$38,7) | P33: =VLOOKUP(_xlfn.XLOOKUP($A33,'MM configuration'!$D$2:$D$601,'MM configuration'!$C$2:$C$601),$S$24:$AA$38,8) | Q33: =VLOOKUP(_xlfn.XLOOKUP($A33,'MM configuration'!$D$2:$D$601,'MM configuration'!$C$2:$C$601),$S$24:$AA$38,9) | S33: 10 | T33: =T15*(100%-T$5)/$S15 | U33: =U15*(100%-U$5)/$S15 | V33: =V15*(100%-V$5)/$S15 | W33: =W15*(100%-W$5)/$S15 | X33: =X15*(100%-X$5)/$S15 | Y33: =Y15*(100%-Y$5)/$S15 | Z33: =Z15*(100%-Z$5)/$S15 | AA33: =AA15*(100%-AA$5)/$S15
A34: 33 | B34: 0.00185256 | C34: 0.00185256 | J34: =VLOOKUP(_xlfn.XLOOKUP($A34,'MM configuration'!$D$2:$D$601,'MM configuration'!$C$2:$C$601),$S$24:$AA$38,2) | K34: =VLOOKUP(_xlfn.XLOOKUP($A34,'MM configuration'!$D$2:$D$601,'MM configuration'!$C$2:$C$601),$S$24:$AA$38,3) | L34: =VLOOKUP(_xlfn.XLOOKUP($A34,'MM configuration'!$D$2:$D$601,'MM configuration'!$C$2:$C$601),$S$24:$AA$38,4) | M34: =VLOOKUP(_xlfn.XLOOKUP($A34,'MM configuration'!$D$2:$D$601,'MM configuration'!$C$2:$C$601),$S$24:$AA$38,5) | N34: =VLOOKUP(_xlfn.XLOOKUP($A34,'MM configuration'!$D$2:$D$601,'MM configuration'!$C$2:$C$601),$S$24:$AA$38,6) | O34: =VLOOKUP(_xlfn.XLOOKUP($A34,'MM configuration'!$D$2:$D$601,'MM configuration'!$C$2:$C$601),$S$24:$AA$38,7) | P34: =VLOOKUP(_xlfn.XLOOKUP($A34,'MM configuration'!$D$2:$D$601,'MM configuration'!$C$2:$C$601),$S$24:$AA$38,8) | Q34: =VLOOKUP(_xlfn.XLOOKUP($A34,'MM configuration'!$D$2:$D$601,'MM configuration'!$C$2:$C$601),$S$24:$AA$38,9) | S34: 11 | T34: =T16*(100%-T$5)/$S16 | U34: =U16*(100%-U$5)/$S16 | V34: =V16*(100%-V$5)/$S16 | W34: =W16*(100%-W$5)/$S16 | X34: =X16*(100%-X$5)/$S16 | Y34: =Y16*(100%-Y$5)/$S16 | Z34: =Z16*(100%-Z$5)/$S16 | AA34: =AA16*(100%-AA$5)/$S16
A35: 34 | B35: 0.00185256 | C35: 0.00185256 | J35: =VLOOKUP(_xlfn.XLOOKUP($A35,'MM configuration'!$D$2:$D$601,'MM configuration'!$C$2:$C$601),$S$24:$AA$38,2) | K35: =VLOOKUP(_xlfn.XLOOKUP($A35,'MM configuration'!$D$2:$D$601,'MM configuration'!$C$2:$C$601),$S$24:$AA$38,3) | L35: =VLOOKUP(_xlfn.XLOOKUP($A35,'MM configuration'!$D$2:$D$601,'MM configuration'!$C$2:$C$601),$S$24:$AA$38,4) | M35: =VLOOKUP(_xlfn.XLOOKUP($A35,'MM configuration'!$D$2:$D$601,'MM configuration'!$C$2:$C$601),$S$24:$AA$38,5) | N35: =VLOOKUP(_xlfn.XLOOKUP($A35,'MM configuration'!$D$2:$D$601,'MM configuration'!$C$2:$C$601),$S$24:$AA$38,6) | O35: =VLOOKUP(_xlfn.XLOOKUP($A35,'MM configuration'!$D$2:$D$601,'MM configuration'!$C$2:$C$601),$S$24:$AA$38,7) | P35: =VLOOKUP(_xlfn.XLOOKUP($A35,'MM configuration'!$D$2:$D$601,'MM configuration'!$C$2:$C$601),$S$24:$AA$38,8) | Q35: =VLOOKUP(_xlfn.XLOOKUP($A35,'MM configuration'!$D$2:$D$601,'MM configuration'!$C$2:$C$601),$S$24:$AA$38,9) | S35: 12 | T35: =T17*(100%-T$5)/$S17 | U35: =U17*(100%-U$5)/$S17 | V35: =V17*(100%-V$5)/$S17 | W35: =W17*(100%-W$5)/$S17 | X35: =X17*(100%-X$5)/$S17 | Y35: =Y17*(100%-Y$5)/$S17 | Z35: =Z17*(100%-Z$5)/$S17 | AA35: =AA17*(100%-AA$5)/$S17
A36: 35 | B36: 0.00185256 | C36: 0.00185256 | J36: =VLOOKUP(_xlfn.XLOOKUP($A36,'MM configuration'!$D$2:$D$601,'MM configuration'!$C$2:$C$601),$S$24:$AA$38,2) | K36: =VLOOKUP(_xlfn.XLOOKUP($A36,'MM configuration'!$D$2:$D$601,'MM configuration'!$C$2:$C$601),$S$24:$AA$38,3) | L36: =VLOOKUP(_xlfn.XLOOKUP($A36,'MM configuration'!$D$2:$D$601,'MM configuration'!$C$2:$C$601),$S$24:$AA$38,4) | M36: =VLOOKUP(_xlfn.XLOOKUP($A36,'MM configuration'!$D$2:$D$601,'MM configuration'!$C$2:$C$601),$S$24:$AA$38,5) | N36: =VLOOKUP(_xlfn.XLOOKUP($A36,'MM configuration'!$D$2:$D$601,'MM configuration'!$C$2:$C$601),$S$24:$AA$38,6) | O36: =VLOOKUP(_xlfn.XLOOKUP($A36,'MM configuration'!$D$2:$D$601,'MM configuration'!$C$2:$C$601),$S$24:$AA$38,7) | P36: =VLOOKUP(_xlfn.XLOOKUP($A36,'MM configuration'!$D$2:$D$601,'MM configuration'!$C$2:$C$601),$S$24:$AA$38,8) | Q36: =VLOOKUP(_xlfn.XLOOKUP($A36,'MM configuration'!$D$2:$D$601,'MM configuration'!$C$2:$C$601),$S$24:$AA$38,9) | S36: 13 | T36: =T18*(100%-T$5)/$S18 | U36: =U18*(100%-U$5)/$S18 | V36: =V18*(100%-V$5)/$S18 | W36: =W18*(100%-W$5)/$S18 | X36: =X18*(100%-X$5)/$S18 | Y36: =Y18*(100%-Y$5)/$S18 | Z36: =Z18*(100%-Z$5)/$S18 | AA36: =AA18*(100%-AA$5)/$S18
A37: 36 | B37: 0.0020473333 | C37: 0.0018883933 | J37: =VLOOKUP(_xlfn.XLOOKUP($A37,'MM configuration'!$D$2:$D$601,'MM configuration'!$C$2:$C$601),$S$24:$AA$38,2) | K37: =VLOOKUP(_xlfn.XLOOKUP($A37,'MM configuration'!$D$2:$D$601,'MM configuration'!$C$2:$C$601),$S$24:$AA$38,3) | L37: =VLOOKUP(_xlfn.XLOOKUP($A37,'MM configuration'!$D$2:$D$601,'MM configuration'!$C$2:$C$601),$S$24:$AA$38,4) | M37: =VLOOKUP(_xlfn.XLOOKUP($A37,'MM configuration'!$D$2:$D$601,'MM configuration'!$C$2:$C$601),$S$24:$AA$38,5) | N37: =VLOOKUP(_xlfn.XLOOKUP($A37,'MM configuration'!$D$2:$D$601,'MM configuration'!$C$2:$C$601),$S$24:$AA$38,6) | O37: =VLOOKUP(_xlfn.XLOOKUP($A37,'MM configuration'!$D$2:$D$601,'MM configuration'!$C$2:$C$601),$S$24:$AA$38,7) | P37: =VLOOKUP(_xlfn.XLOOKUP($A37,'MM configuration'!$D$2:$D$601,'MM configuration'!$C$2:$C$601),$S$24:$AA$38,8) | Q37: =VLOOKUP(_xlfn.XLOOKUP($A37,'MM configuration'!$D$2:$D$601,'MM configuration'!$C$2:$C$601),$S$24:$AA$38,9) | S37: 14 | T37: =T19*(100%-T$5)/$S19 | U37: =U19*(100%-U$5)/$S19 | V37: =V19*(100%-V$5)/$S19 | W37: =W19*(100%-W$5)/$S19 | X37: =X19*(100%-X$5)/$S19 | Y37: =Y19*(100%-Y$5)/$S19 | Z37: =Z19*(100%-Z$5)/$S19 | AA37: =AA19*(100%-AA$5)/$S19
A38: 37 | B38: 0.0020473333 | C38: 0.0018883933 | J38: =VLOOKUP(_xlfn.XLOOKUP($A38,'MM configuration'!$D$2:$D$601,'MM configuration'!$C$2:$C$601),$S$24:$AA$38,2) | K38: =VLOOKUP(_xlfn.XLOOKUP($A38,'MM configuration'!$D$2:$D$601,'MM configuration'!$C$2:$C$601),$S$24:$AA$38,3) | L38: =VLOOKUP(_xlfn.XLOOKUP($A38,'MM configuration'!$D$2:$D$601,'MM configuration'!$C$2:$C$601),$S$24:$AA$38,4) | M38: =VLOOKUP(_xlfn.XLOOKUP($A38,'MM configuration'!$D$2:$D$601,'MM configuration'!$C$2:$C$601),$S$24:$AA$38,5) | N38: =VLOOKUP(_xlfn.XLOOKUP($A38,'MM configuration'!$D$2:$D$601,'MM configuration'!$C$2:$C$601),$S$24:$AA$38,6) | O38: =VLOOKUP(_xlfn.XLOOKUP($A38,'MM configuration'!$D$2:$D$601,'MM configuration'!$C$2:$C$601),$S$24:$AA$38,7) | P38: =VLOOKUP(_xlfn.XLOOKUP($A38,'MM configuration'!$D$2:$D$601,'MM configuration'!$C$2:$C$601),$S$24:$AA$38,8) | Q38: =VLOOKUP(_xlfn.XLOOKUP($A38,'MM configuration'!$D$2:$D$601,'MM configuration'!$C$2:$C$601),$S$24:$AA$38,9) | S38: 15 | T38: =T20*(100%-T$5)/$S20 | U38: =U20*(100%-U$5)/$S20 | V38: =V20*(100%-V$5)/$S20 | W38: =W20*(100%-W$5)/$S20 | X38: =X20*(100%-X$5)/$S20 | Y38: =Y20*(100%-Y$5)/$S20 | Z38: =Z20*(100%-Z$5)/$S20 | AA38: =AA20*(100%-AA$5)/$S20
A39: 38 | B39: 0.0020473333 | C39: 0.0018883933 | J39: =VLOOKUP(_xlfn.XLOOKUP($A39,'MM configuration'!$D$2:$D$601,'MM configuration'!$C$2:$C$601),$S$24:$AA$38,2) | K39: =VLOOKUP(_xlfn.XLOOKUP($A39,'MM configuration'!$D$2:$D$601,'MM configuration'!$C$2:$C$601),$S$24:$AA$38,3) | L39: =VLOOKUP(_xlfn.XLOOKUP($A39,'MM configuration'!$D$2:$D$601,'MM configuration'!$C$2:$C$601),$S$24:$AA$38,4) | M39: =VLOOKUP(_xlfn.XLOOKUP($A39,'MM configuration'!$D$2:$D$601,'MM configuration'!$C$2:$C$601),$S$24:$AA$38,5) | N39: =VLOOKUP(_xlfn.XLOOKUP($A39,'MM configuration'!$D$2:$D$601,'MM configuration'!$C$2:$C$601),$S$24:$AA$38,6) | O39: =VLOOKUP(_xlfn.XLOOKUP($A39,'MM configuration'!$D$2:$D$601,'MM configuration'!$C$2:$C$601),$S$24:$AA$38,7) | P39: =VLOOKUP(_xlfn.XLOOKUP($A39,'MM configuration'!$D$2:$D$601,'MM configuration'!$C$2:$C$601),$S$24:$AA$38,8) | Q39: =VLOOKUP(_xlfn.XLOOKUP($A39,'MM configuration'!$D$2:$D$601,'MM configuration'!$C$2:$C$601),$S$24:$AA$38,9)
A40: 39 | B40: 0.0020473333 | C40: 0.0018883933 | J40: =VLOOKUP(_xlfn.XLOOKUP($A40,'MM configuration'!$D$2:$D$601,'MM configuration'!$C$2:$C$601),$S$24:$AA$38,2) | K40: =VLOOKUP(_xlfn.XLOOKUP($A40,'MM configuration'!$D$2:$D$601,'MM configuration'!$C$2:$C$601),$S$24:$AA$38,3) | L40: =VLOOKUP(_xlfn.XLOOKUP($A40,'MM configuration'!$D$2:$D$601,'MM configuration'!$C$2:$C$601),$S$24:$AA$38,4) | M40: =VLOOKUP(_xlfn.XLOOKUP($A40,'MM configuration'!$D$2:$D$601,'MM configuration'!$C$2:$C$601),$S$24:$AA$38,5) | N40: =VLOOKUP(_xlfn.XLOOKUP($A40,'MM configuration'!$D$2:$D$601,'MM configuration'!$C$2:$C$601),$S$24:$AA$38,6) | O40: =VLOOKUP(_xlfn.XLOOKUP($A40,'MM configuration'!$D$2:$D$601,'MM configuration'!$C$2:$C$601),$S$24:$AA$38,7) | P40: =VLOOKUP(_xlfn.XLOOKUP($A40,'MM configuration'!$D$2:$D$601,'MM configuration'!$C$2:$C$601),$S$24:$AA$38,8) | Q40: =VLOOKUP(_xlfn.XLOOKUP($A40,'MM configuration'!$D$2:$D$601,'MM configuration'!$C$2:$C$601),$S$24:$AA$38,9)
A41: 40 | B41: 0.0020473333 | C41: 0.0018883933 | J41: =VLOOKUP(_xlfn.XLOOKUP($A41,'MM configuration'!$D$2:$D$601,'MM configuration'!$C$2:$C$601),$S$24:$AA$38,2) | K41: =VLOOKUP(_xlfn.XLOOKUP($A41,'MM configuration'!$D$2:$D$601,'MM configuration'!$C$2:$C$601),$S$24:$AA$38,3) | L41: =VLOOKUP(_xlfn.XLOOKUP($A41,'MM configuration'!$D$2:$D$601,'MM configuration'!$C$2:$C$601),$S$24:$AA$38,4) | M41: =VLOOKUP(_xlfn.XLOOKUP($A41,'MM configuration'!$D$2:$D$601,'MM configuration'!$C$2:$C$601),$S$24:$AA$38,5) | N41: =VLOOKUP(_xlfn.XLOOKUP($A41,'MM configuration'!$D$2:$D$601,'MM configuration'!$C$2:$C$601),$S$24:$AA$38,6) | O41: =VLOOKUP(_xlfn.XLOOKUP($A41,'MM configuration'!$D$2:$D$601,'MM configuration'!$C$2:$C$601),$S$24:$AA$38,7) | P41: =VLOOKUP(_xlfn.XLOOKUP($A41,'MM configuration'!$D$2:$D$601,'MM configuration'!$C$2:$C$601),$S$24:$AA$38,8) | Q41: =VLOOKUP(_xlfn.XLOOKUP($A41,'MM configuration'!$D$2:$D$601,'MM configuration'!$C$2:$C$601),$S$24:$AA$38,9)
A42: 41 | B42: 0.0020473333 | C42: 0.0018883933 | J42: =VLOOKUP(_xlfn.XLOOKUP($A42,'MM configuration'!$D$2:$D$601,'MM configuration'!$C$2:$C$601),$S$24:$AA$38,2) | K42: =VLOOKUP(_xlfn.XLOOKUP($A42,'MM configuration'!$D$2:$D$601,'MM configuration'!$C$2:$C$601),$S$24:$AA$38,3) | L42: =VLOOKUP(_xlfn.XLOOKUP($A42,'MM configuration'!$D$2:$D$601,'MM configuration'!$C$2:$C$601),$S$24:$AA$38,4) | M42: =VLOOKUP(_xlfn.XLOOKUP($A42,'MM configuration'!$D$2:$D$601,'MM configuration'!$C$2:$C$601),$S$24:$AA$38,5) | N42: =VLOOKUP(_xlfn.XLOOKUP($A42,'MM configuration'!$D$2:$D$601,'MM configuration'!$C$2:$C$601),$S$24:$AA$38,6) | O42: =VLOOKUP(_xlfn.XLOOKUP($A42,'MM configuration'!$D$2:$D$601,'MM configuration'!$C$2:$C$601),$S$24:$AA$38,7) | P42: =VLOOKUP(_xlfn.XLOOKUP($A42,'MM configuration'!$D$2:$D$601,'MM configuration'!$C$2:$C$601),$S$24:$AA$38,8) | Q42: =VLOOKUP(_xlfn.XLOOKUP($A42,'MM configuration'!$D$2:$D$601,'MM configuration'!$C$2:$C$601),$S$24:$AA$38,9)
...

Sheet Vignetting rotazi
A1: Position # | B1: Vignetting rotazi | C1: Selected energy [keV] | H1: Row | I1: rotazi [arcmin] | J1: energy [keV] | K1: vignetting_factor
A2: 1 | B2: 0.98784493 | C2: 1 | H2: 1 | I2: 0 | J2: 0.2 | K2: 0.97419871
A3: 2 | B3: 0.97696363 | H3: 1 | I3: 0.5 | J3: 0.2 | K3: 1
A4: 3 | B4: 0.98296647 | H4: 1 | I4: 1 | J4: 0.2 | K4: 0.95480187
A5: 4 | B5: 0.98777929 | H5: 1 | I5: 2 | J5: 0.2 | K5: 0.9165432
A6: 5 | B6: 0.99892635 | H6: 1 | I6: 3 | J6: 0.2 | K6: 0.89139098
A7: 6 | B7: 0.9966326 | H7: 1 | I7: 5 | J7: 0.2 | K7: 0.70769284
A8: 7 | B8: 0.99416582 | H8: 1 | I8: 7 | J8: 0.2 | K8: 0.65622161
A9: 8 | B9: 0.98746454 | H9: 1 | I9: 10 | J9: 0.2 | K9: 0.53951269
A10: 9 | B10: 0.98247354 | H10: 1 | I10: 15 | J10: 0.2 | K10: 0.33934718
A11: 10 | B11: 0.97531913 | H11: 1 | I11: 20 | J11: 0.2 | K11: 0.17057471
A12: 11 | B12: 0.96821376 | H12: 1 | I12: 28 | J12: 0.2 | K12: 0.006274835
A13: 12 | B13: 0.97885521 | H13: 2 | I13: 0 | J13: 0.2 | K13: 1
A14: 13 | B14: 0.93605829 | H14: 2 | I14: 0.5 | J14: 0.2 | K14: 0.98066948
... A601: 600 | B601: 0.47925667 | H601: 10 | I601: 5 | J601: 2 | K601: 0.92109286
H602: 10 | I602: 7 | J602: 2 | K602: 0.89383555
H603: 10 | I603: 10 | J603: 2 | K603: 0.89367774
H604: 10 | I604: 15 | J604: 2 | K604: 0.82971826
H605: 10 | I605: 20 | J605: 2 | K605: 0.73936424
H606: 10 | I606: 28 | J606: 2 | K606: 0.62646802
H607: 11 | I607: 0 | J607: 2 | K607: 1
H608: 11 | I608: 0.5 | J608: 2 | K608: 0.96808599
H609: 11 | I609: 1 | J609: 2 | K609: 0.97056059
H610: 11 | I610: 2 | J610: 2 | K610: 0.97800108
H611: 11 | I611: 3 | J611: 2 | K611: 0.94362587
H612: 11 | I612: 5 | J612: 2 | K612: 0.92396143
H613: 11 | I613: 7 | J613: 2 | K613: 0.90268246
... H811: 14 | I811: 7 | J811: 4 | K811: 0.91994838
H812: 14 | I812: 10 | J812: 4 | K812: 0.89908984 | M812: 0.95480187
H813: 14 | I813: 15 | J813: 4 | K813: 0.82107265 | M813: 0.95480187
H814: 14 | I814: 20 | J814: 4 | K814: 0.78591052 | M814: 0.95480187
H815: 14 | I815: 28 | J815: 4 | K815: 0.68176846 | M815: 0.95480187
H816: 15 | I816: 0 | J816: 4 | K816: 1 | M816: 0.92691529
H817: 15 | I817: 0.5 | J817: 4 | K817: 0.97183356
H818: 15 | I818: 1 | J818: 4 | K818: 0.97008053
H819: 15 | I819: 2 | J819: 4 | K819: 0.97327504
H820: 15 | I820: 3 | J820: 4 | K820: 0.97410806
H821: 15 | I821: 5 | J821: 4 | K821: 0.94059052
H822: 15 | I822: 7 | J822: 4 | K822: 0.92942466
H823: 15 | I823: 10 | J823: 4 | K823: 0.90029348
...

Sheet Vignetting rotrad
A1: Position # | B1: Vignetting rotrad | C1: Selected energy [keV] | H1: Row | I1: rotrad [arcmin] | J1: energy [keV] | K1: vignetting_factor
A2: 1 | B2: 1 | C2: 1 | H2: 1 | I2: 0 | J2: 0.2 | K2: 0.99481295
A3: 2 | B3: 1 | H3: 1 | I3: 0.5 | J3: 0.2 | K3: 1
A4: 3 | B4: 1 | H4: 1 | I4: 1 | J4: 0.2 | K4: 0.9531962
A5: 4 | B5: 1 | H5: 1 | I5: 2 | J5: 0.2 | K5: 0.89559177
A6: 5 | B6: 0.96767736 | H6: 1 | I6: 3 | J6: 0.2 | K6: 0.75600658
A7: 6 | B7: 0.77225869 | H7: 1 | I7: 5 | J7: 0.2 | K7: 0.49594156
A8: 7 | B8: 0.96956509 | H8: 1 | I8: 7 | J8: 0.2 | K8: 0.29026445
A9: 8 | B9: 1 | H9: 1 | I9: 10 | J9: 0.2 | K9: 0.055083971
A10: 9 | B10: 0.98497337 | H10: 1 | I10: 15 | J10: 0.2 | K10: 0
A11: 10 | B11: 0.97047959 | H11: 1 | I11: 20 | J11: 0.2 | K11: 0
A12: 11 | B12: 0.92585571 | H12: 1 | I12: 28 | J12: 0.2 | K12: 0
A13: 12 | B13: 0.97580459 | H13: 2 | I13: 0 | J13: 0.2 | K13: 0.99688871
A14: 13 | B14: 0.22655218 | H14: 2 | I14: 0.5 | J14: 0.2 | K14: 0.98021879
... A601: 600 | B601: 0.2650157 | H601: 10 | I601: 5 | J601: 2 | K601: 0.87070204
H602: 10 | I602: 7 | J602: 2 | K602: 0.8086788
H603: 10 | I603: 10 | J603: 2 | K603: 0.66201125
H604: 10 | I604: 15 | J604: 2 | K604: 0.4455184
H605: 10 | I605: 20 | J605: 2 | K605: 0.2847474
H606: 10 | I606: 28 | J606: 2 | K606: 0.056912287
H607: 11 | I607: 0 | J607: 2 | K607: 1
H608: 11 | I608: 0.5 | J608: 2 | K608: 0.98222625
H609: 11 | I609: 1 | J609: 2 | K609: 0.96184788
H610: 11 | I610: 2 | J610: 2 | K610: 0.95524817
H611: 11 | I611: 3 | J611: 2 | K611: 0.91885662
H612: 11 | I612: 5 | J612: 2 | K612: 0.85161229
H613: 11 | I613: 7 | J613: 2 | K613: 0.7650905
... H1321: 15 | I1321: 28 | J1321: 12 | K1321: 0.1637729

Sheet MM_PSF
A1: MM # | B1: m_rad [arcsec] | C1: m_azi [arcsec] | D1: sigma_rad [arcsec] | E1: sigma_azi [arcsec] | F1: distribution | G1: alpha_rad | H1: alpha_azi | K1: Standard MM_PSF distributions | L1: sigma_rad_ | M1: sigma_azi_ | N1: alpha_rad_ | O1: alpha_azi_
A2: 1 | B2: 0 | C2: 0 | D2: 3.2098945 | E2: 2.3253623 | F2: gaussian | K2: Fixed Sym Gaussian 0.01" | L2: 0.01 | M2: 0.01 | N2: - | O2: -
A3: 2 | B3: 0 | C3: 0 | D3: 1.3196708 | E3: 4.2341806 | F3: gaussian | K3: Fixed Sym Gaussian 4.3" | L3: 1.82635 | M3: 1.82635 | N3: - | O3: - | Q3: From NewAthena Reference telescope design
A4: 3 | B4: 0 | C4: 0 | D4: 3.1144037 | E4: 0.51435662 | F4: gaussian | K4: Fixed Sym Gaussian 8" | L4: 3.39833 | M4: 3.39833 | N4: - | O4: -
A5: 4 | B5: 0 | C5: 0 | D5: 7.3489902 | E5: 1.348912 | F5: gaussian | K5: Fixed Asym Gaussian 4.3" (ratio 4:1) | L5: 2.9637409 | M5: 0.74093523 | N5: - | O5: -
A6: 5 | B6: 0 | C6: 0 | D6: 2.7305294 | E6: 1.5789585 | F6: gaussian | K6: Fixed Asym Gaussian 8" (ratio 7:1) | L6: 5.7972051 | M6: 0.82817216 | N6: - | O6: -
A7: 6 | B7: 0 | C7: 0 | D7: 2.3373613 | E7: 3.724608 | F7: gaussian | K7: Fixed Pseudo-Voigt 4.3" | L7: 2.22057 | M7: 0.679177 | N7: 0.77 | O7: 0.29
A8: 7 | B8: 0 | C8: 0 | D8: 3.6233353 | E8: 4.0265651 | F8: gaussian | K8: Fixed Pseudo-Voigt 8" | L8: 4.1303 | M8: 1.2633 | N8: 0.77 | O8: 0.29
A9: 8 | B9: 0 | C9: 0 | D9: 5.8543212 | E9: 8.6642053 | F9: gaussian | K9: 10% Variable Sym Gaussian 4.3" | L9: gamma (1.82635,10%*1.82635) | M9: gamma (1.82635,10%*1.82635) | N9: - | O9: -
A10: 9 | B10: 0 | C10: 0 | D10: 6.138911 | E10: 5.6608167 | F10: gaussian | K10: 30% Variable Sym Gaussian 4.3" | L10: gamma (1.82635,30%*1.82635) | M10: gamma (1.82635,30%*1.82635) | N10: - | O10: -
A11: 10 | B11: 0 | C11: 0 | D11: 5.9479009 | E11: 4.0694511 | F11: gaussian | K11: 50% Variable Sym Gaussian 4.3" | L11: gamma (1.82635,50%*1.82635) | M11: gamma (1.82635,50%*1.82635) | N11: - | O11: -
A12: 11 | B12: 0 | C12: 0 | D12: 2.7213236 | E12: 5.1652825 | F12: gaussian | K12: 10% Variable Sym Gaussian 8" | L12: gamma (3.39833,10%*3.39833) | M12: gamma (3.39833,10%*3.39833) | N12: - | O12: -
A13: 12 | B13: 0 | C13: 0 | D13: 3.0300301 | E13: 2.3760608 | F13: gaussian | K13: 30% Variable Sym Gaussian 8" | L13: gamma (3.39833,30%*3.39833) | M13: gamma (3.39833,30%*3.39833) | N13: - | O13: -
A14: 13 | B14: 0 | C14: 0 | D14: 5.2985798 | E14: 3.7336244 | F14: gaussian | K14: 50% Variable Sym Gaussian 8" | L14: gamma (3.39833,50%*3.39833) | M14: gamma (3.39833,50%*3.39833) | N14: - | O14: -
A15: 14 | B15: 0 | C15: 0 | D15: 1.8102181 | E15: 8.92371 | F15: gaussian | K15: 10% Variable Asym Gaussian 4.3" (ratio 4:1) | L15: gamma (2.96374,10%*2.96374) | M15: gamma (0.74093,10%*0.74093) | N15: - | O15: -
A16: 15 | B16: 0 | C16: 0 | D16: 5.0104031 | E16: 3.077386 | F16: gaussian | K16: 30% Variable Asym Gaussian 4.3" (ratio 4:1) | L16: gamma (2.96374,30%*2.96374) | M16: gamma (0.74093,30%*0.74093) | N16: - | O16: -
A17: 16 | B17: 0 | C17: 0 | D17: 3.5605108 | E17: 2.7428953 | F17: gaussian | K17: 50% Variable Asym Gaussian 4.3" (ratio 4:1) | L17: gamma (2.96374,50%*2.96374) | M17: gamma (0.74093,50%*0.74093) | N17: - | O17: -
A18: 17 | B18: 0 | C18: 0 | D18: 1.5227586 | E18: 0.71130894 | F18: gaussian | K18: 10% Variable Asym Gaussian 8" (ratio 7:1) | L18: gamma (5.79720,10%*5.79720) | M18: gamma (0.82817,10%*0.82817) | N18: - | O18: -
A19: 18 | B19: 0 | C19: 0 | D19: 2.9294451 | E19: 5.3403858 | F19: gaussian | K19: 30% Variable Asym Gaussian 8" (ratio 7:1) | L19: gamma (5.79720,30%*5.79720) | M19: gamma (0.82817,30%*0.82817) | N19: - | O19: -
A20: 19 | B20: 0 | C20: 0 | D20: 3.865903 | E20: 3.4191907 | F20: gaussian | K20: 50% Variable Asym Gaussian 8" (ratio 7:1) | L20: gamma (5.79720,50%*5.79720) | M20: gamma (0.82817,50%*0.82817) | N20: - | O20: -
... A26: 25 | B26: 0 | C26: 0 | D26: 2.1542752 | E26: 1.8036325 | F26: gaussian | K26: 50% Variable Pseudo-Voigt 8" (alpha 10%) | L26: gamma (4.1303,50%*4.1303) | M26: gamma (1.2633,50%*1.2633) | N26: gamma(0.77,10%*0.77) | O26: gamma(0.29,10%*0.29)
A27: 26 | B27: 0 | C27: 0 | D27: 3.8319353 | E27: 2.3064531 | F27: gaussian | K27: Variable cosine | L27: 2.2+gamma (5.79720-2.2,10%*(5.79720-2.2))
A28: 27 | B28: 0 | C28: 0 | D28: 4.0761994 | E28: 1.9108528 | F28: gaussian
A29: 28 | B29: 0 | C29: 0 | D29: 4.5923231 | E29: 2.2986014 | F29: gaussian
A30: 29 | B30: 0 | C30: 0 | D30: 2.8938162 | E30: 2.9463997 | F30: gaussian | K30: Row | L30: width | M30: length | N30: sigma_rad | O30: sigma_azi | P30: HEW_MM
A31: 30 | B31: 0 | C31: 0 | D31: 3.1090871 | E31: 3.8567138 | F31: gaussian | K31: 1 | L31: 40.222607 | M31: 109.45998 | N31: 8 | O31: 2.2 | P31: 7.66
A32: 31 | B32: 0 | C32: 0 | D32: 3.0747829 | E32: 2.9219533 | F32: gaussian | K32: 2 | L32: 58.079423 | M32: 87.604116 | N32: 8 | O32: 2.2 | P32: 7.83
A33: 32 | B33: 0 | C33: 0 | D33: 3.4615557 | E33: 1.6291007 | F33: gaussian | K33: 3 | L33: 75.933488 | M33: 73.03118 | N33: 8 | O33: 2.2 | P33: 7.96
A34: 33 | B34: 0 | C34: 0 | D34: 10.231479 | E34: 0.51362346 | F34: gaussian | K34: 4 | L34: 71.128591 | M34: 62.617463 | N34: 8 | O34: 2.2 | P34: 8
A35: 34 | B35: 0 | C35: 0 | D35: 2.5049259 | E35: 1.049385 | F35: gaussian | K35: 5 | L35: 85.410004 | M35: 54.801293 | N35: 8 | O35: 2.2 | P35: 8.08
A36: 35 | B36: 0 | C36: 0 | D36: 5.3037328 | E36: 2.6370435 | F36: gaussian | K36: 6 | L36: 79.825493 | M36: 48.721047 | N36: =$N$31+($M36-$M$31)/($M$45-$M$31)*($N$45-$N$31) | O36: =$O$31+($L36-$L$31)/($L$45-$L$31)*($O$45-$O$31) | P36: 8.1
A37: 36 | B37: 0 | C37: 0 | D37: 7.781383 | E37: 3.2325477 | F37: gaussian | K37: 7 | L37: 75.836188 | M37: 43.854908 | N37: =$N$31+($M37-$M$31)/($M$45-$M$31)*($N$45-$N$31) | O37: =$O$31+($L37-$L$31)/($L$45-$L$31)*($O$45-$O$31) | P37: 8.11
A38: 37 | B38: 0 | C38: 0 | D38: 5.3811832 | E38: 6.9276333 | F38: gaussian | K38: 8 | L38: 86.035942 | M38: 39.871414 | N38: =$N$31+($M38-$M$31)/($M$45-$M$31)*($N$45-$N$31) | O38: =$O$31+($L38-$L$31)/($L$45-$L$31)*($O$45-$O$31) | P38: 8.16
A39: 38 | B39: 0 | C39: 0 | D39: 2.4263226 | E39: 7.6008596 | F39: gaussian | K39: 9 | L39: 96.235263 | M39: 36.549135 | N39: =$N$31+($M39-$M$31)/($M$45-$M$31)*($N$45-$N$31) | O39: =$O$31+($L39-$L$31)/($L$45-$L$31)*($O$45-$O$31) | P39: 8.21
A40: 39 | B40: 0 | C40: 0 | D40: 3.5931058 | E40: 6.9835677 | F40: gaussian | K40: 10 | L40: 90.594139 | M40: 33.767506 | N40: =$N$31+($M40-$M$31)/($M$45-$M$31)*($N$45-$N$31) | O40: =$O$31+($L40-$L$31)/($L$45-$L$31)*($O$45-$O$31) | P40: 8.21
A41: 40 | B41: 0 | C41: 0 | D41: 4.5162072 | E41: 3.4553842 | F41: gaussian | K41: 11 | L41: 99.419574 | M41: 31.378308 | N41: =$N$31+($M41-$M$31)/($M$45-$M$31)*($N$45-$N$31) | O41: =$O$31+($L41-$L$31)/($L$45-$L$31)*($O$45-$O$31) | P41: 8.25
A42: 41 | B42: 0 | C42: 0 | D42: 2.420345 | E42: 2.0459089 | F42: gaussian | K42: 12 | L42: 108.24457 | M42: 29.302979 | N42: =$N$31+($M42-$M$31)/($M$45-$M$31)*($N$45-$N$31) | O42: =$O$31+($L42-$L$31)/($L$45-$L$31)*($O$45-$O$31) | P42: 8.28
A43: 42 | B43: 0 | C43: 0 | D43: 1.4768249 | E43: 4.6894424 | F43: gaussian | K43: 13 | L43: 101.89474 | M43: 27.484354 | N43: =$N$31+($M43-$M$31)/($M$45-$M$31)*($N$45-$N$31) | O43: =$O$31+($L43-$L$31)/($L$45-$L$31)*($O$45-$O$31) | P43: 8.27
A44: 43 | B44: 0 | C44: 0 | D44: 1.4510093 | E44: 2.6059095 | F44: gaussian | K44: 14 | L44: 109.73834 | M44: 25.87863 | N44: =$N$31+($M44-$M$31)/($M$45-$M$31)*($N$45-$N$31) | O44: =$O$31+($L44-$L$31)/($L$45-$L$31)*($O$45-$O$31) | P44: 8.31
A45: 44 | B45: 0 | C45: 0 | D45: 2.8201322 | E45: 1.8291144 | F45: gaussian | K45: 15 | L45: 117.58149 | M45: 24.448518 | N45: 4.3 | O45: 1.3 | P45: 8.34
...

Sheet Alignment
A1: Position # | B1: d_align_rad [µm] | C1: d_align_azi [µm] | D1: d_align_z [µm] | E1: d_align_rotazi [arcsec] | F1: d_align_rotrad [arcsec] | G1: d_align_rotz [arcsec] | I1: Standard alignment distributions | J1: d_align_rad_ | K1: d_align_azi_ | L1: d_align_z_ | M1: d_align_rotazi_ | N1: d_align_rotrad_ | O1: d_align_rotz_ | Q1: From MLT documentation (2018) - max values assumed 3 sigma, % is assumed uniform distribution | R1: Unnamed: 5 | S1: Unnamed: 11
A2: 1 | B2: 0 | C2: 0 | D2: 0 | E2: 0 | F2: 0 | G2: 0 | I2: Standard medialario | J2: gaussian (0, 12/3) | K2: gaussian (0, 12/3) | L2: gaussian (0, (380+23+1500+93)/3) | M2: uniform (-30, 30) | N2: uniform (-120, 120) | O2: uniform (-9, 9)
A3: 2 | B3: 0 | C3: 0 | D3: 0 | E3: 0 | F3: 0 | G3: 0 | I3: 10% worse medialario | J3: gaussian (0, 12/3*110%) | K3: gaussian (0, 12/3*110%) | L3: gaussian (0, (380+23+1500+93)/3*110%) | M3: uniform (-30*110%, 30*110%) | N3: uniform (-120*110%, 120*110%) | O3: uniform (-9*110%, 9*110%)
A4: 3 | B4: 0 | C4: 0 | D4: 0 | E4: 0 | F4: 0 | G4: 0 | I4: 30% worse medialario | J4: gaussian (0, 12/3*130%) | K4: gaussian (0, 12/3*130%) | L4: gaussian (0, (380+23+1500+93)/3*130%) | M4: uniform (-30*130%, 30*130%) | N4: uniform (-120*130%, 120*130%) | O4: uniform (-9*130%, 9*130%)
A5: 4 | B5: 0 | C5: 0 | D5: 0 | E5: 0 | F5: 0 | G5: 0 | I5: 50% worse medialario | J5: gaussian (0, 12/3*150%) | K5: gaussian (0, 12/3*150%) | L5: gaussian (0, (380+23+1500+93)/3*150%) | M5: uniform (-30*150%, 30*150%) | N5: uniform (-120*150%, 120*150%) | O5: uniform (-9*150%, 9*150%)
A6: 5 | B6: 0 | C6: 0 | D6: 0 | E6: 0 | F6: 0 | G6: 0 | I6: 100% worse medialario | J6: gaussian (0, 12/3*200%) | K6: gaussian (0, 12/3*200%) | L6: gaussian (0, (380+23+1500+93)/3*200%) | M6: uniform (-30*200%, 30*200%) | N6: uniform (-120*200%, 120*200%) | O6: uniform (-9*200%, 9*200%)
A7: 6 | B7: 0 | C7: 0 | D7: 0 | E7: 0 | F7: 0 | G7: 0
A8: 7 | B8: 0 | C8: 0 | D8: 0 | E8: 0 | F8: 0 | G8: 0
A9: 8 | B9: 0 | C9: 0 | D9: 0 | E9: 0 | F9: 0 | G9: 0
A10: 9 | B10: 0 | C10: 0 | D10: 0 | E10: 0 | F10: 0 | G10: 0
A11: 10 | B11: 0 | C11: 0 | D11: 0 | E11: 0 | F11: 0 | G11: 0
A12: 11 | B12: 0 | C12: 0 | D12: 0 | E12: 0 | F12: 0 | G12: 0
A13: 12 | B13: 0 | C13: 0 | D13: 0 | E13: 0 | F13: 0 | G13: 0
A14: 13 | B14: 0 | C14: 0 | D14: 0 | E14: 0 | F14: 0 | G14: 0
