Workbook

Sheet MM configuration
A1: Position # | B1: Petal # | C1: Row # | D1: MM # | E1: x_MM [m] | F1: y_MM [m] | G1: z_MM [m] | H1: r_MM [m]
A2: 1 | B2: 1 | C2: 1 | D2: 1 | E2: 0.043401333 | F2: 0.271106 | G2: 0.0031507873 | H2: 0.27455808
A3: 2 | B3: 1 | C3: 1 | D3: 2 | E3: 0.10741849 | F3: 0.25267253 | G3: 0.0031507873 | H3: 0.27455808
A4: 3 | B4: 1 | C4: 1 | D4: 3 | E4: 0.16511158 | F4: 0.21936341 | G4: 0.0031507873 | H4: 0.27455808
A5: 4 | B5: 1 | C5: 1 | D5: 4 | E5: 0.21308402 | F5: 0.17313966 | G5: 0.0031507873 | H5: 0.27455808
A6: 5 | B6: 1 | C6: 2 | D6: 5 | E6: 0.05212616 | F6: 0.33875848 | G6: 0.0049052246 | H6: 0.34274545
A7: 6 | B7: 1 | C7: 2 | D7: 6 | E7: 0.13345813 | F7: 0.31569507 | G7: 0.0049052246 | H7: 0.34274545
A8: 7 | B8: 1 | C8: 2 | D8: 7 | E8: 0.20667088 | F8: 0.27342566 | G8: 0.0049052246 | H8: 0.34274545
A9: 8 | B9: 1 | C9: 2 | D9: 8 | E9: 0.26731037 | F9: 0.21452182 | G9: 0.0049052246 | H9: 0.34274545
A10: 9 | B10: 1 | C10: 3 | D10: 9 | E10: 0.060914095 | F10: 0.40639176 | G10: 0.0070475585 | H10: 0.41093161
A11: 10 | B11: 1 | C11: 3 | D11: 10 | E11: 0.15951698 | F11: 0.37870717 | G11: 0.0070475585 | H11: 0.41093161
A12: 11 | B12: 1 | C12: 3 | D12: 11 | E12: 0.24821154 | F12: 0.32749934 | G12: 0.0070475585 | H12: 0.41093161
A13: 12 | B13: 1 | C13: 3 | D13: 12 | E13: 0.32148854 | F13: 0.25594903 | G13: 0.0070475585 | H13: 0.41093161
... A601: 600 | B601: 6 | C601: 15 | D601: 600 | E601: -0.079467227 | F601: 1.2219025 | G601: 0.06264642 | H601: 1.2244839

Sheet A_eff
A1: MM # | B1: A_eff | D1: Standard distributions A_eff | E1: Values | J1: A_eff @0.25 keV | K1: A_eff @0.35 keV | L1: A_eff @1 keV | M1: A_eff @2.5 keV | N1: A_eff @7 keV | O1: A_eff @10 keV
A2: 1 | B2: 0.0011432763 | D2: 0.25 keV | E2: J | J2: =VLOOKUP(_xlfn.XLOOKUP($A2,'MM configuration'!$D$2:$D$601,'MM configuration'!$C$2:$C$601),$S$24:$Y$38,2) -> 0.0011545041 | K2: =VLOOKUP(_xlfn.XLOOKUP($A2,'MM configuration'!$D$2:$D$601,'MM configuration'!$C$2:$C$601),$S$24:$Y$38,3) -> 0.00106802 | L2: =VLOOKUP(_xlfn.XLOOKUP($A2,'MM configuration'!$D$2:$D$601,'MM configuration'!$C$2:$C$601),$S$24:$Y$38,4) -> 0.0011432763 | M2: =VLOOKUP(_xlfn.XLOOKUP($A2,'MM configuration'!$D$2:$D$601,'MM configuration'!$C$2:$C$601),$S$24:$Y$38,5) -> 0.001098281 | N2: =VLOOKUP(_xlfn.XLOOKUP($A2,'MM configuration'!$D$2:$D$601,'MM configuration'!$C$2:$C$601),$S$24:$Y$38,6) -> 0.0010808679 | O2: =VLOOKUP(_xlfn.XLOOKUP($A2,'MM configuration'!$D$2:$D$601,'MM configuration'!$C$2:$C$601),$S$24:$Y$38,7) -> 0.00082167111 | R2: From effective area budget (05/02/2025). It includes the reductions due to losses at MM level, 7% losses at MAM level and the also the ESA system margin) - results in green
A3: 2 | B3: 0.0011432763 | D3: 0.35 keV | E3: K | J3: =VLOOKUP(_xlfn.XLOOKUP($A3,'MM configuration'!$D$2:$D$601,'MM configuration'!$C$2:$C$601),$S$24:$Y$38,2) -> 0.0011545041 | K3: =VLOOKUP(_xlfn.XLOOKUP($A3,'MM configuration'!$D$2:$D$601,'MM configuration'!$C$2:$C$601),$S$24:$Y$38,3) -> 0.00106802 | L3: =VLOOKUP(_xlfn.XLOOKUP($A3,'MM configuration'!$D$2:$D$601,'MM configuration'!$C$2:$C$601),$S$24:$Y$38,4) -> 0.0011432763 | M3: =VLOOKUP(_xlfn.XLOOKUP($A3,'MM configuration'!$D$2:$D$601,'MM configuration'!$C$2:$C$601),$S$24:$Y$38,5) -> 0.001098281 | N3: =VLOOKUP(_xlfn.XLOOKUP($A3,'MM configuration'!$D$2:$D$601,'MM configuration'!$C$2:$C$601),$S$24:$Y$38,6) -> 0.0010808679 | O3: =VLOOKUP(_xlfn.XLOOKUP($A3,'MM configuration'!$D$2:$D$601,'MM configuration'!$C$2:$C$601),$S$24:$Y$38,7) -> 0.00082167111
A4: 3 | B4: 0.0011432763 | D4: 1 keV | E4: L | J4: =VLOOKUP(_xlfn.XLOOKUP($A4,'MM configuration'!$D$2:$D$601,'MM configuration'!$C$2:$C$601),$S$24:$Y$38,2) -> 0.0011545041 | K4: =VLOOKUP(_xlfn.XLOOKUP($A4,'MM configuration'!$D$2:$D$601,'MM configuration'!$C$2:$C$601),$S$24:$Y$38,3) -> 0.00106802 | L4: =VLOOKUP(_xlfn.XLOOKUP($A4,'MM configuration'!$D$2:$D$601,'MM configuration'!$C$2:$C$601),$S$24:$Y$38,4) -> 0.0011432763 | M4: =VLOOKUP(_xlfn.XLOOKUP($A4,'MM configuration'!$D$2:$D$601,'MM configuration'!$C$2:$C$601),$S$24:$Y$38,5) -> 0.001098281 | N4: =VLOOKUP(_xlfn.XLOOKUP($A4,'MM configuration'!$D$2:$D$601,'MM configuration'!$C$2:$C$601),$S$24:$Y$38,6) -> 0.0010808679 | O4: =VLOOKUP(_xlfn.XLOOKUP($A4,'MM configuration'!$D$2:$D$601,'MM configuration'!$C$2:$C$601),$S$24:$Y$38,7) -> 0.00082167111 | S4: Energies | T4: @0.25 keV | U4: @0.35 keV | V4: @1 keV | W4: @2.5 keV | X4: @7 keV | Y4: @10 keV
A5: 4 | B5: 0.0011432763 | D5: 2.5 keV | E5: M | J5: =VLOOKUP(_xlfn.XLOOKUP($A5,'MM configuration'!$D$2:$D$601,'MM configuration'!$C$2:$C$601),$S$24:$Y$38,2) -> 0.0011545041 | K5: =VLOOKUP(_xlfn.XLOOKUP($A5,'MM configuration'!$D$2:$D$601,'MM configuration'!$C$2:$C$601),$S$24:$Y$38,3) -> 0.00106802 | L5: =VLOOKUP(_xlfn.XLOOKUP($A5,'MM configuration'!$D$2:$D$601,'MM configuration'!$C$2:$C$601),$S$24:$Y$38,4) -> 0.0011432763 | M5: =VLOOKUP(_xlfn.XLOOKUP($A5,'MM configuration'!$D$2:$D$601,'MM configuration'!$C$2:$C$601),$S$24:$Y$38,5) -> 0.001098281 | N5: =VLOOKUP(_xlfn.XLOOKUP($A5,'MM configuration'!$D$2:$D$601,'MM configuration'!$C$2:$C$601),$S$24:$Y$38,6) -> 0.0010808679 | O5: =VLOOKUP(_xlfn.XLOOKUP($A5,'MM configuration'!$D$2:$D$601,'MM configuration'!$C$2:$C$601),$S$24:$Y$38,7) -> 0.00082167111 | R5: Row | S5: System Margin | T5: 0.0968 | U5: 0.0703 | V5: 0.0704 | W5: 0.0466 | X5: -0.0219 | Y5: 0.0187
A6: 5 | B6: 0.0016374246 | D6: 7 keV | E6: N | J6: =VLOOKUP(_xlfn.XLOOKUP($A6,'MM configuration'!$D$2:$D$601,'MM configuration'!$C$2:$C$601),$S$24:$Y$38,2) -> 0.001673464 | K6: =VLOOKUP(_xlfn.XLOOKUP($A6,'MM configuration'!$D$2:$D$601,'MM configuration'!$C$2:$C$601),$S$24:$Y$38,3) -> 0.0015071289 | L6: =VLOOKUP(_xlfn.XLOOKUP($A6,'MM configuration'!$D$2:$D$601,'MM configuration'!$C$2:$C$601),$S$24:$Y$38,4) -> 0.0016374246 | M6: =VLOOKUP(_xlfn.XLOOKUP($A6,'MM configuration'!$D$2:$D$601,'MM configuration'!$C$2:$C$601),$S$24:$Y$38,5) -> 0.0015485679 | N6: =VLOOKUP(_xlfn.XLOOKUP($A6,'MM configuration'!$D$2:$D$601,'MM configuration'!$C$2:$C$601),$S$24:$Y$38,6) -> 0.0013017643 | O6: =VLOOKUP(_xlfn.XLOOKUP($A6,'MM configuration'!$D$2:$D$601,'MM configuration'!$C$2:$C$601),$S$24:$Y$38,7) -> 0.00080565957 | R6: 1 | S6: 24 | T6: 0.0306777 | U6: 0.0275707 | V6: 0.0295166 | W6: 0.0276471 | X6: 0.0253849 | Y6: 0.0200959
A7: 6 | B7: 0.0016374246 | D7: 10 keV | E7: O | J7: =VLOOKUP(_xlfn.XLOOKUP($A7,'MM configuration'!$D$2:$D$601,'MM configuration'!$C$2:$C$601),$S$24:$Y$38,2) -> 0.001673464 | K7: =VLOOKUP(_xlfn.XLOOKUP($A7,'MM configuration'!$D$2:$D$601,'MM configuration'!$C$2:$C$601),$S$24:$Y$38,3) -> 0.0015071289 | L7: =VLOOKUP(_xlfn.XLOOKUP($A7,'MM configuration'!$D$2:$D$601,'MM configuration'!$C$2:$C$601),$S$24:$Y$38,4) -> 0.0016374246 | M7: =VLOOKUP(_xlfn.XLOOKUP($A7,'MM configuration'!$D$2:$D$601,'MM configuration'!$C$2:$C$601),$S$24:$Y$38,5) -> 0.0015485679 | N7: =VLOOKUP(_xlfn.XLOOKUP($A7,'MM configuration'!$D$2:$D$601,'MM configuration'!$C$2:$C$601),$S$24:$Y$38,6) -> 0.0013017643 | O7: =VLOOKUP(_xlfn.XLOOKUP($A7,'MM configuration'!$D$2:$D$601,'MM configuration'!$C$2:$C$601),$S$24:$Y$38,7) -> 0.00080565957 | R7: 2 | S7: 24 | T7: 0.0444676 | U7: 0.0389062 | V7: 0.0422743 | W7: 0.0389822 | X7: 0.0305728 | Y7: 0.0197043
A8: 7 | B8: 0.0016374246 | D8: Variable 5% 0.25 keV | E8: gaussian(J,5%*J) | J8: =VLOOKUP(_xlfn.XLOOKUP($A8,'MM configuration'!$D$2:$D$601,'MM configuration'!$C$2:$C$601),$S$24:$Y$38,2) -> 0.001673464 | K8: =VLOOKUP(_xlfn.XLOOKUP($A8,'MM configuration'!$D$2:$D$601,'MM configuration'!$C$2:$C$601),$S$24:$Y$38,3) -> 0.0015071289 | L8: =VLOOKUP(_xlfn.XLOOKUP($A8,'MM configuration'!$D$2:$D$601,'MM configuration'!$C$2:$C$601),$S$24:$Y$38,4) -> 0.0016374246 | M8: =VLOOKUP(_xlfn.XLOOKUP($A8,'MM configuration'!$D$2:$D$601,'MM configuration'!$C$2:$C$601),$S$24:$Y$38,5) -> 0.0015485679 | N8: =VLOOKUP(_xlfn.XLOOKUP($A8,'MM configuration'!$D$2:$D$601,'MM configuration'!$C$2:$C$601),$S$24:$Y$38,6) -> 0.0013017643 | O8: =VLOOKUP(_xlfn.XLOOKUP($A8,'MM configuration'!$D$2:$D$601,'MM configuration'!$C$2:$C$601),$S$24:$Y$38,7) -> 0.00080565957 | R8: 3 | S8: 24 | T8: 0.0584217 | U8: 0.0497536 | V8: 0.0549288 | W8: 0.0493485 | X8: 0.0299599 | Y8: 0.0073208
A9: 8 | B9: 0.0016374246 | D9: Variable 10% 0.25 keV | E9: gaussian(J,10%*J) | J9: =VLOOKUP(_xlfn.XLOOKUP($A9,'MM configuration'!$D$2:$D$601,'MM configuration'!$C$2:$C$601),$S$24:$Y$38,2) -> 0.001673464 | K9: =VLOOKUP(_xlfn.XLOOKUP($A9,'MM configuration'!$D$2:$D$601,'MM configuration'!$C$2:$C$601),$S$24:$Y$38,3) -> 0.0015071289 | L9: =VLOOKUP(_xlfn.XLOOKUP($A9,'MM configuration'!$D$2:$D$601,'MM configuration'!$C$2:$C$601),$S$24:$Y$38,4) -> 0.0016374246 | M9: =VLOOKUP(_xlfn.XLOOKUP($A9,'MM configuration'!$D$2:$D$601,'MM configuration'!$C$2:$C$601),$S$24:$Y$38,5) -> 0.0015485679 | N9: =VLOOKUP(_xlfn.XLOOKUP($A9,'MM configuration'!$D$2:$D$601,'MM configuration'!$C$2:$C$601),$S$24:$Y$38,6) -> 0.0013017643 | O9: =VLOOKUP(_xlfn.XLOOKUP($A9,'MM configuration'!$D$2:$D$601,'MM configuration'!$C$2:$C$601),$S$24:$Y$38,7) -> 0.00080565957 | R9: 4 | S9: 30 | T9: 0.0689765 | U9: 0.0570826 | V9: 0.0640197 | W9: 0.0554219 | X9: 0.0257771 | Y9: 0.0001266
A10: 9 | B10: 0.0021275755 | D10: Variable 20% 0.25 keV | E10: gaussian(J,20%*J) | J10: =VLOOKUP(_xlfn.XLOOKUP($A10,'MM configuration'!$D$2:$D$601,'MM configuration'!$C$2:$C$601),$S$24:$Y$38,2) -> 0.0021986033 | K10: =VLOOKUP(_xlfn.XLOOKUP($A10,'MM configuration'!$D$2:$D$601,'MM configuration'!$C$2:$C$601),$S$24:$Y$38,3) -> 0.0019273301 | L10: =VLOOKUP(_xlfn.XLOOKUP($A10,'MM configuration'!$D$2:$D$601,'MM configuration'!$C$2:$C$601),$S$24:$Y$38,4) -> 0.0021275755 | M10: =VLOOKUP(_xlfn.XLOOKUP($A10,'MM configuration'!$D$2:$D$601,'MM configuration'!$C$2:$C$601),$S$24:$Y$38,5) -> 0.0019603692 | N10: =VLOOKUP(_xlfn.XLOOKUP($A10,'MM configuration'!$D$2:$D$601,'MM configuration'!$C$2:$C$601),$S$24:$Y$38,6) -> 0.0012756676 | O10: =VLOOKUP(_xlfn.XLOOKUP($A10,'MM configuration'!$D$2:$D$601,'MM configuration'!$C$2:$C$601),$S$24:$Y$38,7) -> 0.00029932921 | R10: 5 | S10: 30 | T10: 0.0828713 | U10: 0.0668814 | V10: 0.075946 | W10: 0.0620219 | X10: 0.0180059 | Y10: 9.11e-05
A11: 10 | B11: 0.0021275755 | D11: Variable 5% 0.35 keV | E11: gaussian(K,5%*K) | J11: =VLOOKUP(_xlfn.XLOOKUP($A11,'MM configuration'!$D$2:$D$601,'MM configuration'!$C$2:$C$601),$S$24:$Y$38,2) -> 0.0021986033 | K11: =VLOOKUP(_xlfn.XLOOKUP($A11,'MM configuration'!$D$2:$D$601,'MM configuration'!$C$2:$C$601),$S$24:$Y$38,3) -> 0.0019273301 | L11: =VLOOKUP(_xlfn.XLOOKUP($A11,'MM configuration'!$D$2:$D$601,'MM configuration'!$C$2:$C$601),$S$24:$Y$38,4) -> 0.0021275755 | M11: =VLOOKUP(_xlfn.XLOOKUP($A11,'MM configuration'!$D$2:$D$601,'MM configuration'!$C$2:$C$601),$S$24:$Y$38,5) -> 0.0019603692 | N11: =VLOOKUP(_xlfn.XLOOKUP($A11,'MM configuration'!$D$2:$D$601,'MM configuration'!$C$2:$C$601),$S$24:$Y$38,6) -> 0.0012756676 | O11: =VLOOKUP(_xlfn.XLOOKUP($A11,'MM configuration'!$D$2:$D$601,'MM configuration'!$C$2:$C$601),$S$24:$Y$38,7) -> 0.00029932921 | R11: 6 | S11: 36 | T11: 0.0931819 | U11: 0.0731615 | V11: 0.0840759 | W11: 0.0648836 | X11: 0.0046315 | Y11: 3.58e-05
A12: 11 | B12: 0.0021275755 | D12: Variable 10% 0.35 keV | E12: gaussian(K,10%*K) | J12: =VLOOKUP(_xlfn.XLOOKUP($A12,'MM configuration'!$D$2:$D$601,'MM configuration'!$C$2:$C$601),$S$24:$Y$38,2) -> 0.0021986033 | K12: =VLOOKUP(_xlfn.XLOOKUP($A12,'MM configuration'!$D$2:$D$601,'MM configuration'!$C$2:$C$601),$S$24:$Y$38,3) -> 0.0019273301 | L12: =VLOOKUP(_xlfn.XLOOKUP($A12,'MM configuration'!$D$2:$D$601,'MM configuration'!$C$2:$C$601),$S$24:$Y$38,4) -> 0.0021275755 | M12: =VLOOKUP(_xlfn.XLOOKUP($A12,'MM configuration'!$D$2:$D$601,'MM configuration'!$C$2:$C$601),$S$24:$Y$38,5) -> 0.0019603692 | N12: =VLOOKUP(_xlfn.XLOOKUP($A12,'MM configuration'!$D$2:$D$601,'MM configuration'!$C$2:$C$601),$S$24:$Y$38,6) -> 0.0012756676 | O12: =VLOOKUP(_xlfn.XLOOKUP($A12,'MM configuration'!$D$2:$D$601,'MM configuration'!$C$2:$C$601),$S$24:$Y$38,7) -> 0.00029932921 | R12: 7 | S12: 42 | T12: 0.1035582 | U12: 0.0791522 | V12: 0.0921518 | W12: 0.0647503 | X12: 0.000222 | Y12: 3.2e-06
A13: 12 | B13: 0.0021275755 | D13: Variable 20% 0.35 keV | E13: gaussian(K,20%*K) | J13: =VLOOKUP(_xlfn.XLOOKUP($A13,'MM configuration'!$D$2:$D$601,'MM configuration'!$C$2:$C$601),$S$24:$Y$38,2) -> 0.0021986033 | K13: =VLOOKUP(_xlfn.XLOOKUP($A13,'MM configuration'!$D$2:$D$601,'MM configuration'!$C$2:$C$601),$S$24:$Y$38,3) -> 0.0019273301 | L13: =VLOOKUP(_xlfn.XLOOKUP($A13,'MM configuration'!$D$2:$D$601,'MM configuration'!$C$2:$C$601),$S$24:$Y$38,4) -> 0.0021275755 | M13: =VLOOKUP(_xlfn.XLOOKUP($A13,'MM configuration'!$D$2:$D$601,'MM configuration'!$C$2:$C$601),$S$24:$Y$38,5) -> 0.0019603692 | N13: =VLOOKUP(_xlfn.XLOOKUP($A13,'MM configuration'!$D$2:$D$601,'MM configuration'!$C$2:$C$601),$S$24:$Y$38,6) -> 0.0012756676 | O13: =VLOOKUP(_xlfn.XLOOKUP($A13,'MM configuration'!$D$2:$D$601,'MM configuration'!$C$2:$C$601),$S$24:$Y$38,7) -> 0.00029932921 | R13: 8 | S13: 42 | T13: 0.11637 | U13: 0.0866057 | V13: 0.1019048 | W13: 0.0622199 | X13: 7.61e-05 | Y13: 2e-06
A14: 13 | B14: 0.0019837571 | D14: Variable 5% 1 keV | E14: gaussian(L,5%*L) | J14: =VLOOKUP(_xlfn.XLOOKUP($A14,'MM configuration'!$D$2:$D$601,'MM configuration'!$C$2:$C$601),$S$24:$Y$38,2) -> 0.0020766525 | K14: =VLOOKUP(_xlfn.XLOOKUP($A14,'MM configuration'!$D$2:$D$601,'MM configuration'!$C$2:$C$601),$S$24:$Y$38,3) -> 0.0017689898 | L14: =VLOOKUP(_xlfn.XLOOKUP($A14,'MM configuration'!$D$2:$D$601,'MM configuration'!$C$2:$C$601),$S$24:$Y$38,4) -> 0.0019837571 | M14: =VLOOKUP(_xlfn.XLOOKUP($A14,'MM configuration'!$D$2:$D$601,'MM configuration'!$C$2:$C$601),$S$24:$Y$38,5) -> 0.001761308 | N14: =VLOOKUP(_xlfn.XLOOKUP($A14,'MM configuration'!$D$2:$D$601,'MM configuration'!$C$2:$C$601),$S$24:$Y$38,6) -> 0.00087805395 | O14: =VLOOKUP(_xlfn.XLOOKUP($A14,'MM configuration'!$D$2:$D$601,'MM configuration'!$C$2:$C$601),$S$24:$Y$38,7) -> 4.141086e-06 | R14: 9 | S14: 42 | T14: 0.1165133 | U14: 0.0936818 | V14: 0.1115269 | W14: 0.0559518 | X14: 0.0001508 | Y14: 5.5e-06
A15: 14 | B15: 0.0019837571 | D15: Variable 10% 1 keV | E15: gaussian(L,10%*L) | J15: =VLOOKUP(_xlfn.XLOOKUP($A15,'MM configuration'!$D$2:$D$601,'MM configuration'!$C$2:$C$601),$S$24:$Y$38,2) -> 0.0020766525 | K15: =VLOOKUP(_xlfn.XLOOKUP($A15,'MM configuration'!$D$2:$D$601,'MM configuration'!$C$2:$C$601),$S$24:$Y$38,3) -> 0.0017689898 | L15: =VLOOKUP(_xlfn.XLOOKUP($A15,'MM configuration'!$D$2:$D$601,'MM configuration'!$C$2:$C$601),$S$24:$Y$38,4) -> 0.0019837571 | M15: =VLOOKUP(_xlfn.XLOOKUP($A15,'MM configuration'!$D$2:$D$601,'MM configuration'!$C$2:$C$601),$S$24:$Y$38,5) -> 0.001761308 | N15: =VLOOKUP(_xlfn.XLOOKUP($A15,'MM configuration'!$D$2:$D$601,'MM configuration'!$C$2:$C$601),$S$24:$Y$38,6) -> 0.00087805395 | O15: =VLOOKUP(_xlfn.XLOOKUP($A15,'MM configuration'!$D$2:$D$601,'MM configuration'!$C$2:$C$601),$S$24:$Y$38,7) -> 4.141086e-06 | R15: 10 | S15: 48 | T15: 0.1389669 | U15: 0.0976777 | V15: 0.1175242 | W15: 0.0454628 | X15: 4.66e-05 | Y15: 8e-07
A16: 15 | B16: 0.0019837571 | D16: Variable 20% 1 keV | E16: gaussian(L,20%*L) | J16: =VLOOKUP(_xlfn.XLOOKUP($A16,'MM configuration'!$D$2:$D$601,'MM configuration'!$C$2:$C$601),$S$24:$Y$38,2) -> 0.0020766525 | K16: =VLOOKUP(_xlfn.XLOOKUP($A16,'MM configuration'!$D$2:$D$601,'MM configuration'!$C$2:$C$601),$S$24:$Y$38,3) -> 0.0017689898 | L16: =VLOOKUP(_xlfn.XLOOKUP($A16,'MM configuration'!$D$2:$D$601,'MM configuration'!$C$2:$C$601),$S$24:$Y$38,4) -> 0.0019837571 | M16: =VLOOKUP(_xlfn.XLOOKUP($A16,'MM configuration'!$D$2:$D$601,'MM configuration'!$C$2:$C$601),$S$24:$Y$38,5) -> 0.001761308 | N16: =VLOOKUP(_xlfn.XLOOKUP($A16,'MM configuration'!$D$2:$D$601,'MM configuration'!$C$2:$C$601),$S$24:$Y$38,6) -> 0.00087805395 | O16: =VLOOKUP(_xlfn.XLOOKUP($A16,'MM configuration'!$D$2:$D$601,'MM configuration'!$C$2:$C$601),$S$24:$Y$38,7) -> 4.141086e-06 | R16: 11 | S16: 48 | T16: 0.1515634 | U16: 0.1036544 | V16: 0.1256972 | W16: 0.0350108 | X16: 1.07e-05 | Y16: 1e-07
A17: 16 | B17: 0.0019837571 | D17: Variable 5% 2.5 keV | E17: gaussian(M,5%*M) | J17: =VLOOKUP(_xlfn.XLOOKUP($A17,'MM configuration'!$D$2:$D$601,'MM configuration'!$C$2:$C$601),$S$24:$Y$38,2) -> 0.0020766525 | K17: =VLOOKUP(_xlfn.XLOOKUP($A17,'MM configuration'!$D$2:$D$601,'MM configuration'!$C$2:$C$601),$S$24:$Y$38,3) -> 0.0017689898 | L17: =VLOOKUP(_xlfn.XLOOKUP($A17,'MM configuration'!$D$2:$D$601,'MM configuration'!$C$2:$C$601),$S$24:$Y$38,4) -> 0.0019837571 | M17: =VLOOKUP(_xlfn.XLOOKUP($A17,'MM configuration'!$D$2:$D$601,'MM configuration'!$C$2:$C$601),$S$24:$Y$38,5) -> 0.001761308 | N17: =VLOOKUP(_xlfn.XLOOKUP($A17,'MM configuration'!$D$2:$D$601,'MM configuration'!$C$2:$C$601),$S$24:$Y$38,6) -> 0.00087805395 | O17: =VLOOKUP(_xlfn.XLOOKUP($A17,'MM configuration'!$D$2:$D$601,'MM configuration'!$C$2:$C$601),$S$24:$Y$38,7) -> 4.141086e-06 | R17: 12 | S17: 48 | T17: 0.163788 | U17: 0.1089055 | V17: 0.1328818 | W17: 0.0250923 | X17: 8e-07 | Y17: 2e-07
... A20: 19 | B20: 0.0023533134 | D20: Variable 5% 7 keV | E20: gaussian(N,5%*N) | J20: =VLOOKUP(_xlfn.XLOOKUP($A20,'MM configuration'!$D$2:$D$601,'MM configuration'!$C$2:$C$601),$S$24:$Y$38,2) -> 0.0024949786 | K20: =VLOOKUP(_xlfn.XLOOKUP($A20,'MM configuration'!$D$2:$D$601,'MM configuration'!$C$2:$C$601),$S$24:$Y$38,3) -> 0.0020726546 | L20: =VLOOKUP(_xlfn.XLOOKUP($A20,'MM configuration'!$D$2:$D$601,'MM configuration'!$C$2:$C$601),$S$24:$Y$38,4) -> 0.0023533134 | M20: =VLOOKUP(_xlfn.XLOOKUP($A20,'MM configuration'!$D$2:$D$601,'MM configuration'!$C$2:$C$601),$S$24:$Y$38,5) -> 0.001971056 | N20: =VLOOKUP(_xlfn.XLOOKUP($A20,'MM configuration'!$D$2:$D$601,'MM configuration'!$C$2:$C$601),$S$24:$Y$38,6) -> 0.00061334097 | O20: =VLOOKUP(_xlfn.XLOOKUP($A20,'MM configuration'!$D$2:$D$601,'MM configuration'!$C$2:$C$601),$S$24:$Y$38,7) -> 2.979881e-06 | R20: 15 | S20: 54 | T20: 0.1959741 | U20: 0.1199263 | V20: 0.1473081 | W20: 0.0088317 | X20: 3.5e-06 | Y20: 0
A21: 20 | B21: 0.0023533134 | D21: Variable 10% 7 keV | E21: gaussian(N,10%*N) | J21: =VLOOKUP(_xlfn.XLOOKUP($A21,'MM configuration'!$D$2:$D$601,'MM configuration'!$C$2:$C$601),$S$24:$Y$38,2) -> 0.0024949786 | K21: =VLOOKUP(_xlfn.XLOOKUP($A21,'MM configuration'!$D$2:$D$601,'MM configuration'!$C$2:$C$601),$S$24:$Y$38,3) -> 0.0020726546 | L21: =VLOOKUP(_xlfn.XLOOKUP($A21,'MM configuration'!$D$2:$D$601,'MM configuration'!$C$2:$C$601),$S$24:$Y$38,4) -> 0.0023533134 | M21: =VLOOKUP(_xlfn.XLOOKUP($A21,'MM configuration'!$D$2:$D$601,'MM configuration'!$C$2:$C$601),$S$24:$Y$38,5) -> 0.001971056 | N21: =VLOOKUP(_xlfn.XLOOKUP($A21,'MM configuration'!$D$2:$D$601,'MM configuration'!$C$2:$C$601),$S$24:$Y$38,6) -> 0.00061334097 | O21: =VLOOKUP(_xlfn.XLOOKUP($A21,'MM configuration'!$D$2:$D$601,'MM configuration'!$C$2:$C$601),$S$24:$Y$38,7) -> 2.979881e-06
A22: 21 | B22: 0.0023533134 | D22: Variable 20% 7 keV | E22: gaussian(N,20%*N) | J22: =VLOOKUP(_xlfn.XLOOKUP($A22,'MM configuration'!$D$2:$D$601,'MM configuration'!$C$2:$C$601),$S$24:$Y$38,2) -> 0.0024949786 | K22: =VLOOKUP(_xlfn.XLOOKUP($A22,'MM configuration'!$D$2:$D$601,'MM configuration'!$C$2:$C$601),$S$24:$Y$38,3) -> 0.0020726546 | L22: =VLOOKUP(_xlfn.XLOOKUP($A22,'MM configuration'!$D$2:$D$601,'MM configuration'!$C$2:$C$601),$S$24:$Y$38,4) -> 0.0023533134 | M22: =VLOOKUP(_xlfn.XLOOKUP($A22,'MM configuration'!$D$2:$D$601,'MM configuration'!$C$2:$C$601),$S$24:$Y$38,5) -> 0.001971056 | N22: =VLOOKUP(_xlfn.XLOOKUP($A22,'MM configuration'!$D$2:$D$601,'MM configuration'!$C$2:$C$601),$S$24:$Y$38,6) -> 0.00061334097 | O22: =VLOOKUP(_xlfn.XLOOKUP($A22,'MM configuration'!$D$2:$D$601,'MM configuration'!$C$2:$C$601),$S$24:$Y$38,7) -> 2.979881e-06 | R22: Per MM type
A23: 22 | B23: 0.0023533134 | D23: Variable 5% 10 keV | E23: gaussian(O,5%*O) | J23: =VLOOKUP(_xlfn.XLOOKUP($A23,'MM configuration'!$D$2:$D$601,'MM configuration'!$C$2:$C$601),$S$24:$Y$38,2) -> 0.0024949786 | K23: =VLOOKUP(_xlfn.XLOOKUP($A23,'MM configuration'!$D$2:$D$601,'MM configuration'!$C$2:$C$601),$S$24:$Y$38,3) -> 0.0020726546 | L23: =VLOOKUP(_xlfn.XLOOKUP($A23,'MM configuration'!$D$2:$D$601,'MM configuration'!$C$2:$C$601),$S$24:$Y$38,4) -> 0.0023533134 | M23: =VLOOKUP(_xlfn.XLOOKUP($A23,'MM configuration'!$D$2:$D$601,'MM configuration'!$C$2:$C$601),$S$24:$Y$38,5) -> 0.001971056 | N23: =VLOOKUP(_xlfn.XLOOKUP($A23,'MM configuration'!$D$2:$D$601,'MM configuration'!$C$2:$C$601),$S$24:$Y$38,6) -> 0.00061334097 | O23: =VLOOKUP(_xlfn.XLOOKUP($A23,'MM configuration'!$D$2:$D$601,'MM configuration'!$C$2:$C$601),$S$24:$Y$38,7) -> 2.979881e-06 | S23: Row
A24: 23 | B24: 0.0021710266 | D24: Variable 10% 10 keV | E24: gaussian(O,10%*O) | J24: =VLOOKUP(_xlfn.XLOOKUP($A24,'MM configuration'!$D$2:$D$601,'MM configuration'!$C$2:$C$601),$S$24:$Y$38,2) -> 0.0023378303 | K24: =VLOOKUP(_xlfn.XLOOKUP($A24,'MM configuration'!$D$2:$D$601,'MM configuration'!$C$2:$C$601),$S$24:$Y$38,3) -> 0.0018893957 | L24: =VLOOKUP(_xlfn.XLOOKUP($A24,'MM configuration'!$D$2:$D$601,'MM configuration'!$C$2:$C$601),$S$24:$Y$38,4) -> 0.0021710266 | M24: =VLOOKUP(_xlfn.XLOOKUP($A24,'MM configuration'!$D$2:$D$601,'MM configuration'!$C$2:$C$601),$S$24:$Y$38,5) -> 0.001718334 | N24: =VLOOKUP(_xlfn.XLOOKUP($A24,'MM configuration'!$D$2:$D$601,'MM configuration'!$C$2:$C$601),$S$24:$Y$38,6) -> 0.00013147027 | O24: =VLOOKUP(_xlfn.XLOOKUP($A24,'MM configuration'!$D$2:$D$601,'MM configuration'!$C$2:$C$601),$S$24:$Y$38,7) -> 9.7584833e-07 | S24: 1 | T24: =T6*(100%-T$5)/$S6 -> 0.0011545041 | U24: =U6*(100%-U$5)/$S6 -> 0.00106802 | V24: =V6*(100%-V$5)/$S6 -> 0.0011432763 | W24: =W6*(100%-W$5)/$S6 -> 0.001098281 | X24: =X6*(100%-X$5)/$S6 -> 0.0010808679 | Y24: =Y6*(100%-Y$5)/$S6 -> 0.00082167111
A25: 24 | B25: 0.0021710266 | D25: Variable 20% 10 keV | E25: gaussian(O,20%*O) | J25: =VLOOKUP(_xlfn.XLOOKUP($A25,'MM configuration'!$D$2:$D$601,'MM configuration'!$C$2:$C$601),$S$24:$Y$38,2) -> 0.0023378303 | K25: =VLOOKUP(_xlfn.XLOOKUP($A25,'MM configuration'!$D$2:$D$601,'MM configuration'!$C$2:$C$601),$S$24:$Y$38,3) -> 0.0018893957 | L25: =VLOOKUP(_xlfn.XLOOKUP($A25,'MM configuration'!$D$2:$D$601,'MM configuration'!$C$2:$C$601),$S$24:$Y$38,4) -> 0.0021710266 | M25: =VLOOKUP(_xlfn.XLOOKUP($A25,'MM configuration'!$D$2:$D$601,'MM configuration'!$C$2:$C$601),$S$24:$Y$38,5) -> 0.001718334 | N25: =VLOOKUP(_xlfn.XLOOKUP($A25,'MM configuration'!$D$2:$D$601,'MM configuration'!$C$2:$C$601),$S$24:$Y$38,6) -> 0.00013147027 | O25: =VLOOKUP(_xlfn.XLOOKUP($A25,'MM configuration'!$D$2:$D$601,'MM configuration'!$C$2:$C$601),$S$24:$Y$38,7) -> 9.7584833e-07 | S25: 2 | T25: =T7*(100%-T$5)/$S7 -> 0.001673464 | U25: =U7*(100%-U$5)/$S7 -> 0.0015071289 | V25: =V7*(100%-V$5)/$S7 -> 0.0016374246 | W25: =W7*(100%-W$5)/$S7 -> 0.0015485679 | X25: =X7*(100%-X$5)/$S7 -> 0.0013017643 | Y25: =Y7*(100%-Y$5)/$S7 -> 0.00080565957
A26: 25 | B26: 0.0021710266 | J26: =VLOOKUP(_xlfn.XLOOKUP($A26,'MM configuration'!$D$2:$D$601,'MM configuration'!$C$2:$C$601),$S$24:$Y$38,2) -> 0.0023378303 | K26: =VLOOKUP(_xlfn.XLOOKUP($A26,'MM configuration'!$D$2:$D$601,'MM configuration'!$C$2:$C$601),$S$24:$Y$38,3) -> 0.0018893957 | L26: =VLOOKUP(_xlfn.XLOOKUP($A26,'MM configuration'!$D$2:$D$601,'MM configuration'!$C$2:$C$601),$S$24:$Y$38,4) -> 0.0021710266 | M26: =VLOOKUP(_xlfn.XLOOKUP($A26,'MM configuration'!$D$2:$D$601,'MM configuration'!$C$2:$C$601),$S$24:$Y$38,5) -> 0.001718334 | N26: =VLOOKUP(_xlfn.XLOOKUP($A26,'MM configuration'!$D$2:$D$601,'MM configuration'!$C$2:$C$601),$S$24:$Y$38,6) -> 0.00013147027 | O26: =VLOOKUP(_xlfn.XLOOKUP($A26,'MM configuration'!$D$2:$D$601,'MM configuration'!$C$2:$C$601),$S$24:$Y$38,7) -> 9.7584833e-07 | S26: 3 | T26: =T8*(100%-T$5)/$S8 -> 0.0021986033 | U26: =U8*(100%-U$5)/$S8 -> 0.0019273301 | V26: =V8*(100%-V$5)/$S8 -> 0.0021275755 | W26: =W8*(100%-W$5)/$S8 -> 0.0019603692 | X26: =X8*(100%-X$5)/$S8 -> 0.0012756676 | Y26: =Y8*(100%-Y$5)/$S8 -> 0.00029932921
A27: 26 | B27: 0.0021710266 | J27: =VLOOKUP(_xlfn.XLOOKUP($A27,'MM configuration'!$D$2:$D$601,'MM configuration'!$C$2:$C$601),$S$24:$Y$38,2) -> 0.0023378303 | K27: =VLOOKUP(_xlfn.XLOOKUP($A27,'MM configuration'!$D$2:$D$601,'MM configuration'!$C$2:$C$601),$S$24:$Y$38,3) -> 0.0018893957 | L27: =VLOOKUP(_xlfn.XLOOKUP($A27,'MM configuration'!$D$2:$D$601,'MM configuration'!$C$2:$C$601),$S$24:$Y$38,4) -> 0.0021710266 | M27: =VLOOKUP(_xlfn.XLOOKUP($A27,'MM configuration'!$D$2:$D$601,'MM configuration'!$C$2:$C$601),$S$24:$Y$38,5) -> 0.001718334 | N27: =VLOOKUP(_xlfn.XLOOKUP($A27,'MM configuration'!$D$2:$D$601,'MM configuration'!$C$2:$C$601),$S$24:$Y$38,6) -> 0.00013147027 | O27: =VLOOKUP(_xlfn.XLOOKUP($A27,'MM configuration'!$D$2:$D$601,'MM configuration'!$C$2:$C$601),$S$24:$Y$38,7) -> 9.7584833e-07 | S27: 4 | T27: =T9*(100%-T$5)/$S9 -> 0.0020766525 | U27: =U9*(100%-U$5)/$S9 -> 0.0017689898 | V27: =V9*(100%-V$5)/$S9 -> 0.0019837571 | W27: =W9*(100%-W$5)/$S9 -> 0.001761308 | X27: =X9*(100%-X$5)/$S9 -> 0.00087805395 | Y27: =Y9*(100%-Y$5)/$S9 -> 4.141086e-06
A28: 27 | B28: 0.0021710266 | J28: =VLOOKUP(_xlfn.XLOOKUP($A28,'MM configuration'!$D$2:$D$601,'MM configuration'!$C$2:$C$601),$S$24:$Y$38,2) -> 0.0023378303 | K28: =VLOOKUP(_xlfn.XLOOKUP($A28,'MM configuration'!$D$2:$D$601,'MM configuration'!$C$2:$C$601),$S$24:$Y$38,3) -> 0.0018893957 | L28: =VLOOKUP(_xlfn.XLOOKUP($A28,'MM configuration'!$D$2:$D$601,'MM configuration'!$C$2:$C$601),$S$24:$Y$38,4) -> 0.0021710266 | M28: =VLOOKUP(_xlfn.XLOOKUP($A28,'MM configuration'!$D$2:$D$601,'MM configuration'!$C$2:$C$601),$S$24:$Y$38,5) -> 0.001718334 | N28: =VLOOKUP(_xlfn.XLOOKUP($A28,'MM configuration'!$D$2:$D$601,'MM configuration'!$C$2:$C$601),$S$24:$Y$38,6) -> 0.00013147027 | O28: =VLOOKUP(_xlfn.XLOOKUP($A28,'MM configuration'!$D$2:$D$601,'MM configuration'!$C$2:$C$601),$S$24:$Y$38,7) -> 9.7584833e-07 | S28: 5 | T28: =T10*(100%-T$5)/$S10 -> 0.0024949786 | U28: =U10*(100%-U$5)/$S10 -> 0.0020726546 | V28: =V10*(100%-V$5)/$S10 -> 0.0023533134 | W28: =W10*(100%-W$5)/$S10 -> 0.001971056 | X28: =X10*(100%-X$5)/$S10 -> 0.00061334097 | Y28: =Y10*(100%-Y$5)/$S10 -> 2.979881e-06
A29: 28 | B29: 0.0021710266 | J29: =VLOOKUP(_xlfn.XLOOKUP($A29,'MM configuration'!$D$2:$D$601,'MM configuration'!$C$2:$C$601),$S$24:$Y$38,2) -> 0.0023378303 | K29: =VLOOKUP(_xlfn.XLOOKUP($A29,'MM configuration'!$D$2:$D$601,'MM configuration'!$C$2:$C$601),$S$24:$Y$38,3) -> 0.0018893957 | L29: =VLOOKUP(_xlfn.XLOOKUP($A29,'MM configuration'!$D$2:$D$601,'MM configuration'!$C$2:$C$601),$S$24:$Y$38,4) -> 0.0021710266 | M29: =VLOOKUP(_xlfn.XLOOKUP($A29,'MM configuration'!$D$2:$D$601,'MM configuration'!$C$2:$C$601),$S$24:$Y$38,5) -> 0.001718334 | N29: =VLOOKUP(_xlfn.XLOOKUP($A29,'MM configuration'!$D$2:$D$601,'MM configuration'!$C$2:$C$601),$S$24:$Y$38,6) -> 0.00013147027 | O29: =VLOOKUP(_xlfn.XLOOKUP($A29,'MM configuration'!$D$2:$D$601,'MM configuration'!$C$2:$C$601),$S$24:$Y$38,7) -> 9.7584833e-07 | S29: 6 | T29: =T11*(100%-T$5)/$S11 -> 0.0023378303 | U29: =U11*(100%-U$5)/$S11 -> 0.0018893957 | V29: =V11*(100%-V$5)/$S11 -> 0.0021710266 | W29: =W11*(100%-W$5)/$S11 -> 0.001718334 | X29: =X11*(100%-X$5)/$S11 -> 0.00013147027 | Y29: =Y11*(100%-Y$5)/$S11 -> 9.7584833e-07
A30: 29 | B30: 0.0020396265 | J30: =VLOOKUP(_xlfn.XLOOKUP($A30,'MM configuration'!$D$2:$D$601,'MM configuration'!$C$2:$C$601),$S$24:$Y$38,2) -> 0.0022269944 | K30: =VLOOKUP(_xlfn.XLOOKUP($A30,'MM configuration'!$D$2:$D$601,'MM configuration'!$C$2:$C$601),$S$24:$Y$38,3) -> 0.0017520905 | L30: =VLOOKUP(_xlfn.XLOOKUP($A30,'MM configuration'!$D$2:$D$601,'MM configuration'!$C$2:$C$601),$S$24:$Y$38,4) -> 0.0020396265 | M30: =VLOOKUP(_xlfn.XLOOKUP($A30,'MM configuration'!$D$2:$D$601,'MM configuration'!$C$2:$C$601),$S$24:$Y$38,5) -> 0.0014698318 | N30: =VLOOKUP(_xlfn.XLOOKUP($A30,'MM configuration'!$D$2:$D$601,'MM configuration'!$C$2:$C$601),$S$24:$Y$38,6) -> 5.4014714e-06 | O30: =VLOOKUP(_xlfn.XLOOKUP($A30,'MM configuration'!$D$2:$D$601,'MM configuration'!$C$2:$C$601),$S$24:$Y$38,7) -> 7.4765714e-08 | S30: 7 | T30: =T12*(100%-T$5)/$S12 -> 0.0022269944 | U30: =U12*(100%-U$5)/$S12 -> 0.0017520905 | V30: =V12*(100%-V$5)/$S12 -> 0.0020396265 | W30: =W12*(100%-W$5)/$S12 -> 0.0014698318 | X30: =X12*(100%-X$5)/$S12 -> 5.4014714e-06 | Y30: =Y12*(100%-Y$5)/$S12 -> 7.4765714e-08
A31: 30 | B31: 0.0020396265 | J31: =VLOOKUP(_xlfn.XLOOKUP($A31,'MM configuration'!$D$2:$D$601,'MM configuration'!$C$2:$C$601),$S$24:$Y$38,2) -> 0.0022269944 | K31: =VLOOKUP(_xlfn.XLOOKUP($A31,'MM configuration'!$D$2:$D$601,'MM configuration'!$C$2:$C$601),$S$24:$Y$38,3) -> 0.0017520905 | L31: =VLOOKUP(_xlfn.XLOOKUP($A31,'MM configuration'!$D$2:$D$601,'MM configuration'!$C$2:$C$601),$S$24:$Y$38,4) -> 0.0020396265 | M31: =VLOOKUP(_xlfn.XLOOKUP($A31,'MM configuration'!$D$2:$D$601,'MM configuration'!$C$2:$C$601),$S$24:$Y$38,5) -> 0.0014698318 | N31: =VLOOKUP(_xlfn.XLOOKUP($A31,'MM configuration'!$D$2:$D$601,'MM configuration'!$C$2:$C$601),$S$24:$Y$38,6) -> 5.4014714e-06 | O31: =VLOOKUP(_xlfn.XLOOKUP($A31,'MM configuration'!$D$2:$D$601,'MM configuration'!$C$2:$C$601),$S$24:$Y$38,7) -> 7.4765714e-08 | S31: 8 | T31: =T13*(100%-T$5)/$S13 -> 0.0025025091 | U31: =U13*(100%-U$5)/$S13 -> 0.001917079 | V31: =V13*(100%-V$5)/$S13 -> 0.0022554929 | W31: =W13*(100%-W$5)/$S13 -> 0.0014123917 | X31: =X13*(100%-X$5)/$S13 -> 1.8515855e-06 | Y31: =Y13*(100%-Y$5)/$S13 -> 4.6728571e-08
A32: 31 | B32: 0.0020396265 | J32: =VLOOKUP(_xlfn.XLOOKUP($A32,'MM configuration'!$D$2:$D$601,'MM configuration'!$C$2:$C$601),$S$24:$Y$38,2) -> 0.0022269944 | K32: =VLOOKUP(_xlfn.XLOOKUP($A32,'MM configuration'!$D$2:$D$601,'MM configuration'!$C$2:$C$601),$S$24:$Y$38,3) -> 0.0017520905 | L32: =VLOOKUP(_xlfn.XLOOKUP($A32,'MM configuration'!$D$2:$D$601,'MM configuration'!$C$2:$C$601),$S$24:$Y$38,4) -> 0.0020396265 | M32: =VLOOKUP(_xlfn.XLOOKUP($A32,'MM configuration'!$D$2:$D$601,'MM configuration'!$C$2:$C$601),$S$24:$Y$38,5) -> 0.0014698318 | N32: =VLOOKUP(_xlfn.XLOOKUP($A32,'MM configuration'!$D$2:$D$601,'MM configuration'!$C$2:$C$601),$S$24:$Y$38,6) -> 5.4014714e-06 | O32: =VLOOKUP(_xlfn.XLOOKUP($A32,'MM configuration'!$D$2:$D$601,'MM configuration'!$C$2:$C$601),$S$24:$Y$38,7) -> 7.4765714e-08 | S32: 9 | T32: =T14*(100%-T$5)/$S14 -> 0.0025055908 | U32: =U14*(100%-U$5)/$S14 -> 0.0020737136 | V32: =V14*(100%-V$5)/$S14 -> 0.0024684621 | W32: =W14*(100%-W$5)/$S14 -> 0.0012701059 | X32: =X14*(100%-X$5)/$S14 -> 3.6691076e-06 | Y32: =Y14*(100%-Y$5)/$S14 -> 1.2850357e-07
A33: 32 | B33: 0.0020396265 | J33: =VLOOKUP(_xlfn.XLOOKUP($A33,'MM configuration'!$D$2:$D$601,'MM configuration'!$C$2:$C$601),$S$24:$Y$38,2) -> 0.0022269944 | K33: =VLOOKUP(_xlfn.XLOOKUP($A33,'MM configuration'!$D$2:$D$601,'MM configuration'!$C$2:$C$601),$S$24:$Y$38,3) -> 0.0017520905 | L33: =VLOOKUP(_xlfn.XLOOKUP($A33,'MM configuration'!$D$2:$D$601,'MM configuration'!$C$2:$C$601),$S$24:$Y$38,4) -> 0.0020396265 | M33: =VLOOKUP(_xlfn.XLOOKUP($A33,'MM configuration'!$D$2:$D$601,'MM configuration'!$C$2:$C$601),$S$24:$Y$38,5) -> 0.0014698318 | N33: =VLOOKUP(_xlfn.XLOOKUP($A33,'MM configuration'!$D$2:$D$601,'MM configuration'!$C$2:$C$601),$S$24:$Y$38,6) -> 5.4014714e-06 | O33: =VLOOKUP(_xlfn.XLOOKUP($A33,'MM configuration'!$D$2:$D$601,'MM configuration'!$C$2:$C$601),$S$24:$Y$38,7) -> 7.4765714e-08 | S33: 10 | T33: =T15*(100%-T$5)/$S15 -> 0.0026148938 | U33: =U15*(100%-U$5)/$S15 -> 0.001891895 | V33: =V15*(100%-V$5)/$S15 -> 0.002276052 | W33: =W15*(100%-W$5)/$S15 -> 0.00090300486 | X33: =X15*(100%-X$5)/$S15 -> 9.9209458e-07 | Y33: =Y15*(100%-Y$5)/$S15 -> 1.6355e-08
A34: 33 | B34: 0.0020396265 | J34: =VLOOKUP(_xlfn.XLOOKUP($A34,'MM configuration'!$D$2:$D$601,'MM configuration'!$C$2:$C$601),$S$24:$Y$38,2) -> 0.0022269944 | K34: =VLOOKUP(_xlfn.XLOOKUP($A34,'MM configuration'!$D$2:$D$601,'MM configuration'!$C$2:$C$601),$S$24:$Y$38,3) -> 0.0017520905 | L34: =VLOOKUP(_xlfn.XLOOKUP($A34,'MM configuration'!$D$2:$D$601,'MM configuration'!$C$2:$C$601),$S$24:$Y$38,4) -> 0.0020396265 | M34: =VLOOKUP(_xlfn.XLOOKUP($A34,'MM configuration'!$D$2:$D$601,'MM configuration'!$C$2:$C$601),$S$24:$Y$38,5) -> 0.0014698318 | N34: =VLOOKUP(_xlfn.XLOOKUP($A34,'MM configuration'!$D$2:$D$601,'MM configuration'!$C$2:$C$601),$S$24:$Y$38,6) -> 5.4014714e-06 | O34: =VLOOKUP(_xlfn.XLOOKUP($A34,'MM configuration'!$D$2:$D$601,'MM configuration'!$C$2:$C$601),$S$24:$Y$38,7) -> 7.4765714e-08 | S34: 11 | T34: =T16*(100%-T$5)/$S16 -> 0.002851918 | U34: =U16*(100%-U$5)/$S16 -> 0.0020076562 | V34: =V16*(100%-V$5)/$S16 -> 0.0024343358 | W34: =W16*(100%-W$5)/$S16 -> 0.00069540201 | X34: =X16*(100%-X$5)/$S16 -> 2.2779854e-07 | Y34: =Y16*(100%-Y$5)/$S16 -> 2.044375e-09
A35: 34 | B35: 0.0020396265 | J35: =VLOOKUP(_xlfn.XLOOKUP($A35,'MM configuration'!$D$2:$D$601,'MM configuration'!$C$2:$C$601),$S$24:$Y$38,2) -> 0.0022269944 | K35: =VLOOKUP(_xlfn.XLOOKUP($A35,'MM configuration'!$D$2:$D$601,'MM configuration'!$C$2:$C$601),$S$24:$Y$38,3) -> 0.0017520905 | L35: =VLOOKUP(_xlfn.XLOOKUP($A35,'MM configuration'!$D$2:$D$601,'MM configuration'!$C$2:$C$601),$S$24:$Y$38,4) -> 0.0020396265 | M35: =VLOOKUP(_xlfn.XLOOKUP($A35,'MM configuration'!$D$2:$D$601,'MM configuration'!$C$2:$C$601),$S$24:$Y$38,5) -> 0.0014698318 | N35: =VLOOKUP(_xlfn.XLOOKUP($A35,'MM configuration'!$D$2:$D$601,'MM configuration'!$C$2:$C$601),$S$24:$Y$38,6) -> 5.4014714e-06 | O35: =VLOOKUP(_xlfn.XLOOKUP($A35,'MM configuration'!$D$2:$D$601,'MM configuration'!$C$2:$C$601),$S$24:$Y$38,7) -> 7.4765714e-08 | S35: 12 | T35: =T17*(100%-T$5)/$S17 -> 0.0030819442 | U35: =U17*(100%-U$5)/$S17 -> 0.0021093634 | V35: =V17*(100%-V$5)/$S17 -> 0.0025734775 | W35: =W17*(100%-W$5)/$S17 -> 0.00049839581 | X35: =X17*(100%-X$5)/$S17 -> 1.7031667e-08 | Y35: =Y17*(100%-Y$5)/$S17 -> 4.08875e-09
A36: 35 | B36: 0.0020396265 | J36: =VLOOKUP(_xlfn.XLOOKUP($A36,'MM configuration'!$D$2:$D$601,'MM configuration'!$C$2:$C$601),$S$24:$Y$38,2) -> 0.0022269944 | K36: =VLOOKUP(_xlfn.XLOOKUP($A36,'MM configuration'!$D$2:$D$601,'MM configuration'!$C$2:$C$601),$S$24:$Y$38,3) -> 0.0017520905 | L36: =VLOOKUP(_xlfn.XLOOKUP($A36,'MM configuration'!$D$2:$D$601,'MM configuration'!$C$2:$C$601),$S$24:$Y$38,4) -> 0.0020396265 | M36: =VLOOKUP(_xlfn.XLOOKUP($A36,'MM configuration'!$D$2:$D$601,'MM configuration'!$C$2:$C$601),$S$24:$Y$38,5) -> 0.0014698318 | N36: =VLOOKUP(_xlfn.XLOOKUP($A36,'MM configuration'!$D$2:$D$601,'MM configuration'!$C$2:$C$601),$S$24:$Y$38,6) -> 5.4014714e-06 | O36: =VLOOKUP(_xlfn.XLOOKUP($A36,'MM configuration'!$D$2:$D$601,'MM configuration'!$C$2:$C$601),$S$24:$Y$38,7) -> 7.4765714e-08 | S36: 13 | T36: =T18*(100%-T$5)/$S18 -> 0.0028975509 | U36: =U18*(100%-U$5)/$S18 -> 0.001928933 | V36: =V18*(100%-V$5)/$S18 -> 0.0023623684 | W36: =W18*(100%-W$5)/$S18 -> 0.00030228783 | X36: =X18*(100%-X$5)/$S18 -> 9.0835556e-08 | Y36: =Y18*(100%-Y$5)/$S18 -> 5.4516667e-09
A37: 36 | B37: 0.0022554929 | J37: =VLOOKUP(_xlfn.XLOOKUP($A37,'MM configuration'!$D$2:$D$601,'MM configuration'!$C$2:$C$601),$S$24:$Y$38,2) -> 0.0025025091 | K37: =VLOOKUP(_xlfn.XLOOKUP($A37,'MM configuration'!$D$2:$D$601,'MM configuration'!$C$2:$C$601),$S$24:$Y$38,3) -> 0.001917079 | L37: =VLOOKUP(_xlfn.XLOOKUP($A37,'MM configuration'!$D$2:$D$601,'MM configuration'!$C$2:$C$601),$S$24:$Y$38,4) -> 0.0022554929 | M37: =VLOOKUP(_xlfn.XLOOKUP($A37,'MM configuration'!$D$2:$D$601,'MM configuration'!$C$2:$C$601),$S$24:$Y$38,5) -> 0.0014123917 | N37: =VLOOKUP(_xlfn.XLOOKUP($A37,'MM configuration'!$D$2:$D$601,'MM configuration'!$C$2:$C$601),$S$24:$Y$38,6) -> 1.8515855e-06 | O37: =VLOOKUP(_xlfn.XLOOKUP($A37,'MM configuration'!$D$2:$D$601,'MM configuration'!$C$2:$C$601),$S$24:$Y$38,7) -> 4.6728571e-08 | S37: 14 | T37: =T19*(100%-T$5)/$S19 -> 0.0030858029 | U37: =U19*(100%-U$5)/$S19 -> 0.002000179 | V37: =V19*(100%-V$5)/$S19 -> 0.002454342 | W37: =W19*(100%-W$5)/$S19 -> 0.00021177486 | X37: =X19*(100%-X$5)/$S19 -> 2.0438e-07 | Y37: =Y19*(100%-Y$5)/$S19 -> 3.6344444e-09
A38: 37 | B38: 0.0022554929 | J38: =VLOOKUP(_xlfn.XLOOKUP($A38,'MM configuration'!$D$2:$D$601,'MM configuration'!$C$2:$C$601),$S$24:$Y$38,2) -> 0.0025025091 | K38: =VLOOKUP(_xlfn.XLOOKUP($A38,'MM configuration'!$D$2:$D$601,'MM configuration'!$C$2:$C$601),$S$24:$Y$38,3) -> 0.001917079 | L38: =VLOOKUP(_xlfn.XLOOKUP($A38,'MM configuration'!$D$2:$D$601,'MM configuration'!$C$2:$C$601),$S$24:$Y$38,4) -> 0.0022554929 | M38: =VLOOKUP(_xlfn.XLOOKUP($A38,'MM configuration'!$D$2:$D$601,'MM configuration'!$C$2:$C$601),$S$24:$Y$38,5) -> 0.0014123917 | N38: =VLOOKUP(_xlfn.XLOOKUP($A38,'MM configuration'!$D$2:$D$601,'MM configuration'!$C$2:$C$601),$S$24:$Y$38,6) -> 1.8515855e-06 | O38: =VLOOKUP(_xlfn.XLOOKUP($A38,'MM configuration'!$D$2:$D$601,'MM configuration'!$C$2:$C$601),$S$24:$Y$38,7) -> 4.6728571e-08 | S38: 15 | T38: =T20*(100%-T$5)/$S20 -> 0.0032778483 | U38: =U20*(100%-U$5)/$S20 -> 0.0020647311 | V38: =V20*(100%-V$5)/$S20 -> 0.0025358817 | W38: =W20*(100%-W$5)/$S20 -> 0.00015592857 | X38: =X20*(100%-X$5)/$S20 -> 6.6234259e-08 | Y38: =Y20*(100%-Y$5)/$S20 -> 0
A39: 38 | B39: 0.0022554929 | J39: =VLOOKUP(_xlfn.XLOOKUP($A39,'MM configuration'!$D$2:$D$601,'MM configuration'!$C$2:$C$601),$S$24:$Y$38,2) -> 0.0025025091 | K39: =VLOOKUP(_xlfn.XLOOKUP($A39,'MM configuration'!$D$2:$D$601,'MM configuration'!$C$2:$C$601),$S$24:$Y$38,3) -> 0.001917079 | L39: =VLOOKUP(_xlfn.XLOOKUP($A39,'MM configuration'!$D$2:$D$601,'MM configuration'!$C$2:$C$601),$S$24:$Y$38,4) -> 0.0022554929 | M39: =VLOOKUP(_xlfn.XLOOKUP($A39,'MM configuration'!$D$2:$D$601,'MM configuration'!$C$2:$C$601),$S$24:$Y$38,5) -> 0.0014123917 | N39: =VLOOKUP(_xlfn.XLOOKUP($A39,'MM configuration'!$D$2:$D$601,'MM configuration'!$C$2:$C$601),$S$24:$Y$38,6) -> 1.8515855e-06 | O39: =VLOOKUP(_xlfn.XLOOKUP($A39,'MM configuration'!$D$2:$D$601,'MM configuration'!$C$2:$C$601),$S$24:$Y$38,7) -> 4.6728571e-08
A40: 39 | B40: 0.0022554929 | J40: =VLOOKUP(_xlfn.XLOOKUP($A40,'MM configuration'!$D$2:$D$601,'MM configuration'!$C$2:$C$601),$S$24:$Y$38,2) -> 0.0025025091 | K40: =VLOOKUP(_xlfn.XLOOKUP($A40,'MM configuration'!$D$2:$D$601,'MM configuration'!$C$2:$C$601),$S$24:$Y$38,3) -> 0.001917079 | L40: =VLOOKUP(_xlfn.XLOOKUP($A40,'MM configuration'!$D$2:$D$601,'MM configuration'!$C$2:$C$601),$S$24:$Y$38,4) -> 0.0022554929 | M40: =VLOOKUP(_xlfn.XLOOKUP($A40,'MM configuration'!$D$2:$D$601,'MM configuration'!$C$2:$C$601),$S$24:$Y$38,5) -> 0.0014123917 | N40: =VLOOKUP(_xlfn.XLOOKUP($A40,'MM configuration'!$D$2:$D$601,'MM configuration'!$C$2:$C$601),$S$24:$Y$38,6) -> 1.8515855e-06 | O40: =VLOOKUP(_xlfn.XLOOKUP($A40,'MM configuration'!$D$2:$D$601,'MM configuration'!$C$2:$C$601),$S$24:$Y$38,7) -> 4.6728571e-08
A41: 40 | B41: 0.0022554929 | J41: =VLOOKUP(_xlfn.XLOOKUP($A41,'MM configuration'!$D$2:$D$601,'MM configuration'!$C$2:$C$601),$S$24:$Y$38,2) -> 0.0025025091 | K41: =VLOOKUP(_xlfn.XLOOKUP($A41,'MM configuration'!$D$2:$D$601,'MM configuration'!$C$2:$C$601),$S$24:$Y$38,3) -> 0.001917079 | L41: =VLOOKUP(_xlfn.XLOOKUP($A41,'MM configuration'!$D$2:$D$601,'MM configuration'!$C$2:$C$601),$S$24:$Y$38,4) -> 0.0022554929 | M41: =VLOOKUP(_xlfn.XLOOKUP($A41,'MM configuration'!$D$2:$D$601,'MM configuration'!$C$2:$C$601),$S$24:$Y$38,5) -> 0.0014123917 | N41: =VLOOKUP(_xlfn.XLOOKUP($A41,'MM configuration'!$D$2:$D$601,'MM configuration'!$C$2:$C$601),$S$24:$Y$38,6) -> 1.8515855e-06 | O41: =VLOOKUP(_xlfn.XLOOKUP($A41,'MM configuration'!$D$2:$D$601,'MM configuration'!$C$2:$C$601),$S$24:$Y$38,7) -> 4.6728571e-08
A42: 41 | B42: 0.0022554929 | J42: =VLOOKUP(_xlfn.XLOOKUP($A42,'MM configuration'!$D$2:$D$601,'MM configuration'!$C$2:$C$601),$S$24:$Y$38,2) -> 0.0025025091 | K42: =VLOOKUP(_xlfn.XLOOKUP($A42,'MM configuration'!$D$2:$D$601,'MM configuration'!$C$2:$C$601),$S$24:$Y$38,3) -> 0.001917079 | L42: =VLOOKUP(_xlfn.XLOOKUP($A42,'MM configuration'!$D$2:$D$601,'MM configuration'!$C$2:$C$601),$S$24:$Y$38,4) -> 0.0022554929 | M42: =VLOOKUP(_xlfn.XLOOKUP($A42,'MM configuration'!$D$2:$D$601,'MM configuration'!$C$2:$C$601),$S$24:$Y$38,5) -> 0.0014123917 | N42: =VLOOKUP(_xlfn.XLOOKUP($A42,'MM configuration'!$D$2:$D$601,'MM configuration'!$C$2:$C$601),$S$24:$Y$38,6) -> 1.8515855e-06 | O42: =VLOOKUP(_xlfn.XLOOKUP($A42,'MM configuration'!$D$2:$D$601,'MM configuration'!$C$2:$C$601),$S$24:$Y$38,7) -> 4.6728571e-08
...

Sheet MM_PSF
A1: MM # | B1: m_rad [arcsec] | C1: m_azi [arcsec] | D1: sigma_rad [arcsec] | E1: sigma_azi [arcsec] | F1: distribution | G1: alpha_rad | H1: alpha_azi | K1: Standard MM_PSF distributions | L1: sigma_rad_ | M1: sigma_azi_ | N1: alpha_rad_ | O1: alpha_azi_
A2: 1 | B2: 0 | C2: 0 | D2: 0.01 | E2: 0.01 | F2: gaussian | G2: - | H2: - | K2: Fixed Sym Gaussian 0.01" | L2: 0.01 | M2: 0.01 | N2: - | O2: -
A3: 2 | B3: 0 | C3: 0 | D3: 0.01 | E3: 0.01 | F3: gaussian | G3: - | H3: - | K3: Fixed Sym Gaussian 4.3" | L3: 1.82635 | M3: 1.82635 | N3: - | O3: - | Q3: From NewAthena Reference telescope design
A4: 3 | B4: 0 | C4: 0 | D4: 0.01 | E4: 0.01 | F4: gaussian | G4: - | H4: - | K4: Fixed Sym Gaussian 8" | L4: 3.39833 | M4: 3.39833 | N4: - | O4: -
A5: 4 | B5: 0 | C5: 0 | D5: 0.01 | E5: 0.01 | F5: gaussian | G5: - | H5: - | K5: Fixed Asym Gaussian 4.3" (ratio 4:1) | L5: 2.9637409 | M5: 0.74093523 | N5: - | O5: -
A6: 5 | B6: 0 | C6: 0 | D6: 0.01 | E6: 0.01 | F6: gaussian | G6: - | H6: - | K6: Fixed Asym Gaussian 8" (ratio 7:1) | L6: 5.7972051 | M6: 0.82817216 | N6: - | O6: -
A7: 6 | B7: 0 | C7: 0 | D7: 0.01 | E7: 0.01 | F7: gaussian | G7: - | H7: - | K7: Fixed Pseudo-Voigt 4.3" | L7: 2.22057 | M7: 0.679177 | N7: 0.77 | O7: 0.29
A8: 7 | B8: 0 | C8: 0 | D8: 0.01 | E8: 0.01 | F8: gaussian | G8: - | H8: - | K8: Fixed Pseudo-Voigt 8" | L8: 4.1303 | M8: 1.2633 | N8: 0.77 | O8: 0.29
A9: 8 | B9: 0 | C9: 0 | D9: 0.01 | E9: 0.01 | F9: gaussian | G9: - | H9: - | K9: 10% Variable Sym Gaussian 4.3" | L9: gamma (1.82635,10%*1.82635) | M9: gamma (1.82635,10%*1.82635) | N9: - | O9: -
A10: 9 | B10: 0 | C10: 0 | D10: 0.01 | E10: 0.01 | F10: gaussian | G10: - | H10: - | K10: 30% Variable Sym Gaussian 4.3" | L10: gamma (1.82635,30%*1.82635) | M10: gamma (1.82635,30%*1.82635) | N10: - | O10: -
A11: 10 | B11: 0 | C11: 0 | D11: 0.01 | E11: 0.01 | F11: gaussian | G11: - | H11: - | K11: 50% Variable Sym Gaussian 4.3" | L11: gamma (1.82635,50%*1.82635) | M11: gamma (1.82635,50%*1.82635) | N11: - | O11: -
A12: 11 | B12: 0 | C12: 0 | D12: 0.01 | E12: 0.01 | F12: gaussian | G12: - | H12: - | K12: 10% Variable Sym Gaussian 8" | L12: gamma (3.39833,10%*3.39833) | M12: gamma (3.39833,10%*3.39833) | N12: - | O12: -
A13: 12 | B13: 0 | C13: 0 | D13: 0.01 | E13: 0.01 | F13: gaussian | G13: - | H13: - | K13: 30% Variable Sym Gaussian 8" | L13: gamma (3.39833,30%*3.39833) | M13: gamma (3.39833,30%*3.39833) | N13: - | O13: -
A14: 13 | B14: 0 | C14: 0 | D14: 0.01 | E14: 0.01 | F14: gaussian | G14: - | H14: - | K14: 50% Variable Sym Gaussian 8" | L14: gamma (3.39833,50%*3.39833) | M14: gamma (3.39833,50%*3.39833) | N14: - | O14: -
A15: 14 | B15: 0 | C15: 0 | D15: 0.01 | E15: 0.01 | F15: gaussian | G15: - | H15: - | K15: 10% Variable Asym Gaussian 4.3" (ratio 4:1) | L15: gamma (2.96374,10%*2.96374) | M15: gamma (0.74093,10%*0.74093) | N15: - | O15: -
A16: 15 | B16: 0 | C16: 0 | D16: 0.01 | E16: 0.01 | F16: gaussian | G16: - | H16: - | K16: 30% Variable Asym Gaussian 4.3" (ratio 4:1) | L16: gamma (2.96374,30%*2.96374) | M16: gamma (0.74093,30%*0.74093) | N16: - | O16: -
A17: 16 | B17: 0 | C17: 0 | D17: 0.01 | E17: 0.01 | F17: gaussian | G17: - | H17: - | K17: 50% Variable Asym Gaussian 4.3" (ratio 4:1) | L17: gamma (2.96374,50%*2.96374) | M17: gamma (0.74093,50%*0.74093) | N17: - | O17: -
A18: 17 | B18: 0 | C18: 0 | D18: 0.01 | E18: 0.01 | F18: gaussian | G18: - | H18: - | K18: 10% Variable Asym Gaussian 8" (ratio 7:1) | L18: gamma (5.79720,10%*5.79720) | M18: gamma (0.82817,10%*0.82817) | N18: - | O18: -
A19: 18 | B19: 0 | C19: 0 | D19: 0.01 | E19: 0.01 | F19: gaussian | G19: - | H19: - | K19: 30% Variable Asym Gaussian 8" (ratio 7:1) | L19: gamma (5.79720,30%*5.79720) | M19: gamma (0.82817,30%*0.82817) | N19: - | O19: -
A20: 19 | B20: 0 | C20: 0 | D20: 0.01 | E20: 0.01 | F20: gaussian | G20: - | H20: - | K20: 50% Variable Asym Gaussian 8" (ratio 7:1) | L20: gamma (5.79720,50%*5.79720) | M20: gamma (0.82817,50%*0.82817) | N20: - | O20: -
... A26: 25 | B26: 0 | C26: 0 | D26: 0.01 | E26: 0.01 | F26: gaussian | G26: - | H26: - | K26: 50% Variable Pseudo-Voigt 8" (alpha 10%) | L26: gamma (4.1303,50%*4.1303) | M26: gamma (1.2633,50%*1.2633) | N26: gamma(0.77,10%*0.77) | O26: gamma(0.29,10%*0.29)
A27: 26 | B27: 0 | C27: 0 | D27: 0.01 | E27: 0.01 | F27: gaussian | G27: - | H27: -
A28: 27 | B28: 0 | C28: 0 | D28: 0.01 | E28: 0.01 | F28: gaussian | G28: - | H28: -
A29: 28 | B29: 0 | C29: 0 | D29: 0.01 | E29: 0.01 | F29: gaussian | G29: - | H29: -
A30: 29 | B30: 0 | C30: 0 | D30: 0.01 | E30: 0.01 | F30: gaussian | G30: - | H30: -
A31: 30 | B31: 0 | C31: 0 | D31: 0.01 | E31: 0.01 | F31: gaussian | G31: - | H31: -
A32: 31 | B32: 0 | C32: 0 | D32: 0.01 | E32: 0.01 | F32: gaussian | G32: - | H32: -
A33: 32 | B33: 0 | C33: 0 | D33: 0.01 | E33: 0.01 | F33: gaussian | G33: - | H33: -
A34: 33 | B34: 0 | C34: 0 | D34: 0.01 | E34: 0.01 | F34: gaussian | G34: - | H34: -
A35: 34 | B35: 0 | C35: 0 | D35: 0.01 | E35: 0.01 | F35: gaussian | G35: - | H35: -
A36: 35 | B36: 0 | C36: 0 | D36: 0.01 | E36: 0.01 | F36: gaussian | G36: - | H36: -
A37: 36 | B37: 0 | C37: 0 | D37: 0.01 | E37: 0.01 | F37: gaussian | G37: - | H37: -
A38: 37 | B38: 0 | C38: 0 | D38: 0.01 | E38: 0.01 | F38: gaussian | G38: - | H38: -
... A601: 600 | B601: 0 | C601: 0 | D601: 0.01 | E601: 0.01 | F601: gaussian | G601: - | H601: -

Sheet Alignment
A1: Position # | B1: d_align_rad [µm] | C1: d_align_azi [µm] | D1: d_align_z [µm] | E1: d_align_rotz [arcsec] | G1: Standard alignment distributions | H1: d_align_rad_ | I1: d_align_azi_ | J1: d_align_z_ | K1: d_align_rotz_ | M1: From MLT documentation (2018) - max values assumed 3 sigma, % is assumed uniform distribution | N1: Unnamed: 5 | O1: Unnamed: 11
A2: 1 | B2: 0 | C2: 0 | D2: 0 | E2: 0 | G2: Standard medialario | H2: gaussian (0, 12/3) | I2: gaussian (0, 12/3) | J2: gaussian (0, (380+23+1500+93)/3) | K2: uniform (-9, 9)
A3: 2 | B3: 0 | C3: 0 | D3: 0 | E3: 0 | G3: 10% worse medialario | H3: gaussian (0, 12/3*110%) | I3: gaussian (0, 12/3*110%) | J3: gaussian (0, (380+23+1500+93)/3*110%) | K3: uniform (-9*110%, 9*110%)
A4: 3 | B4: 0 | C4: 0 | D4: 0 | E4: 0 | G4: 30% worse medialario | H4: gaussian (0, 12/3*130%) | I4: gaussian (0, 12/3*130%) | J4: gaussian (0, (380+23+1500+93)/3*130%) | K4: uniform (-9*130%, 9*130%)
A5: 4 | B5: 0 | C5: 0 | D5: 0 | E5: 0 | G5: 50% worse medialario | H5: gaussian (0, 12/3*150%) | I5: gaussian (0, 12/3*150%) | J5: gaussian (0, (380+23+1500+93)/3*150%) | K5: uniform (-9*150%, 9*150%)
A6: 5 | B6: 0 | C6: 0 | D6: 0 | E6: 0 | G6: 100% worse medialario | H6: gaussian (0, 12/3*200%) | I6: gaussian (0, 12/3*200%) | J6: gaussian (0, (380+23+1500+93)/3*200%) | K6: uniform (-9*200%, 9*200%)
A7: 6 | B7: 0 | C7: 0 | D7: 0 | E7: 0
A8: 7 | B8: 0 | C8: 0 | D8: 0 | E8: 0
A9: 8 | B9: 0 | C9: 0 | D9: 0 | E9: 0
A10: 9 | B10: 0 | C10: 0 | D10: 0 | E10: 0
A11: 10 | B11: 0 | C11: 0 | D11: 0 | E11: 0
A12: 11 | B12: 0 | C12: 0 | D12: 0 | E12: 0
A13: 12 | B13: 0 | C13: 0 | D13: 0 | E13: 0
A14: 13 | B14: 0 | C14: 0 | D14: 0 | E14: 0
A15: 14 | B15: 0 | C15: 0 | D15: 0 | E15: 0
A16: 15 | B16: 0 | C16: 0 | D16: 0 | E16: 0
A17: 16 | B17: 0 | C17: 0 | D17: 0 | E17: 0
A18: 17 | B18: 0 | C18: 0 | D18: 0 | E18: 0
... A601: 600 | B601: 0 | C601: 0 | D601: 0 | E601: 0

Sheet Gravity offload
A1: Position # | B1: d_grav_x [µm] | C1: d_grav_y [µm] | D1: d_grav_z [µm] | E1: d_grav_rotz [arcsec] | G1: Standard alignment distributions | H1: d_grav_x_ | I1: d_grav_y_ | J1: d_grav_z_ | K1: d_grav_rotz_ | Q1: 1GX disX [µm] | R1: 1GX disY [µm] | S1: 1GX disZ [µm] | T1: 1GX rotX [arcsec] | U1: 1GX rotY [arcsec] | V1: 1GX rotZ [arcsec] | W1: 1GY disX [µm] | X1: 1GY disY [µm] | Y1: 1GY disZ [µm] | Z1: 1GY rotX [arcsec] | AA1: 1GY rotY [arcsec] | AB1: 1GY rotZ [arcsec] | AC1: 1GZ disX [µm] | AD1: 1GZ disY [µm] | AE1: 1GZ disZ [µm] | AF1: 1GZ rotX [arcsec] | AG1: 1GZ rotY [arcsec] | AH1: 1GZ rotZ [arcsec]
A2: 1 | B2: 0 | C2: 0 | D2: 0 | E2: 0 | G2: GX | H2: Q | I2: R | J2: S | K2: V | Q2: -18.58871 | R2: -0.05507033 | S2: -2.0839711 | T2: -2.9602108 | U2: -3.2343573 | V2: -10.740646 | W2: -1.3255328 | X2: -18.164879 | Y2: 0.41699731 | Z2: 2.4414682 | AA2: 0.35403555 | AB2: 5.6369779 | AC2: 1.6037272 | AD2: -0.10678088 | AE2: -94.487488 | AF2: 0.4567937 | AG2: 0.61296861 | AH2: -1.3888335
A3: 2 | B3: 0 | C3: 0 | D3: 0 | E3: 0 | G3: GY | H3: W | I3: X | J3: Y | K3: AB | Q3: -15.112552 | R3: -1.1750112 | S3: -1.6408278 | T3: -0.49696921 | U3: -2.094758 | V3: -14.710421 | W3: -2.575988 | X3: -17.516275 | Y3: 0.71711701 | Z3: 1.9680426 | AA3: 0.05347824 | AB3: 3.6768094 | AC3: 2.4044212 | AD3: -0.77199516 | AE3: -94.60373 | AF3: 1.8782741 | AG3: 3.9745618 | AH3: -2.7236585
A4: 3 | B4: 0 | C4: 0 | D4: 0 | E4: 0 | G4: GZ | H4: AC | I4: AD | J4: AE | K4: AH | Q4: -14.225165 | R4: -1.5800352 | S4: -1.6258441 | T4: -2.1421125 | U4: -1.3542057 | V4: 9.6651619 | W4: -1.3186681 | X4: -16.911163 | Y4: 1.4515669 | Z4: 4.329378 | AA4: -0.075622185 | AB4: -12.029276 | AC4: 2.2126294 | AD4: -1.0612004 | AE4: -94.539351 | AF4: 0.42737779 | AG4: 0.14166445 | AH4: 3.7575866
A5: 4 | B5: 0 | C5: 0 | D5: 0 | E5: 0 | Q5: -17.697866 | R5: -0.84364399 | S5: -1.2990941 | T5: -1.7274982 | U5: -1.1571582 | V5: 9.3580758 | W5: 0.6066019 | X5: -18.928496 | Y5: 1.738088 | Z5: 5.1042519 | AA5: -0.7203865 | AB5: -5.6288602 | AC5: 1.1239928 | AD5: -0.98576507 | AE5: -94.467011 | AF5: -0.45868657 | AG5: -1.458067 | AH5: 2.6274738
A6: 5 | B6: 0 | C6: 0 | D6: 0 | E6: 0 | Q6: -20.627641 | R6: -1.4712712 | S6: -2.0098895 | T6: -1.4030395 | U6: -11.381494 | V6: -9.4384348 | W6: -1.9668897 | X6: -21.964624 | Y6: 0.44143973 | Z6: 2.0220126 | AA6: 0.46833234 | AB6: 6.7423474 | AC6: 2.3283985 | AD6: -0.53419403 | AE6: -93.590606 | AF6: 1.0492041 | AG6: 7.9264945 | AH6: -0.82043524
A7: 6 | B7: 0 | C7: 0 | D7: 0 | E7: 0 | Q7: -15.90996 | R7: -3.6110576 | S7: -1.9250205 | T7: -0.061709504 | U7: -2.060807 | V7: -15.127308 | W7: -3.9418348 | X7: -20.817115 | Y7: 0.81674757 | Z7: 1.6855346 | AA7: 0.088056873 | AB7: 5.3715937 | AC7: 2.6867284 | AD7: -1.8410252 | AE7: -93.1992 | AF7: 3.5044202 | AG7: 5.1434517 | AH7: -3.5514768
A8: 7 | B8: 0 | C8: 0 | D8: 0 | E8: 0 | Q8: -15.534318 | R8: -2.6630894 | S8: -1.4388448 | T8: -4.8214381 | U8: -8.9256273 | V8: 12.100423 | W8: -2.8309769 | X8: -19.234599 | Y8: 1.3571049 | Z8: 5.7531362 | AA8: 5.21846 | AB8: -12.385575 | AC8: 3.2320826 | AD8: -1.4658238 | AE8: -93.365356 | AF8: 3.7266751 | AG8: 8.6622812 | AH8: 4.9642698
A9: 8 | B9: 0 | C9: 0 | D9: 0 | E9: 0 | Q9: -19.980855 | R9: -1.3722864 | S9: -1.2200174 | T9: -6.0373587 | U9: -7.6299067 | V9: 10.298832 | W9: -0.98207109 | X9: -22.27946 | Y9: 1.6442184 | Z9: 9.1301851 | AA9: 6.1139499 | AB9: -4.8426568 | AC9: 2.3175679 | AD9: -1.1138855 | AE9: -93.551791 | AF9: 4.6908833 | AG9: 5.2672313 | AH9: 1.4206453
A10: 9 | B10: 0 | C10: 0 | D10: 0 | E10: 0 | Q10: -32.145172 | R10: -1.7375565 | S10: -2.4398167 | T10: -0.68744842 | U10: -11.629356 | V10: -21.109315 | W10: -1.4399453 | X10: -27.617009 | Y10: 0.40350603 | Z10: 1.9098775 | AA10: -0.17620513 | AB10: 6.6804634 | AC10: 4.9260421 | AD10: -0.41615694 | AE10: -91.061598 | AF10: 0.85288705 | AG10: 10.852122 | AH10: 0.57787903
A11: 10 | B11: 0 | C11: 0 | D11: 0 | E11: 0 | Q11: -18.958251 | R11: -6.4375421 | S11: -2.2258395 | T11: 0.050133259 | U11: -2.3803089 | V11: -23.490683 | W11: -5.5035859 | X11: -24.773654 | Y11: 1.019135 | Z11: 1.7247371 | AA11: 0.46418809 | AB11: 8.0812209 | AC11: 4.5458415 | AD11: -1.9045773 | AE11: -90.811104 | AF11: 4.5206978 | AG11: 7.8884608 | AH11: -0.46913823
A12: 11 | B12: 0 | C12: 0 | D12: 0 | E12: 0 | Q12: -17.795475 | R12: -4.265274 | S12: -1.8296947 | T12: -4.037215 | U12: -7.0155424 | V12: 19.512923 | W12: -4.5357115 | X12: -23.828984 | Y12: 1.5711101 | Z12: 5.3832892 | AA12: 4.2803929 | AB12: -18.464641 | AC12: 4.6190551 | AD12: -2.4480809 | AE12: -90.942771 | AF12: 5.0041144 | AG12: 9.9500146 | AH12: 1.5185969
A13: 12 | B13: 0 | C13: 0 | D13: 0 | E13: 0 | Q13: -26.895186 | R13: 1.7389346 | S13: -1.3645685 | T13: -5.1352602 | U13: -6.2715193 | V13: 16.288967 | W13: 0.71722651 | X13: -32.528234 | Y13: 2.0478844 | Z13: 8.4866213 | AA13: 5.2566591 | AB13: -15.058263 | AC13: 3.5186717 | AD13: -3.5791439 | AE13: -91.047343 | AF13: 8.0203946 | AG13: 7.235612 | AH13: -0.27053349
A14: 13 | B14: 0 | C14: 0 | D14: 0 | E14: 0 | Q14: -39.779334 | R14: -1.184954 | S14: -2.7874278 | T14: -0.8145719 | U14: -10.09276 | V14: -39.186877 | W14: -1.5007556 | X14: -32.146737 | Y14: 0.49672186 | Z14: 1.8727532 | AA14: -0.071782275 | AB14: 9.3312076 | AC14: 6.1577568 | AD14: -1.4731726 | AE14: -88.058548 | AF14: 1.5540725 | AG14: 13.555051 | AH14: 1.6075856
A15: 14 | B15: 0 | C15: 0 | D15: 0 | E15: 0 | Q15: -28.859286 | R15: -5.8557225 | S15: -2.6682756 | T15: -1.2467065 | U15: -7.3694392 | V15: -25.172441 | W15: -5.1199157 | X15: -31.300953 | Y15: 0.90616748 | Z15: 2.0092864 | AA15: 0.74789786 | AB15: 11.510156 | AC15: 5.9028242 | AD15: -1.6737719 | AE15: -87.819448 | AF15: 3.6602781 | AG15: 12.63326 | AH15: 0.46143486
A16: 15 | B16: 0 | C16: 0 | D16: 0 | E16: 0 | Q16: -21.074504 | R16: -7.5331211 | S16: -2.2845431 | T16: -1.6797148 | U16: -4.5137376 | V16: -2.33514 | W16: -7.0861662 | X16: -29.277074 | Y16: 1.4263597 | Z16: 3.3726559 | AA16: 2.1073494 | AB16: -5.3295762 | AC16: 5.7610239 | AD16: -2.6281303 | AE16: -87.659508 | AF16: 6.3790248 | AG16: 11.371863 | AH16: 0.4938747
... A601: 600 | B601: 0 | C601: 0 | D601: 0 | E601: 0 | Q601: -19.332181 | R601: -0.17367578 | S601: -2.454952 | T601: 0.50871253 | U601: -5.0893987 | V601: 2.1070216 | W601: 0.61696946 | X601: -12.696 | Y601: -0.11238612 | Z601: 0.83917196 | AA601: -1.1745227 | AB601: 1.3945464 | AC601: 1.241618 | AD601: 2.0875927 | AE601: -18.502937 | AF601: -1.9313613 | AG601: 4.9889287 | AH601: 2.6942395

Sheet Thermal
A1: Position # | B1: d_therm_x [µm] | C1: d_therm_y [µm] | D1: d_therm_z [µm] | E1: d_therm_rotz [arcsec] | G1: Standard alignment distributions | H1: d_therm_x_ | I1: d_therm_y_ | J1: d_therm_z_ | K1: d_therm_rotz_ | Q1: Thermal Load Case TC01 (0° FMS Tilt) disX [µm] | R1: Thermal Load Case TC01 (0° FMS Tilt) disY [µm] | S1: Thermal Load Case TC01 (0° FMS Tilt) disZ [µm] | T1: Thermal Load Case TC01 (0° FMS Tilt) rotX [arcsec] | U1: Thermal Load Case TC01 (0° FMS Tilt) rotY [arcsec] | V1: Thermal Load Case TC01 (0° FMS Tilt) rotZ [arcsec] | W1: Thermal Load Case TC02 (+30° FMS Tilt) disX [µm] | X1: Thermal Load Case TC02 (+30° FMS Tilt) disY [µm] | Y1: Thermal Load Case TC02 (+30° FMS Tilt) disZ [µm] | Z1: Thermal Load Case TC02 (+30° FMS Tilt) rotX [arcsec] | AA1: Thermal Load Case TC02 (+30° FMS Tilt) rotY [arcsec] | AB1: Thermal Load Case TC02 (+30° FMS Tilt) rotZ [arcsec] | AC1: Thermal Load Case TC03 (-30° FMS Tilt) disX [µm] | AD1: Thermal Load Case TC03 (-30° FMS Tilt) disY [µm] | AE1: Thermal Load Case TC03 (-30° FMS Tilt) disZ [µm] | AF1: Thermal Load Case TC03 (-30° FMS Tilt) rotX [arcsec] | AG1: Thermal Load Case TC03 (-30° FMS Tilt) rotY [arcsec] | AH1: Thermal Load Case TC03 (-30° FMS Tilt) rotZ [arcsec]
A2: 1 | B2: =Q2 -> -3.8066778 | C2: =R2 -> 0.22637149 | D2: =S2 -> 4.7915206 | E2: =V2 -> -2.4616056 | G2: 0 deg FMS Tilt | H2: Q | I2: R | J2: S | K2: V | Q2: -3.8066778 | R2: 0.22637149 | S2: 4.7915206 | T2: 2.0449545 | U2: 9.701933 | V2: -2.4616056 | W2: -3.9816873 | X2: 0.19947733 | Y2: 5.2359768 | Z2: 2.2470485 | AA2: 10.841087 | AB2: -2.3420322 | AC2: -4.3212135 | AD2: 0.23987976 | AE2: 5.9159129 | AF2: 2.5538772 | AG2: 12.53887 | AH2: -2.3662373
A3: 2 | B3: =Q3 -> -2.8274579 | C3: =R3 -> 0.52698884 | D3: =S3 -> 4.8884306 | E3: =V3 -> -1.8350676 | G3: 30 deg FMS Tilt | H3: W | I3: X | J3: Y | K3: AB | Q3: -2.8274579 | R3: 0.52698884 | S3: 4.8884306 | T3: 4.1921996 | U3: 8.1554014 | V3: -1.8350676 | W3: -3.0303229 | X3: 0.53719387 | Y3: 5.3275011 | Z3: 4.6121681 | AA3: 9.0901787 | AB3: -1.5188059 | AC3: -3.3407764 | AD3: 0.62221504 | AE3: 6.0041448 | AF3: 5.233475 | AG3: 10.461773 | AH3: -1.3492641
A4: 3 | B4: =Q4 -> -1.7987873 | C4: =R4 -> 1.428479 | D4: =S4 -> 5.1072909 | E4: =V4 -> 3.4303523 | G4: 30*-1 deg FMS Tilt | H4: AC | I4: AD | J4: AE | K4: AH | Q4: -1.7987873 | R4: 1.428479 | S4: 5.1072909 | T4: 7.1408154 | U4: 8.4344472 | V4: 3.4303523 | W4: -1.9649101 | X4: 1.5351071 | Y4: 5.5450182 | Z4: 7.8681528 | AA4: 9.3949064 | AB4: 3.5853327 | AC4: -2.1408831 | AD4: 1.7011182 | AE4: 6.2300162 | AF4: 8.9620382 | AG4: 10.791217 | AH4: 3.5983646
A5: 4 | B5: =Q5 -> -1.7116333 | C5: =R5 -> 2.2931226 | D5: =S5 -> 5.4540887 | E5: =V5 -> 1.878407 | Q5: -1.7116333 | R5: 2.2931226 | S5: 5.4540887 | T5: 9.0476932 | U5: 7.7712348 | V5: 1.878407 | W5: -1.8275681 | X5: 2.4671348 | Y5: 5.9053976 | Z5: 10.009225 | AA5: 8.6833049 | AB5: 1.9723991 | AC5: -1.9097949 | AD5: 2.6533269 | AE5: 6.6198508 | AF5: 11.486019 | AG5: 10.0052 | AH5: 2.0237104
A6: 5 | B6: =Q6 -> -3.9573646 | C6: =R6 -> -0.19858261 | D6: =S6 -> 7.7800883 | E6: =V6 -> -2.5421605 | Q6: -3.9573646 | R6: -0.19858261 | S6: 7.7800883 | T6: 3.5677771 | U6: 12.275618 | V6: -2.5421605 | W6: -4.1121062 | X6: -0.2569682 | Y6: 8.5780155 | Z6: 3.8668827 | AA6: 13.700344 | AB6: -2.4964392 | AC6: -4.4347496 | AD6: -0.21887576 | AE6: 9.779345 | AF6: 4.3264233 | AG6: 15.807614 | AH6: -2.6513583
A7: 6 | B7: =Q7 -> -2.4469388 | C7: =R7 -> -0.30216001 | D7: =S7 -> 8.1815972 | E7: =V7 -> -3.5602846 | Q7: -2.4469388 | R7: -0.30216001 | S7: 8.1815972 | T7: 6.9073151 | U7: 12.437262 | V7: -3.5602846 | W7: -2.5912608 | X7: -0.33133466 | Y7: 8.9911236 | Z7: 7.5394525 | AA7: 13.834947 | AB7: -3.3780273 | AC7: -2.7923845 | AD7: -0.2592694 | AE7: 10.193252 | AF7: 8.4896433 | AG7: 15.913291 | AH7: -3.4858713
A8: 7 | B8: =Q8 -> -1.4409867 | C8: =R8 -> 0.98522772 | D8: =S8 -> 8.7307097 | E8: =V8 -> 5.8630522 | Q8: -1.4409867 | R8: 0.98522772 | S8: 8.7307097 | T8: 9.3304114 | U8: 10.337152 | V8: 5.8630522 | W8: -1.5720098 | X8: 1.0526768 | Y8: 9.5565092 | Z8: 10.297313 | AA8: 11.492641 | AB8: 6.1781346 | AC8: -1.6354417 | AD8: 1.1856073 | AE8: 10.789332 | AF8: 11.765204 | AG8: 13.188339 | AH8: 6.3675468
A9: 8 | B9: =Q9 -> -1.6968837 | C9: =R9 -> 2.3891609 | D9: =S9 -> 8.8830008 | E9: =V9 -> 2.9845518 | Q9: -1.6968837 | R9: 2.3891609 | S9: 8.8830008 | T9: 11.063324 | U9: 8.3263571 | V9: 2.9845518 | W9: -1.8205558 | X9: 2.5627114 | Y9: 9.7046952 | Z9: 12.211042 | AA9: 9.2943985 | AB9: 3.1966171 | AC9: -1.8590771 | AD9: 2.736498 | AE9: 10.95665 | AF9: 13.980072 | AG9: 10.682958 | AH9: 3.4013822
A10: 9 | B10: =Q10 -> -4.6136551 | C10: =R10 -> -0.43684495 | D10: =S10 -> 13.289464 | E10: =V10 -> -6.5165997 | Q10: -4.6136551 | R10: -0.43684495 | S10: 13.289464 | T10: 3.7788015 | U10: 18.926677 | V10: -6.5165997 | W10: -4.7483602 | X10: -0.52678431 | Y10: 14.674552 | Z10: 4.0907825 | AA10: 20.87607 | AB10: -6.797217 | AC10: -5.1147973 | AD10: -0.5075473 | AE10: 16.741732 | AF10: 4.5575146 | AG10: 23.739605 | AH10: -7.3751295
A11: 10 | B11: =Q11 -> -0.79129846 | C11: =R11 -> -0.72111299 | D11: =S11 -> 13.609377 | E11: =V11 -> -1.7782028 | Q11: -0.79129846 | R11: -0.72111299 | S11: 13.609377 | T11: 9.7358065 | U11: 17.988082 | V11: -1.7782028 | W11: -0.80749162 | X11: -0.77625 | Y11: 14.974347 | Z11: 10.574313 | AA11: 19.821931 | AB11: -1.4606427 | AC11: -0.81687358 | AD11: -0.72692627 | AE11: 17.052497 | AF11: 11.821834 | AG11: 22.517346 | AH11: -1.5492223
A12: 11 | B12: =Q12 -> -0.10325321 | C12: =R12 -> -0.16691823 | D12: =S12 -> 14.255627 | E12: =V12 -> 4.2071571 | Q12: -0.10325321 | R12: -0.16691823 | S12: 14.255627 | T12: 13.461536 | U12: 15.752901 | V12: 4.2071571 | W12: -0.1385292 | X12: -0.16264114 | Y12: 15.638142 | Z12: 14.724411 | AA12: 17.32426 | AB12: 4.4588076 | AC12: -0.01534833 | AD12: -0.11684649 | AE12: 17.762306 | AF12: 16.640467 | AG12: 19.630123 | AH12: 4.458067
A13: 12 | B13: =Q13 -> -1.7266828 | C13: =R13 -> 2.696465 | D13: =S13 -> 15.216443 | E13: =V13 -> 7.1497367 | Q13: -1.7266828 | R13: 2.696465 | S13: 15.216443 | T13: 17.831246 | U13: 11.995891 | V13: 7.1497367 | W13: -1.8385922 | X13: 2.9311973 | Y13: 16.646892 | Z13: 19.454046 | AA13: 13.223455 | AB13: 7.6089352 | AC13: -1.8060138 | AD13: 3.1238252 | AE13: 18.868827 | AF13: 21.896186 | AG13: 14.984751 | AH13: 8.1907007
